[rospy.client][INFO] 2012-12-15 18:13:10,870: init_node, name[/depth_detection], pid[25520]
[xmlrpc][INFO] 2012-12-15 18:13:10,871: XML-RPC server binding to 0.0.0.0
[xmlrpc][INFO] 2012-12-15 18:13:10,871: Started XML-RPC server [http://pc:58744/]
[rospy.init][INFO] 2012-12-15 18:13:10,871: ROS Slave URI: [http://pc:58744/]
[rospy.impl.masterslave][INFO] 2012-12-15 18:13:10,871: _ready: http://pc:58744/
[rospy.registration][INFO] 2012-12-15 18:13:10,872: Registering with master node http://localhost:11311
[xmlrpc][INFO] 2012-12-15 18:13:10,873: xml rpc node: starting XML-RPC server
[rospy.init][INFO] 2012-12-15 18:13:10,972: registered with master
[rospy.rosout][INFO] 2012-12-15 18:13:11,009: initializing /rosout core topic
[rospy.rosout][INFO] 2012-12-15 18:13:11,012: connected to core topic /rosout
[rospy.simtime][INFO] 2012-12-15 18:13:11,013: /use_sim_time is not set, will not subscribe to simulated time [/clock] topic
[rosout][ERROR] 2012-12-15 18:13:24,053: bad callback: <bound method DepthDetector.depth_cb of <__main__.DepthDetector instance at 0x397da28>>
Traceback (most recent call last):
  File "/opt/ros/electric/stacks/ros_comm/clients/rospy/src/rospy/topics.py", line 581, in _invoke_callback
    cb(msg)
  File "/home/alex/MAS/CV/project/cv_nxtdrive/src/depth_detection.py", line 282, in depth_cb
    (contours, img_contours) = self.get_contours(img_fore)
  File "/home/alex/MAS/CV/project/cv_nxtdrive/src/depth_detection.py", line 107, in get_contours
    cont[0] = DepthDetector.merge_contours(cont[0])
  File "/home/alex/MAS/CV/project/cv_nxtdrive/src/depth_detection.py", line 161, in merge_contours
    return cls.merge_contours(new_cont)
  File "/home/alex/MAS/CV/project/cv_nxtdrive/src/depth_detection.py", line 156, in merge_contours
    i, j, i_pos, j_pos = cls.find_close_conts(cont)
  File "/home/alex/MAS/CV/project/cv_nxtdrive/src/depth_detection.py", line 140, in find_close_conts
    np.save('debug', np.array([list(x.shape) for x in cont]))
ValueError: setting an array element with a sequence.

[rosout][ERROR] 2012-12-15 18:13:24,083: bad callback: <bound method DepthDetector.depth_cb of <__main__.DepthDetector instance at 0x397da28>>
Traceback (most recent call last):
  File "/opt/ros/electric/stacks/ros_comm/clients/rospy/src/rospy/topics.py", line 581, in _invoke_callback
    cb(msg)
  File "/home/alex/MAS/CV/project/cv_nxtdrive/src/depth_detection.py", line 282, in depth_cb
    (contours, img_contours) = self.get_contours(img_fore)
  File "/home/alex/MAS/CV/project/cv_nxtdrive/src/depth_detection.py", line 107, in get_contours
    cont[0] = DepthDetector.merge_contours(cont[0])
  File "/home/alex/MAS/CV/project/cv_nxtdrive/src/depth_detection.py", line 161, in merge_contours
    return cls.merge_contours(new_cont)
  File "/home/alex/MAS/CV/project/cv_nxtdrive/src/depth_detection.py", line 161, in merge_contours
    return cls.merge_contours(new_cont)
  File "/home/alex/MAS/CV/project/cv_nxtdrive/src/depth_detection.py", line 156, in merge_contours
    i, j, i_pos, j_pos = cls.find_close_conts(cont)
  File "/home/alex/MAS/CV/project/cv_nxtdrive/src/depth_detection.py", line 140, in find_close_conts
    np.save('debug', np.array([list(x.shape) for x in cont]))
ValueError: setting an array element with a sequence.

[rosout][ERROR] 2012-12-15 18:13:24,116: bad callback: <bound method DepthDetector.depth_cb of <__main__.DepthDetector instance at 0x397da28>>
Traceback (most recent call last):
  File "/opt/ros/electric/stacks/ros_comm/clients/rospy/src/rospy/topics.py", line 581, in _invoke_callback
    cb(msg)
  File "/home/alex/MAS/CV/project/cv_nxtdrive/src/depth_detection.py", line 282, in depth_cb
    (contours, img_contours) = self.get_contours(img_fore)
  File "/home/alex/MAS/CV/project/cv_nxtdrive/src/depth_detection.py", line 107, in get_contours
    cont[0] = DepthDetector.merge_contours(cont[0])
  File "/home/alex/MAS/CV/project/cv_nxtdrive/src/depth_detection.py", line 161, in merge_contours
    return cls.merge_contours(new_cont)
  File "/home/alex/MAS/CV/project/cv_nxtdrive/src/depth_detection.py", line 156, in merge_contours
    i, j, i_pos, j_pos = cls.find_close_conts(cont)
  File "/home/alex/MAS/CV/project/cv_nxtdrive/src/depth_detection.py", line 140, in find_close_conts
    np.save('debug', np.array([list(x.shape) for x in cont]))
ValueError: setting an array element with a sequence.

[rosout][ERROR] 2012-12-15 18:13:24,148: bad callback: <bound method DepthDetector.depth_cb of <__main__.DepthDetector instance at 0x397da28>>
Traceback (most recent call last):
  File "/opt/ros/electric/stacks/ros_comm/clients/rospy/src/rospy/topics.py", line 581, in _invoke_callback
    cb(msg)
  File "/home/alex/MAS/CV/project/cv_nxtdrive/src/depth_detection.py", line 282, in depth_cb
    (contours, img_contours) = self.get_contours(img_fore)
  File "/home/alex/MAS/CV/project/cv_nxtdrive/src/depth_detection.py", line 107, in get_contours
    cont[0] = DepthDetector.merge_contours(cont[0])
  File "/home/alex/MAS/CV/project/cv_nxtdrive/src/depth_detection.py", line 161, in merge_contours
    return cls.merge_contours(new_cont)
  File "/home/alex/MAS/CV/project/cv_nxtdrive/src/depth_detection.py", line 156, in merge_contours
    i, j, i_pos, j_pos = cls.find_close_conts(cont)
  File "/home/alex/MAS/CV/project/cv_nxtdrive/src/depth_detection.py", line 140, in find_close_conts
    np.save('debug', np.array([list(x.shape) for x in cont]))
ValueError: setting an array element with a sequence.

[rosout][ERROR] 2012-12-15 18:13:24,181: bad callback: <bound method DepthDetector.depth_cb of <__main__.DepthDetector instance at 0x397da28>>
Traceback (most recent call last):
  File "/opt/ros/electric/stacks/ros_comm/clients/rospy/src/rospy/topics.py", line 581, in _invoke_callback
    cb(msg)
  File "/home/alex/MAS/CV/project/cv_nxtdrive/src/depth_detection.py", line 282, in depth_cb
    (contours, img_contours) = self.get_contours(img_fore)
  File "/home/alex/MAS/CV/project/cv_nxtdrive/src/depth_detection.py", line 107, in get_contours
    cont[0] = DepthDetector.merge_contours(cont[0])
  File "/home/alex/MAS/CV/project/cv_nxtdrive/src/depth_detection.py", line 161, in merge_contours
    return cls.merge_contours(new_cont)
  File "/home/alex/MAS/CV/project/cv_nxtdrive/src/depth_detection.py", line 156, in merge_contours
    i, j, i_pos, j_pos = cls.find_close_conts(cont)
  File "/home/alex/MAS/CV/project/cv_nxtdrive/src/depth_detection.py", line 140, in find_close_conts
    np.save('debug', np.array([list(x.shape) for x in cont]))
ValueError: setting an array element with a sequence.

[rosout][ERROR] 2012-12-15 18:13:24,210: bad callback: <bound method DepthDetector.depth_cb of <__main__.DepthDetector instance at 0x397da28>>
Traceback (most recent call last):
  File "/opt/ros/electric/stacks/ros_comm/clients/rospy/src/rospy/topics.py", line 581, in _invoke_callback
    cb(msg)
  File "/home/alex/MAS/CV/project/cv_nxtdrive/src/depth_detection.py", line 282, in depth_cb
    (contours, img_contours) = self.get_contours(img_fore)
  File "/home/alex/MAS/CV/project/cv_nxtdrive/src/depth_detection.py", line 107, in get_contours
    cont[0] = DepthDetector.merge_contours(cont[0])
  File "/home/alex/MAS/CV/project/cv_nxtdrive/src/depth_detection.py", line 161, in merge_contours
    return cls.merge_contours(new_cont)
  File "/home/alex/MAS/CV/project/cv_nxtdrive/src/depth_detection.py", line 156, in merge_contours
    i, j, i_pos, j_pos = cls.find_close_conts(cont)
  File "/home/alex/MAS/CV/project/cv_nxtdrive/src/depth_detection.py", line 140, in find_close_conts
    np.save('debug', np.array([list(x.shape) for x in cont]))
ValueError: setting an array element with a sequence.

[rosout][ERROR] 2012-12-15 18:13:24,243: bad callback: <bound method DepthDetector.depth_cb of <__main__.DepthDetector instance at 0x397da28>>
Traceback (most recent call last):
  File "/opt/ros/electric/stacks/ros_comm/clients/rospy/src/rospy/topics.py", line 581, in _invoke_callback
    cb(msg)
  File "/home/alex/MAS/CV/project/cv_nxtdrive/src/depth_detection.py", line 282, in depth_cb
    (contours, img_contours) = self.get_contours(img_fore)
  File "/home/alex/MAS/CV/project/cv_nxtdrive/src/depth_detection.py", line 107, in get_contours
    cont[0] = DepthDetector.merge_contours(cont[0])
  File "/home/alex/MAS/CV/project/cv_nxtdrive/src/depth_detection.py", line 161, in merge_contours
    return cls.merge_contours(new_cont)
  File "/home/alex/MAS/CV/project/cv_nxtdrive/src/depth_detection.py", line 156, in merge_contours
    i, j, i_pos, j_pos = cls.find_close_conts(cont)
  File "/home/alex/MAS/CV/project/cv_nxtdrive/src/depth_detection.py", line 140, in find_close_conts
    np.save('debug', np.array([list(x.shape) for x in cont]))
ValueError: setting an array element with a sequence.

[rosout][ERROR] 2012-12-15 18:13:24,273: bad callback: <bound method DepthDetector.depth_cb of <__main__.DepthDetector instance at 0x397da28>>
Traceback (most recent call last):
  File "/opt/ros/electric/stacks/ros_comm/clients/rospy/src/rospy/topics.py", line 581, in _invoke_callback
    cb(msg)
  File "/home/alex/MAS/CV/project/cv_nxtdrive/src/depth_detection.py", line 282, in depth_cb
    (contours, img_contours) = self.get_contours(img_fore)
  File "/home/alex/MAS/CV/project/cv_nxtdrive/src/depth_detection.py", line 107, in get_contours
    cont[0] = DepthDetector.merge_contours(cont[0])
  File "/home/alex/MAS/CV/project/cv_nxtdrive/src/depth_detection.py", line 161, in merge_contours
    return cls.merge_contours(new_cont)
  File "/home/alex/MAS/CV/project/cv_nxtdrive/src/depth_detection.py", line 156, in merge_contours
    i, j, i_pos, j_pos = cls.find_close_conts(cont)
  File "/home/alex/MAS/CV/project/cv_nxtdrive/src/depth_detection.py", line 140, in find_close_conts
    np.save('debug', np.array([list(x.shape) for x in cont]))
ValueError: setting an array element with a sequence.

[rosout][ERROR] 2012-12-15 18:13:24,306: bad callback: <bound method DepthDetector.depth_cb of <__main__.DepthDetector instance at 0x397da28>>
Traceback (most recent call last):
  File "/opt/ros/electric/stacks/ros_comm/clients/rospy/src/rospy/topics.py", line 581, in _invoke_callback
    cb(msg)
  File "/home/alex/MAS/CV/project/cv_nxtdrive/src/depth_detection.py", line 282, in depth_cb
    (contours, img_contours) = self.get_contours(img_fore)
  File "/home/alex/MAS/CV/project/cv_nxtdrive/src/depth_detection.py", line 107, in get_contours
    cont[0] = DepthDetector.merge_contours(cont[0])
  File "/home/alex/MAS/CV/project/cv_nxtdrive/src/depth_detection.py", line 161, in merge_contours
    return cls.merge_contours(new_cont)
  File "/home/alex/MAS/CV/project/cv_nxtdrive/src/depth_detection.py", line 156, in merge_contours
    i, j, i_pos, j_pos = cls.find_close_conts(cont)
  File "/home/alex/MAS/CV/project/cv_nxtdrive/src/depth_detection.py", line 140, in find_close_conts
    np.save('debug', np.array([list(x.shape) for x in cont]))
ValueError: setting an array element with a sequence.

[rosout][ERROR] 2012-12-15 18:13:24,343: bad callback: <bound method DepthDetector.depth_cb of <__main__.DepthDetector instance at 0x397da28>>
Traceback (most recent call last):
  File "/opt/ros/electric/stacks/ros_comm/clients/rospy/src/rospy/topics.py", line 581, in _invoke_callback
    cb(msg)
  File "/home/alex/MAS/CV/project/cv_nxtdrive/src/depth_detection.py", line 282, in depth_cb
    (contours, img_contours) = self.get_contours(img_fore)
  File "/home/alex/MAS/CV/project/cv_nxtdrive/src/depth_detection.py", line 107, in get_contours
    cont[0] = DepthDetector.merge_contours(cont[0])
  File "/home/alex/MAS/CV/project/cv_nxtdrive/src/depth_detection.py", line 161, in merge_contours
    return cls.merge_contours(new_cont)
  File "/home/alex/MAS/CV/project/cv_nxtdrive/src/depth_detection.py", line 156, in merge_contours
    i, j, i_pos, j_pos = cls.find_close_conts(cont)
  File "/home/alex/MAS/CV/project/cv_nxtdrive/src/depth_detection.py", line 140, in find_close_conts
    np.save('debug', np.array([list(x.shape) for x in cont]))
ValueError: setting an array element with a sequence.

[rosout][ERROR] 2012-12-15 18:13:24,385: bad callback: <bound method DepthDetector.depth_cb of <__main__.DepthDetector instance at 0x397da28>>
Traceback (most recent call last):
  File "/opt/ros/electric/stacks/ros_comm/clients/rospy/src/rospy/topics.py", line 581, in _invoke_callback
    cb(msg)
  File "/home/alex/MAS/CV/project/cv_nxtdrive/src/depth_detection.py", line 282, in depth_cb
    (contours, img_contours) = self.get_contours(img_fore)
  File "/home/alex/MAS/CV/project/cv_nxtdrive/src/depth_detection.py", line 107, in get_contours
    cont[0] = DepthDetector.merge_contours(cont[0])
  File "/home/alex/MAS/CV/project/cv_nxtdrive/src/depth_detection.py", line 161, in merge_contours
    return cls.merge_contours(new_cont)
  File "/home/alex/MAS/CV/project/cv_nxtdrive/src/depth_detection.py", line 156, in merge_contours
    i, j, i_pos, j_pos = cls.find_close_conts(cont)
  File "/home/alex/MAS/CV/project/cv_nxtdrive/src/depth_detection.py", line 140, in find_close_conts
    np.save('debug', np.array([list(x.shape) for x in cont]))
ValueError: setting an array element with a sequence.

[rosout][ERROR] 2012-12-15 18:13:24,414: bad callback: <bound method DepthDetector.depth_cb of <__main__.DepthDetector instance at 0x397da28>>
Traceback (most recent call last):
  File "/opt/ros/electric/stacks/ros_comm/clients/rospy/src/rospy/topics.py", line 581, in _invoke_callback
    cb(msg)
  File "/home/alex/MAS/CV/project/cv_nxtdrive/src/depth_detection.py", line 282, in depth_cb
    (contours, img_contours) = self.get_contours(img_fore)
  File "/home/alex/MAS/CV/project/cv_nxtdrive/src/depth_detection.py", line 107, in get_contours
    cont[0] = DepthDetector.merge_contours(cont[0])
  File "/home/alex/MAS/CV/project/cv_nxtdrive/src/depth_detection.py", line 161, in merge_contours
    return cls.merge_contours(new_cont)
  File "/home/alex/MAS/CV/project/cv_nxtdrive/src/depth_detection.py", line 156, in merge_contours
    i, j, i_pos, j_pos = cls.find_close_conts(cont)
  File "/home/alex/MAS/CV/project/cv_nxtdrive/src/depth_detection.py", line 140, in find_close_conts
    np.save('debug', np.array([list(x.shape) for x in cont]))
ValueError: setting an array element with a sequence.

[rosout][ERROR] 2012-12-15 18:13:24,446: bad callback: <bound method DepthDetector.depth_cb of <__main__.DepthDetector instance at 0x397da28>>
Traceback (most recent call last):
  File "/opt/ros/electric/stacks/ros_comm/clients/rospy/src/rospy/topics.py", line 581, in _invoke_callback
    cb(msg)
  File "/home/alex/MAS/CV/project/cv_nxtdrive/src/depth_detection.py", line 282, in depth_cb
    (contours, img_contours) = self.get_contours(img_fore)
  File "/home/alex/MAS/CV/project/cv_nxtdrive/src/depth_detection.py", line 107, in get_contours
    cont[0] = DepthDetector.merge_contours(cont[0])
  File "/home/alex/MAS/CV/project/cv_nxtdrive/src/depth_detection.py", line 161, in merge_contours
    return cls.merge_contours(new_cont)
  File "/home/alex/MAS/CV/project/cv_nxtdrive/src/depth_detection.py", line 156, in merge_contours
    i, j, i_pos, j_pos = cls.find_close_conts(cont)
  File "/home/alex/MAS/CV/project/cv_nxtdrive/src/depth_detection.py", line 140, in find_close_conts
    np.save('debug', np.array([list(x.shape) for x in cont]))
ValueError: setting an array element with a sequence.

[rosout][ERROR] 2012-12-15 18:13:24,478: bad callback: <bound method DepthDetector.depth_cb of <__main__.DepthDetector instance at 0x397da28>>
Traceback (most recent call last):
  File "/opt/ros/electric/stacks/ros_comm/clients/rospy/src/rospy/topics.py", line 581, in _invoke_callback
    cb(msg)
  File "/home/alex/MAS/CV/project/cv_nxtdrive/src/depth_detection.py", line 282, in depth_cb
    (contours, img_contours) = self.get_contours(img_fore)
  File "/home/alex/MAS/CV/project/cv_nxtdrive/src/depth_detection.py", line 107, in get_contours
    cont[0] = DepthDetector.merge_contours(cont[0])
  File "/home/alex/MAS/CV/project/cv_nxtdrive/src/depth_detection.py", line 161, in merge_contours
    return cls.merge_contours(new_cont)
  File "/home/alex/MAS/CV/project/cv_nxtdrive/src/depth_detection.py", line 156, in merge_contours
    i, j, i_pos, j_pos = cls.find_close_conts(cont)
  File "/home/alex/MAS/CV/project/cv_nxtdrive/src/depth_detection.py", line 140, in find_close_conts
    np.save('debug', np.array([list(x.shape) for x in cont]))
ValueError: setting an array element with a sequence.

[rosout][ERROR] 2012-12-15 18:13:24,510: bad callback: <bound method DepthDetector.depth_cb of <__main__.DepthDetector instance at 0x397da28>>
Traceback (most recent call last):
  File "/opt/ros/electric/stacks/ros_comm/clients/rospy/src/rospy/topics.py", line 581, in _invoke_callback
    cb(msg)
  File "/home/alex/MAS/CV/project/cv_nxtdrive/src/depth_detection.py", line 282, in depth_cb
    (contours, img_contours) = self.get_contours(img_fore)
  File "/home/alex/MAS/CV/project/cv_nxtdrive/src/depth_detection.py", line 107, in get_contours
    cont[0] = DepthDetector.merge_contours(cont[0])
  File "/home/alex/MAS/CV/project/cv_nxtdrive/src/depth_detection.py", line 161, in merge_contours
    return cls.merge_contours(new_cont)
  File "/home/alex/MAS/CV/project/cv_nxtdrive/src/depth_detection.py", line 156, in merge_contours
    i, j, i_pos, j_pos = cls.find_close_conts(cont)
  File "/home/alex/MAS/CV/project/cv_nxtdrive/src/depth_detection.py", line 140, in find_close_conts
    np.save('debug', np.array([list(x.shape) for x in cont]))
ValueError: setting an array element with a sequence.

[rosout][ERROR] 2012-12-15 18:13:24,541: bad callback: <bound method DepthDetector.depth_cb of <__main__.DepthDetector instance at 0x397da28>>
Traceback (most recent call last):
  File "/opt/ros/electric/stacks/ros_comm/clients/rospy/src/rospy/topics.py", line 581, in _invoke_callback
    cb(msg)
  File "/home/alex/MAS/CV/project/cv_nxtdrive/src/depth_detection.py", line 282, in depth_cb
    (contours, img_contours) = self.get_contours(img_fore)
  File "/home/alex/MAS/CV/project/cv_nxtdrive/src/depth_detection.py", line 107, in get_contours
    cont[0] = DepthDetector.merge_contours(cont[0])
  File "/home/alex/MAS/CV/project/cv_nxtdrive/src/depth_detection.py", line 161, in merge_contours
    return cls.merge_contours(new_cont)
  File "/home/alex/MAS/CV/project/cv_nxtdrive/src/depth_detection.py", line 161, in merge_contours
    return cls.merge_contours(new_cont)
  File "/home/alex/MAS/CV/project/cv_nxtdrive/src/depth_detection.py", line 156, in merge_contours
    i, j, i_pos, j_pos = cls.find_close_conts(cont)
  File "/home/alex/MAS/CV/project/cv_nxtdrive/src/depth_detection.py", line 140, in find_close_conts
    np.save('debug', np.array([list(x.shape) for x in cont]))
ValueError: setting an array element with a sequence.

[rosout][ERROR] 2012-12-15 18:13:24,572: bad callback: <bound method DepthDetector.depth_cb of <__main__.DepthDetector instance at 0x397da28>>
Traceback (most recent call last):
  File "/opt/ros/electric/stacks/ros_comm/clients/rospy/src/rospy/topics.py", line 581, in _invoke_callback
    cb(msg)
  File "/home/alex/MAS/CV/project/cv_nxtdrive/src/depth_detection.py", line 282, in depth_cb
    (contours, img_contours) = self.get_contours(img_fore)
  File "/home/alex/MAS/CV/project/cv_nxtdrive/src/depth_detection.py", line 107, in get_contours
    cont[0] = DepthDetector.merge_contours(cont[0])
  File "/home/alex/MAS/CV/project/cv_nxtdrive/src/depth_detection.py", line 161, in merge_contours
    return cls.merge_contours(new_cont)
  File "/home/alex/MAS/CV/project/cv_nxtdrive/src/depth_detection.py", line 156, in merge_contours
    i, j, i_pos, j_pos = cls.find_close_conts(cont)
  File "/home/alex/MAS/CV/project/cv_nxtdrive/src/depth_detection.py", line 140, in find_close_conts
    np.save('debug', np.array([list(x.shape) for x in cont]))
ValueError: setting an array element with a sequence.

[rosout][ERROR] 2012-12-15 18:13:24,604: bad callback: <bound method DepthDetector.depth_cb of <__main__.DepthDetector instance at 0x397da28>>
Traceback (most recent call last):
  File "/opt/ros/electric/stacks/ros_comm/clients/rospy/src/rospy/topics.py", line 581, in _invoke_callback
    cb(msg)
  File "/home/alex/MAS/CV/project/cv_nxtdrive/src/depth_detection.py", line 282, in depth_cb
    (contours, img_contours) = self.get_contours(img_fore)
  File "/home/alex/MAS/CV/project/cv_nxtdrive/src/depth_detection.py", line 107, in get_contours
    cont[0] = DepthDetector.merge_contours(cont[0])
  File "/home/alex/MAS/CV/project/cv_nxtdrive/src/depth_detection.py", line 161, in merge_contours
    return cls.merge_contours(new_cont)
  File "/home/alex/MAS/CV/project/cv_nxtdrive/src/depth_detection.py", line 156, in merge_contours
    i, j, i_pos, j_pos = cls.find_close_conts(cont)
  File "/home/alex/MAS/CV/project/cv_nxtdrive/src/depth_detection.py", line 140, in find_close_conts
    np.save('debug', np.array([list(x.shape) for x in cont]))
ValueError: setting an array element with a sequence.

[rosout][ERROR] 2012-12-15 18:13:24,638: bad callback: <bound method DepthDetector.depth_cb of <__main__.DepthDetector instance at 0x397da28>>
Traceback (most recent call last):
  File "/opt/ros/electric/stacks/ros_comm/clients/rospy/src/rospy/topics.py", line 581, in _invoke_callback
    cb(msg)
  File "/home/alex/MAS/CV/project/cv_nxtdrive/src/depth_detection.py", line 282, in depth_cb
    (contours, img_contours) = self.get_contours(img_fore)
  File "/home/alex/MAS/CV/project/cv_nxtdrive/src/depth_detection.py", line 107, in get_contours
    cont[0] = DepthDetector.merge_contours(cont[0])
  File "/home/alex/MAS/CV/project/cv_nxtdrive/src/depth_detection.py", line 161, in merge_contours
    return cls.merge_contours(new_cont)
  File "/home/alex/MAS/CV/project/cv_nxtdrive/src/depth_detection.py", line 156, in merge_contours
    i, j, i_pos, j_pos = cls.find_close_conts(cont)
  File "/home/alex/MAS/CV/project/cv_nxtdrive/src/depth_detection.py", line 140, in find_close_conts
    np.save('debug', np.array([list(x.shape) for x in cont]))
ValueError: setting an array element with a sequence.

[rosout][ERROR] 2012-12-15 18:13:24,668: bad callback: <bound method DepthDetector.depth_cb of <__main__.DepthDetector instance at 0x397da28>>
Traceback (most recent call last):
  File "/opt/ros/electric/stacks/ros_comm/clients/rospy/src/rospy/topics.py", line 581, in _invoke_callback
    cb(msg)
  File "/home/alex/MAS/CV/project/cv_nxtdrive/src/depth_detection.py", line 282, in depth_cb
    (contours, img_contours) = self.get_contours(img_fore)
  File "/home/alex/MAS/CV/project/cv_nxtdrive/src/depth_detection.py", line 107, in get_contours
    cont[0] = DepthDetector.merge_contours(cont[0])
  File "/home/alex/MAS/CV/project/cv_nxtdrive/src/depth_detection.py", line 161, in merge_contours
    return cls.merge_contours(new_cont)
  File "/home/alex/MAS/CV/project/cv_nxtdrive/src/depth_detection.py", line 156, in merge_contours
    i, j, i_pos, j_pos = cls.find_close_conts(cont)
  File "/home/alex/MAS/CV/project/cv_nxtdrive/src/depth_detection.py", line 140, in find_close_conts
    np.save('debug', np.array([list(x.shape) for x in cont]))
ValueError: setting an array element with a sequence.

[rosout][ERROR] 2012-12-15 18:13:24,702: bad callback: <bound method DepthDetector.depth_cb of <__main__.DepthDetector instance at 0x397da28>>
Traceback (most recent call last):
  File "/opt/ros/electric/stacks/ros_comm/clients/rospy/src/rospy/topics.py", line 581, in _invoke_callback
    cb(msg)
  File "/home/alex/MAS/CV/project/cv_nxtdrive/src/depth_detection.py", line 282, in depth_cb
    (contours, img_contours) = self.get_contours(img_fore)
  File "/home/alex/MAS/CV/project/cv_nxtdrive/src/depth_detection.py", line 107, in get_contours
    cont[0] = DepthDetector.merge_contours(cont[0])
  File "/home/alex/MAS/CV/project/cv_nxtdrive/src/depth_detection.py", line 161, in merge_contours
    return cls.merge_contours(new_cont)
  File "/home/alex/MAS/CV/project/cv_nxtdrive/src/depth_detection.py", line 156, in merge_contours
    i, j, i_pos, j_pos = cls.find_close_conts(cont)
  File "/home/alex/MAS/CV/project/cv_nxtdrive/src/depth_detection.py", line 140, in find_close_conts
    np.save('debug', np.array([list(x.shape) for x in cont]))
ValueError: setting an array element with a sequence.

[rosout][ERROR] 2012-12-15 18:13:24,737: bad callback: <bound method DepthDetector.depth_cb of <__main__.DepthDetector instance at 0x397da28>>
Traceback (most recent call last):
  File "/opt/ros/electric/stacks/ros_comm/clients/rospy/src/rospy/topics.py", line 581, in _invoke_callback
    cb(msg)
  File "/home/alex/MAS/CV/project/cv_nxtdrive/src/depth_detection.py", line 282, in depth_cb
    (contours, img_contours) = self.get_contours(img_fore)
  File "/home/alex/MAS/CV/project/cv_nxtdrive/src/depth_detection.py", line 107, in get_contours
    cont[0] = DepthDetector.merge_contours(cont[0])
  File "/home/alex/MAS/CV/project/cv_nxtdrive/src/depth_detection.py", line 161, in merge_contours
    return cls.merge_contours(new_cont)
  File "/home/alex/MAS/CV/project/cv_nxtdrive/src/depth_detection.py", line 156, in merge_contours
    i, j, i_pos, j_pos = cls.find_close_conts(cont)
  File "/home/alex/MAS/CV/project/cv_nxtdrive/src/depth_detection.py", line 140, in find_close_conts
    np.save('debug', np.array([list(x.shape) for x in cont]))
ValueError: setting an array element with a sequence.

[rosout][ERROR] 2012-12-15 18:13:24,773: bad callback: <bound method DepthDetector.depth_cb of <__main__.DepthDetector instance at 0x397da28>>
Traceback (most recent call last):
  File "/opt/ros/electric/stacks/ros_comm/clients/rospy/src/rospy/topics.py", line 581, in _invoke_callback
    cb(msg)
  File "/home/alex/MAS/CV/project/cv_nxtdrive/src/depth_detection.py", line 282, in depth_cb
    (contours, img_contours) = self.get_contours(img_fore)
  File "/home/alex/MAS/CV/project/cv_nxtdrive/src/depth_detection.py", line 107, in get_contours
    cont[0] = DepthDetector.merge_contours(cont[0])
  File "/home/alex/MAS/CV/project/cv_nxtdrive/src/depth_detection.py", line 161, in merge_contours
    return cls.merge_contours(new_cont)
  File "/home/alex/MAS/CV/project/cv_nxtdrive/src/depth_detection.py", line 161, in merge_contours
    return cls.merge_contours(new_cont)
  File "/home/alex/MAS/CV/project/cv_nxtdrive/src/depth_detection.py", line 156, in merge_contours
    i, j, i_pos, j_pos = cls.find_close_conts(cont)
  File "/home/alex/MAS/CV/project/cv_nxtdrive/src/depth_detection.py", line 140, in find_close_conts
    np.save('debug', np.array([list(x.shape) for x in cont]))
ValueError: setting an array element with a sequence.

[rosout][ERROR] 2012-12-15 18:13:24,827: bad callback: <bound method DepthDetector.depth_cb of <__main__.DepthDetector instance at 0x397da28>>
Traceback (most recent call last):
  File "/opt/ros/electric/stacks/ros_comm/clients/rospy/src/rospy/topics.py", line 581, in _invoke_callback
    cb(msg)
  File "/home/alex/MAS/CV/project/cv_nxtdrive/src/depth_detection.py", line 282, in depth_cb
    (contours, img_contours) = self.get_contours(img_fore)
  File "/home/alex/MAS/CV/project/cv_nxtdrive/src/depth_detection.py", line 107, in get_contours
    cont[0] = DepthDetector.merge_contours(cont[0])
  File "/home/alex/MAS/CV/project/cv_nxtdrive/src/depth_detection.py", line 161, in merge_contours
    return cls.merge_contours(new_cont)
  File "/home/alex/MAS/CV/project/cv_nxtdrive/src/depth_detection.py", line 156, in merge_contours
    i, j, i_pos, j_pos = cls.find_close_conts(cont)
  File "/home/alex/MAS/CV/project/cv_nxtdrive/src/depth_detection.py", line 140, in find_close_conts
    np.save('debug', np.array([list(x.shape) for x in cont]))
ValueError: setting an array element with a sequence.

[rosout][ERROR] 2012-12-15 18:13:24,862: bad callback: <bound method DepthDetector.depth_cb of <__main__.DepthDetector instance at 0x397da28>>
Traceback (most recent call last):
  File "/opt/ros/electric/stacks/ros_comm/clients/rospy/src/rospy/topics.py", line 581, in _invoke_callback
    cb(msg)
  File "/home/alex/MAS/CV/project/cv_nxtdrive/src/depth_detection.py", line 282, in depth_cb
    (contours, img_contours) = self.get_contours(img_fore)
  File "/home/alex/MAS/CV/project/cv_nxtdrive/src/depth_detection.py", line 107, in get_contours
    cont[0] = DepthDetector.merge_contours(cont[0])
  File "/home/alex/MAS/CV/project/cv_nxtdrive/src/depth_detection.py", line 161, in merge_contours
    return cls.merge_contours(new_cont)
  File "/home/alex/MAS/CV/project/cv_nxtdrive/src/depth_detection.py", line 161, in merge_contours
    return cls.merge_contours(new_cont)
  File "/home/alex/MAS/CV/project/cv_nxtdrive/src/depth_detection.py", line 156, in merge_contours
    i, j, i_pos, j_pos = cls.find_close_conts(cont)
  File "/home/alex/MAS/CV/project/cv_nxtdrive/src/depth_detection.py", line 140, in find_close_conts
    np.save('debug', np.array([list(x.shape) for x in cont]))
ValueError: setting an array element with a sequence.

[rosout][ERROR] 2012-12-15 18:13:24,898: bad callback: <bound method DepthDetector.depth_cb of <__main__.DepthDetector instance at 0x397da28>>
Traceback (most recent call last):
  File "/opt/ros/electric/stacks/ros_comm/clients/rospy/src/rospy/topics.py", line 581, in _invoke_callback
    cb(msg)
  File "/home/alex/MAS/CV/project/cv_nxtdrive/src/depth_detection.py", line 282, in depth_cb
    (contours, img_contours) = self.get_contours(img_fore)
  File "/home/alex/MAS/CV/project/cv_nxtdrive/src/depth_detection.py", line 107, in get_contours
    cont[0] = DepthDetector.merge_contours(cont[0])
  File "/home/alex/MAS/CV/project/cv_nxtdrive/src/depth_detection.py", line 161, in merge_contours
    return cls.merge_contours(new_cont)
  File "/home/alex/MAS/CV/project/cv_nxtdrive/src/depth_detection.py", line 156, in merge_contours
    i, j, i_pos, j_pos = cls.find_close_conts(cont)
  File "/home/alex/MAS/CV/project/cv_nxtdrive/src/depth_detection.py", line 140, in find_close_conts
    np.save('debug', np.array([list(x.shape) for x in cont]))
ValueError: setting an array element with a sequence.

[rosout][ERROR] 2012-12-15 18:13:24,930: bad callback: <bound method DepthDetector.depth_cb of <__main__.DepthDetector instance at 0x397da28>>
Traceback (most recent call last):
  File "/opt/ros/electric/stacks/ros_comm/clients/rospy/src/rospy/topics.py", line 581, in _invoke_callback
    cb(msg)
  File "/home/alex/MAS/CV/project/cv_nxtdrive/src/depth_detection.py", line 282, in depth_cb
    (contours, img_contours) = self.get_contours(img_fore)
  File "/home/alex/MAS/CV/project/cv_nxtdrive/src/depth_detection.py", line 107, in get_contours
    cont[0] = DepthDetector.merge_contours(cont[0])
  File "/home/alex/MAS/CV/project/cv_nxtdrive/src/depth_detection.py", line 161, in merge_contours
    return cls.merge_contours(new_cont)
  File "/home/alex/MAS/CV/project/cv_nxtdrive/src/depth_detection.py", line 156, in merge_contours
    i, j, i_pos, j_pos = cls.find_close_conts(cont)
  File "/home/alex/MAS/CV/project/cv_nxtdrive/src/depth_detection.py", line 140, in find_close_conts
    np.save('debug', np.array([list(x.shape) for x in cont]))
ValueError: setting an array element with a sequence.

[rosout][ERROR] 2012-12-15 18:13:24,968: bad callback: <bound method DepthDetector.depth_cb of <__main__.DepthDetector instance at 0x397da28>>
Traceback (most recent call last):
  File "/opt/ros/electric/stacks/ros_comm/clients/rospy/src/rospy/topics.py", line 581, in _invoke_callback
    cb(msg)
  File "/home/alex/MAS/CV/project/cv_nxtdrive/src/depth_detection.py", line 282, in depth_cb
    (contours, img_contours) = self.get_contours(img_fore)
  File "/home/alex/MAS/CV/project/cv_nxtdrive/src/depth_detection.py", line 107, in get_contours
    cont[0] = DepthDetector.merge_contours(cont[0])
  File "/home/alex/MAS/CV/project/cv_nxtdrive/src/depth_detection.py", line 161, in merge_contours
    return cls.merge_contours(new_cont)
  File "/home/alex/MAS/CV/project/cv_nxtdrive/src/depth_detection.py", line 156, in merge_contours
    i, j, i_pos, j_pos = cls.find_close_conts(cont)
  File "/home/alex/MAS/CV/project/cv_nxtdrive/src/depth_detection.py", line 140, in find_close_conts
    np.save('debug', np.array([list(x.shape) for x in cont]))
ValueError: setting an array element with a sequence.

[rosout][ERROR] 2012-12-15 18:13:25,000: bad callback: <bound method DepthDetector.depth_cb of <__main__.DepthDetector instance at 0x397da28>>
Traceback (most recent call last):
  File "/opt/ros/electric/stacks/ros_comm/clients/rospy/src/rospy/topics.py", line 581, in _invoke_callback
    cb(msg)
  File "/home/alex/MAS/CV/project/cv_nxtdrive/src/depth_detection.py", line 282, in depth_cb
    (contours, img_contours) = self.get_contours(img_fore)
  File "/home/alex/MAS/CV/project/cv_nxtdrive/src/depth_detection.py", line 107, in get_contours
    cont[0] = DepthDetector.merge_contours(cont[0])
  File "/home/alex/MAS/CV/project/cv_nxtdrive/src/depth_detection.py", line 161, in merge_contours
    return cls.merge_contours(new_cont)
  File "/home/alex/MAS/CV/project/cv_nxtdrive/src/depth_detection.py", line 156, in merge_contours
    i, j, i_pos, j_pos = cls.find_close_conts(cont)
  File "/home/alex/MAS/CV/project/cv_nxtdrive/src/depth_detection.py", line 140, in find_close_conts
    np.save('debug', np.array([list(x.shape) for x in cont]))
ValueError: setting an array element with a sequence.

[rosout][ERROR] 2012-12-15 18:13:25,039: bad callback: <bound method DepthDetector.depth_cb of <__main__.DepthDetector instance at 0x397da28>>
Traceback (most recent call last):
  File "/opt/ros/electric/stacks/ros_comm/clients/rospy/src/rospy/topics.py", line 581, in _invoke_callback
    cb(msg)
  File "/home/alex/MAS/CV/project/cv_nxtdrive/src/depth_detection.py", line 282, in depth_cb
    (contours, img_contours) = self.get_contours(img_fore)
  File "/home/alex/MAS/CV/project/cv_nxtdrive/src/depth_detection.py", line 107, in get_contours
    cont[0] = DepthDetector.merge_contours(cont[0])
  File "/home/alex/MAS/CV/project/cv_nxtdrive/src/depth_detection.py", line 161, in merge_contours
    return cls.merge_contours(new_cont)
  File "/home/alex/MAS/CV/project/cv_nxtdrive/src/depth_detection.py", line 156, in merge_contours
    i, j, i_pos, j_pos = cls.find_close_conts(cont)
  File "/home/alex/MAS/CV/project/cv_nxtdrive/src/depth_detection.py", line 140, in find_close_conts
    np.save('debug', np.array([list(x.shape) for x in cont]))
ValueError: setting an array element with a sequence.

[rosout][ERROR] 2012-12-15 18:13:25,074: bad callback: <bound method DepthDetector.depth_cb of <__main__.DepthDetector instance at 0x397da28>>
Traceback (most recent call last):
  File "/opt/ros/electric/stacks/ros_comm/clients/rospy/src/rospy/topics.py", line 581, in _invoke_callback
    cb(msg)
  File "/home/alex/MAS/CV/project/cv_nxtdrive/src/depth_detection.py", line 282, in depth_cb
    (contours, img_contours) = self.get_contours(img_fore)
  File "/home/alex/MAS/CV/project/cv_nxtdrive/src/depth_detection.py", line 107, in get_contours
    cont[0] = DepthDetector.merge_contours(cont[0])
  File "/home/alex/MAS/CV/project/cv_nxtdrive/src/depth_detection.py", line 161, in merge_contours
    return cls.merge_contours(new_cont)
  File "/home/alex/MAS/CV/project/cv_nxtdrive/src/depth_detection.py", line 156, in merge_contours
    i, j, i_pos, j_pos = cls.find_close_conts(cont)
  File "/home/alex/MAS/CV/project/cv_nxtdrive/src/depth_detection.py", line 140, in find_close_conts
    np.save('debug', np.array([list(x.shape) for x in cont]))
ValueError: setting an array element with a sequence.

[rosout][ERROR] 2012-12-15 18:13:25,111: bad callback: <bound method DepthDetector.depth_cb of <__main__.DepthDetector instance at 0x397da28>>
Traceback (most recent call last):
  File "/opt/ros/electric/stacks/ros_comm/clients/rospy/src/rospy/topics.py", line 581, in _invoke_callback
    cb(msg)
  File "/home/alex/MAS/CV/project/cv_nxtdrive/src/depth_detection.py", line 282, in depth_cb
    (contours, img_contours) = self.get_contours(img_fore)
  File "/home/alex/MAS/CV/project/cv_nxtdrive/src/depth_detection.py", line 107, in get_contours
    cont[0] = DepthDetector.merge_contours(cont[0])
  File "/home/alex/MAS/CV/project/cv_nxtdrive/src/depth_detection.py", line 161, in merge_contours
    return cls.merge_contours(new_cont)
  File "/home/alex/MAS/CV/project/cv_nxtdrive/src/depth_detection.py", line 156, in merge_contours
    i, j, i_pos, j_pos = cls.find_close_conts(cont)
  File "/home/alex/MAS/CV/project/cv_nxtdrive/src/depth_detection.py", line 140, in find_close_conts
    np.save('debug', np.array([list(x.shape) for x in cont]))
ValueError: setting an array element with a sequence.

[rosout][ERROR] 2012-12-15 18:13:25,149: bad callback: <bound method DepthDetector.depth_cb of <__main__.DepthDetector instance at 0x397da28>>
Traceback (most recent call last):
  File "/opt/ros/electric/stacks/ros_comm/clients/rospy/src/rospy/topics.py", line 581, in _invoke_callback
    cb(msg)
  File "/home/alex/MAS/CV/project/cv_nxtdrive/src/depth_detection.py", line 282, in depth_cb
    (contours, img_contours) = self.get_contours(img_fore)
  File "/home/alex/MAS/CV/project/cv_nxtdrive/src/depth_detection.py", line 107, in get_contours
    cont[0] = DepthDetector.merge_contours(cont[0])
  File "/home/alex/MAS/CV/project/cv_nxtdrive/src/depth_detection.py", line 161, in merge_contours
    return cls.merge_contours(new_cont)
  File "/home/alex/MAS/CV/project/cv_nxtdrive/src/depth_detection.py", line 156, in merge_contours
    i, j, i_pos, j_pos = cls.find_close_conts(cont)
  File "/home/alex/MAS/CV/project/cv_nxtdrive/src/depth_detection.py", line 140, in find_close_conts
    np.save('debug', np.array([list(x.shape) for x in cont]))
ValueError: setting an array element with a sequence.

[rosout][ERROR] 2012-12-15 18:13:25,186: bad callback: <bound method DepthDetector.depth_cb of <__main__.DepthDetector instance at 0x397da28>>
Traceback (most recent call last):
  File "/opt/ros/electric/stacks/ros_comm/clients/rospy/src/rospy/topics.py", line 581, in _invoke_callback
    cb(msg)
  File "/home/alex/MAS/CV/project/cv_nxtdrive/src/depth_detection.py", line 282, in depth_cb
    (contours, img_contours) = self.get_contours(img_fore)
  File "/home/alex/MAS/CV/project/cv_nxtdrive/src/depth_detection.py", line 107, in get_contours
    cont[0] = DepthDetector.merge_contours(cont[0])
  File "/home/alex/MAS/CV/project/cv_nxtdrive/src/depth_detection.py", line 161, in merge_contours
    return cls.merge_contours(new_cont)
  File "/home/alex/MAS/CV/project/cv_nxtdrive/src/depth_detection.py", line 161, in merge_contours
    return cls.merge_contours(new_cont)
  File "/home/alex/MAS/CV/project/cv_nxtdrive/src/depth_detection.py", line 156, in merge_contours
    i, j, i_pos, j_pos = cls.find_close_conts(cont)
  File "/home/alex/MAS/CV/project/cv_nxtdrive/src/depth_detection.py", line 140, in find_close_conts
    np.save('debug', np.array([list(x.shape) for x in cont]))
ValueError: setting an array element with a sequence.

[rosout][ERROR] 2012-12-15 18:13:25,219: bad callback: <bound method DepthDetector.depth_cb of <__main__.DepthDetector instance at 0x397da28>>
Traceback (most recent call last):
  File "/opt/ros/electric/stacks/ros_comm/clients/rospy/src/rospy/topics.py", line 581, in _invoke_callback
    cb(msg)
  File "/home/alex/MAS/CV/project/cv_nxtdrive/src/depth_detection.py", line 282, in depth_cb
    (contours, img_contours) = self.get_contours(img_fore)
  File "/home/alex/MAS/CV/project/cv_nxtdrive/src/depth_detection.py", line 107, in get_contours
    cont[0] = DepthDetector.merge_contours(cont[0])
  File "/home/alex/MAS/CV/project/cv_nxtdrive/src/depth_detection.py", line 161, in merge_contours
    return cls.merge_contours(new_cont)
  File "/home/alex/MAS/CV/project/cv_nxtdrive/src/depth_detection.py", line 156, in merge_contours
    i, j, i_pos, j_pos = cls.find_close_conts(cont)
  File "/home/alex/MAS/CV/project/cv_nxtdrive/src/depth_detection.py", line 140, in find_close_conts
    np.save('debug', np.array([list(x.shape) for x in cont]))
ValueError: setting an array element with a sequence.

[rosout][ERROR] 2012-12-15 18:13:25,252: bad callback: <bound method DepthDetector.depth_cb of <__main__.DepthDetector instance at 0x397da28>>
Traceback (most recent call last):
  File "/opt/ros/electric/stacks/ros_comm/clients/rospy/src/rospy/topics.py", line 581, in _invoke_callback
    cb(msg)
  File "/home/alex/MAS/CV/project/cv_nxtdrive/src/depth_detection.py", line 282, in depth_cb
    (contours, img_contours) = self.get_contours(img_fore)
  File "/home/alex/MAS/CV/project/cv_nxtdrive/src/depth_detection.py", line 107, in get_contours
    cont[0] = DepthDetector.merge_contours(cont[0])
  File "/home/alex/MAS/CV/project/cv_nxtdrive/src/depth_detection.py", line 161, in merge_contours
    return cls.merge_contours(new_cont)
  File "/home/alex/MAS/CV/project/cv_nxtdrive/src/depth_detection.py", line 156, in merge_contours
    i, j, i_pos, j_pos = cls.find_close_conts(cont)
  File "/home/alex/MAS/CV/project/cv_nxtdrive/src/depth_detection.py", line 140, in find_close_conts
    np.save('debug', np.array([list(x.shape) for x in cont]))
ValueError: setting an array element with a sequence.

[rosout][ERROR] 2012-12-15 18:13:25,288: bad callback: <bound method DepthDetector.depth_cb of <__main__.DepthDetector instance at 0x397da28>>
Traceback (most recent call last):
  File "/opt/ros/electric/stacks/ros_comm/clients/rospy/src/rospy/topics.py", line 581, in _invoke_callback
    cb(msg)
  File "/home/alex/MAS/CV/project/cv_nxtdrive/src/depth_detection.py", line 282, in depth_cb
    (contours, img_contours) = self.get_contours(img_fore)
  File "/home/alex/MAS/CV/project/cv_nxtdrive/src/depth_detection.py", line 107, in get_contours
    cont[0] = DepthDetector.merge_contours(cont[0])
  File "/home/alex/MAS/CV/project/cv_nxtdrive/src/depth_detection.py", line 161, in merge_contours
    return cls.merge_contours(new_cont)
  File "/home/alex/MAS/CV/project/cv_nxtdrive/src/depth_detection.py", line 156, in merge_contours
    i, j, i_pos, j_pos = cls.find_close_conts(cont)
  File "/home/alex/MAS/CV/project/cv_nxtdrive/src/depth_detection.py", line 140, in find_close_conts
    np.save('debug', np.array([list(x.shape) for x in cont]))
ValueError: setting an array element with a sequence.

[rosout][ERROR] 2012-12-15 18:13:25,322: bad callback: <bound method DepthDetector.depth_cb of <__main__.DepthDetector instance at 0x397da28>>
Traceback (most recent call last):
  File "/opt/ros/electric/stacks/ros_comm/clients/rospy/src/rospy/topics.py", line 581, in _invoke_callback
    cb(msg)
  File "/home/alex/MAS/CV/project/cv_nxtdrive/src/depth_detection.py", line 282, in depth_cb
    (contours, img_contours) = self.get_contours(img_fore)
  File "/home/alex/MAS/CV/project/cv_nxtdrive/src/depth_detection.py", line 107, in get_contours
    cont[0] = DepthDetector.merge_contours(cont[0])
  File "/home/alex/MAS/CV/project/cv_nxtdrive/src/depth_detection.py", line 161, in merge_contours
    return cls.merge_contours(new_cont)
  File "/home/alex/MAS/CV/project/cv_nxtdrive/src/depth_detection.py", line 161, in merge_contours
    return cls.merge_contours(new_cont)
  File "/home/alex/MAS/CV/project/cv_nxtdrive/src/depth_detection.py", line 156, in merge_contours
    i, j, i_pos, j_pos = cls.find_close_conts(cont)
  File "/home/alex/MAS/CV/project/cv_nxtdrive/src/depth_detection.py", line 140, in find_close_conts
    np.save('debug', np.array([list(x.shape) for x in cont]))
ValueError: setting an array element with a sequence.

[rosout][ERROR] 2012-12-15 18:13:25,360: bad callback: <bound method DepthDetector.depth_cb of <__main__.DepthDetector instance at 0x397da28>>
Traceback (most recent call last):
  File "/opt/ros/electric/stacks/ros_comm/clients/rospy/src/rospy/topics.py", line 581, in _invoke_callback
    cb(msg)
  File "/home/alex/MAS/CV/project/cv_nxtdrive/src/depth_detection.py", line 282, in depth_cb
    (contours, img_contours) = self.get_contours(img_fore)
  File "/home/alex/MAS/CV/project/cv_nxtdrive/src/depth_detection.py", line 107, in get_contours
    cont[0] = DepthDetector.merge_contours(cont[0])
  File "/home/alex/MAS/CV/project/cv_nxtdrive/src/depth_detection.py", line 161, in merge_contours
    return cls.merge_contours(new_cont)
  File "/home/alex/MAS/CV/project/cv_nxtdrive/src/depth_detection.py", line 156, in merge_contours
    i, j, i_pos, j_pos = cls.find_close_conts(cont)
  File "/home/alex/MAS/CV/project/cv_nxtdrive/src/depth_detection.py", line 140, in find_close_conts
    np.save('debug', np.array([list(x.shape) for x in cont]))
ValueError: setting an array element with a sequence.

[rosout][ERROR] 2012-12-15 18:13:25,393: bad callback: <bound method DepthDetector.depth_cb of <__main__.DepthDetector instance at 0x397da28>>
Traceback (most recent call last):
  File "/opt/ros/electric/stacks/ros_comm/clients/rospy/src/rospy/topics.py", line 581, in _invoke_callback
    cb(msg)
  File "/home/alex/MAS/CV/project/cv_nxtdrive/src/depth_detection.py", line 282, in depth_cb
    (contours, img_contours) = self.get_contours(img_fore)
  File "/home/alex/MAS/CV/project/cv_nxtdrive/src/depth_detection.py", line 107, in get_contours
    cont[0] = DepthDetector.merge_contours(cont[0])
  File "/home/alex/MAS/CV/project/cv_nxtdrive/src/depth_detection.py", line 161, in merge_contours
    return cls.merge_contours(new_cont)
  File "/home/alex/MAS/CV/project/cv_nxtdrive/src/depth_detection.py", line 156, in merge_contours
    i, j, i_pos, j_pos = cls.find_close_conts(cont)
  File "/home/alex/MAS/CV/project/cv_nxtdrive/src/depth_detection.py", line 140, in find_close_conts
    np.save('debug', np.array([list(x.shape) for x in cont]))
ValueError: setting an array element with a sequence.

[rosout][ERROR] 2012-12-15 18:13:25,427: bad callback: <bound method DepthDetector.depth_cb of <__main__.DepthDetector instance at 0x397da28>>
Traceback (most recent call last):
  File "/opt/ros/electric/stacks/ros_comm/clients/rospy/src/rospy/topics.py", line 581, in _invoke_callback
    cb(msg)
  File "/home/alex/MAS/CV/project/cv_nxtdrive/src/depth_detection.py", line 282, in depth_cb
    (contours, img_contours) = self.get_contours(img_fore)
  File "/home/alex/MAS/CV/project/cv_nxtdrive/src/depth_detection.py", line 107, in get_contours
    cont[0] = DepthDetector.merge_contours(cont[0])
  File "/home/alex/MAS/CV/project/cv_nxtdrive/src/depth_detection.py", line 161, in merge_contours
    return cls.merge_contours(new_cont)
  File "/home/alex/MAS/CV/project/cv_nxtdrive/src/depth_detection.py", line 156, in merge_contours
    i, j, i_pos, j_pos = cls.find_close_conts(cont)
  File "/home/alex/MAS/CV/project/cv_nxtdrive/src/depth_detection.py", line 140, in find_close_conts
    np.save('debug', np.array([list(x.shape) for x in cont]))
ValueError: setting an array element with a sequence.

[rosout][ERROR] 2012-12-15 18:13:25,461: bad callback: <bound method DepthDetector.depth_cb of <__main__.DepthDetector instance at 0x397da28>>
Traceback (most recent call last):
  File "/opt/ros/electric/stacks/ros_comm/clients/rospy/src/rospy/topics.py", line 581, in _invoke_callback
    cb(msg)
  File "/home/alex/MAS/CV/project/cv_nxtdrive/src/depth_detection.py", line 282, in depth_cb
    (contours, img_contours) = self.get_contours(img_fore)
  File "/home/alex/MAS/CV/project/cv_nxtdrive/src/depth_detection.py", line 107, in get_contours
    cont[0] = DepthDetector.merge_contours(cont[0])
  File "/home/alex/MAS/CV/project/cv_nxtdrive/src/depth_detection.py", line 161, in merge_contours
    return cls.merge_contours(new_cont)
  File "/home/alex/MAS/CV/project/cv_nxtdrive/src/depth_detection.py", line 156, in merge_contours
    i, j, i_pos, j_pos = cls.find_close_conts(cont)
  File "/home/alex/MAS/CV/project/cv_nxtdrive/src/depth_detection.py", line 140, in find_close_conts
    np.save('debug', np.array([list(x.shape) for x in cont]))
ValueError: setting an array element with a sequence.

[rosout][ERROR] 2012-12-15 18:13:25,501: bad callback: <bound method DepthDetector.depth_cb of <__main__.DepthDetector instance at 0x397da28>>
Traceback (most recent call last):
  File "/opt/ros/electric/stacks/ros_comm/clients/rospy/src/rospy/topics.py", line 581, in _invoke_callback
    cb(msg)
  File "/home/alex/MAS/CV/project/cv_nxtdrive/src/depth_detection.py", line 282, in depth_cb
    (contours, img_contours) = self.get_contours(img_fore)
  File "/home/alex/MAS/CV/project/cv_nxtdrive/src/depth_detection.py", line 107, in get_contours
    cont[0] = DepthDetector.merge_contours(cont[0])
  File "/home/alex/MAS/CV/project/cv_nxtdrive/src/depth_detection.py", line 161, in merge_contours
    return cls.merge_contours(new_cont)
  File "/home/alex/MAS/CV/project/cv_nxtdrive/src/depth_detection.py", line 156, in merge_contours
    i, j, i_pos, j_pos = cls.find_close_conts(cont)
  File "/home/alex/MAS/CV/project/cv_nxtdrive/src/depth_detection.py", line 140, in find_close_conts
    np.save('debug', np.array([list(x.shape) for x in cont]))
ValueError: setting an array element with a sequence.

[rosout][ERROR] 2012-12-15 18:13:25,537: bad callback: <bound method DepthDetector.depth_cb of <__main__.DepthDetector instance at 0x397da28>>
Traceback (most recent call last):
  File "/opt/ros/electric/stacks/ros_comm/clients/rospy/src/rospy/topics.py", line 581, in _invoke_callback
    cb(msg)
  File "/home/alex/MAS/CV/project/cv_nxtdrive/src/depth_detection.py", line 282, in depth_cb
    (contours, img_contours) = self.get_contours(img_fore)
  File "/home/alex/MAS/CV/project/cv_nxtdrive/src/depth_detection.py", line 107, in get_contours
    cont[0] = DepthDetector.merge_contours(cont[0])
  File "/home/alex/MAS/CV/project/cv_nxtdrive/src/depth_detection.py", line 161, in merge_contours
    return cls.merge_contours(new_cont)
  File "/home/alex/MAS/CV/project/cv_nxtdrive/src/depth_detection.py", line 156, in merge_contours
    i, j, i_pos, j_pos = cls.find_close_conts(cont)
  File "/home/alex/MAS/CV/project/cv_nxtdrive/src/depth_detection.py", line 140, in find_close_conts
    np.save('debug', np.array([list(x.shape) for x in cont]))
ValueError: setting an array element with a sequence.

[rosout][ERROR] 2012-12-15 18:13:25,567: bad callback: <bound method DepthDetector.depth_cb of <__main__.DepthDetector instance at 0x397da28>>
Traceback (most recent call last):
  File "/opt/ros/electric/stacks/ros_comm/clients/rospy/src/rospy/topics.py", line 581, in _invoke_callback
    cb(msg)
  File "/home/alex/MAS/CV/project/cv_nxtdrive/src/depth_detection.py", line 282, in depth_cb
    (contours, img_contours) = self.get_contours(img_fore)
  File "/home/alex/MAS/CV/project/cv_nxtdrive/src/depth_detection.py", line 107, in get_contours
    cont[0] = DepthDetector.merge_contours(cont[0])
  File "/home/alex/MAS/CV/project/cv_nxtdrive/src/depth_detection.py", line 161, in merge_contours
    return cls.merge_contours(new_cont)
  File "/home/alex/MAS/CV/project/cv_nxtdrive/src/depth_detection.py", line 161, in merge_contours
    return cls.merge_contours(new_cont)
  File "/home/alex/MAS/CV/project/cv_nxtdrive/src/depth_detection.py", line 156, in merge_contours
    i, j, i_pos, j_pos = cls.find_close_conts(cont)
  File "/home/alex/MAS/CV/project/cv_nxtdrive/src/depth_detection.py", line 140, in find_close_conts
    np.save('debug', np.array([list(x.shape) for x in cont]))
ValueError: setting an array element with a sequence.

[rosout][ERROR] 2012-12-15 18:13:25,604: bad callback: <bound method DepthDetector.depth_cb of <__main__.DepthDetector instance at 0x397da28>>
Traceback (most recent call last):
  File "/opt/ros/electric/stacks/ros_comm/clients/rospy/src/rospy/topics.py", line 581, in _invoke_callback
    cb(msg)
  File "/home/alex/MAS/CV/project/cv_nxtdrive/src/depth_detection.py", line 282, in depth_cb
    (contours, img_contours) = self.get_contours(img_fore)
  File "/home/alex/MAS/CV/project/cv_nxtdrive/src/depth_detection.py", line 107, in get_contours
    cont[0] = DepthDetector.merge_contours(cont[0])
  File "/home/alex/MAS/CV/project/cv_nxtdrive/src/depth_detection.py", line 161, in merge_contours
    return cls.merge_contours(new_cont)
  File "/home/alex/MAS/CV/project/cv_nxtdrive/src/depth_detection.py", line 156, in merge_contours
    i, j, i_pos, j_pos = cls.find_close_conts(cont)
  File "/home/alex/MAS/CV/project/cv_nxtdrive/src/depth_detection.py", line 140, in find_close_conts
    np.save('debug', np.array([list(x.shape) for x in cont]))
ValueError: setting an array element with a sequence.

[rosout][ERROR] 2012-12-15 18:13:25,642: bad callback: <bound method DepthDetector.depth_cb of <__main__.DepthDetector instance at 0x397da28>>
Traceback (most recent call last):
  File "/opt/ros/electric/stacks/ros_comm/clients/rospy/src/rospy/topics.py", line 581, in _invoke_callback
    cb(msg)
  File "/home/alex/MAS/CV/project/cv_nxtdrive/src/depth_detection.py", line 282, in depth_cb
    (contours, img_contours) = self.get_contours(img_fore)
  File "/home/alex/MAS/CV/project/cv_nxtdrive/src/depth_detection.py", line 107, in get_contours
    cont[0] = DepthDetector.merge_contours(cont[0])
  File "/home/alex/MAS/CV/project/cv_nxtdrive/src/depth_detection.py", line 161, in merge_contours
    return cls.merge_contours(new_cont)
  File "/home/alex/MAS/CV/project/cv_nxtdrive/src/depth_detection.py", line 156, in merge_contours
    i, j, i_pos, j_pos = cls.find_close_conts(cont)
  File "/home/alex/MAS/CV/project/cv_nxtdrive/src/depth_detection.py", line 140, in find_close_conts
    np.save('debug', np.array([list(x.shape) for x in cont]))
ValueError: setting an array element with a sequence.

[rosout][ERROR] 2012-12-15 18:13:25,679: bad callback: <bound method DepthDetector.depth_cb of <__main__.DepthDetector instance at 0x397da28>>
Traceback (most recent call last):
  File "/opt/ros/electric/stacks/ros_comm/clients/rospy/src/rospy/topics.py", line 581, in _invoke_callback
    cb(msg)
  File "/home/alex/MAS/CV/project/cv_nxtdrive/src/depth_detection.py", line 282, in depth_cb
    (contours, img_contours) = self.get_contours(img_fore)
  File "/home/alex/MAS/CV/project/cv_nxtdrive/src/depth_detection.py", line 107, in get_contours
    cont[0] = DepthDetector.merge_contours(cont[0])
  File "/home/alex/MAS/CV/project/cv_nxtdrive/src/depth_detection.py", line 161, in merge_contours
    return cls.merge_contours(new_cont)
  File "/home/alex/MAS/CV/project/cv_nxtdrive/src/depth_detection.py", line 156, in merge_contours
    i, j, i_pos, j_pos = cls.find_close_conts(cont)
  File "/home/alex/MAS/CV/project/cv_nxtdrive/src/depth_detection.py", line 140, in find_close_conts
    np.save('debug', np.array([list(x.shape) for x in cont]))
ValueError: setting an array element with a sequence.

[rosout][ERROR] 2012-12-15 18:13:25,710: bad callback: <bound method DepthDetector.depth_cb of <__main__.DepthDetector instance at 0x397da28>>
Traceback (most recent call last):
  File "/opt/ros/electric/stacks/ros_comm/clients/rospy/src/rospy/topics.py", line 581, in _invoke_callback
    cb(msg)
  File "/home/alex/MAS/CV/project/cv_nxtdrive/src/depth_detection.py", line 282, in depth_cb
    (contours, img_contours) = self.get_contours(img_fore)
  File "/home/alex/MAS/CV/project/cv_nxtdrive/src/depth_detection.py", line 107, in get_contours
    cont[0] = DepthDetector.merge_contours(cont[0])
  File "/home/alex/MAS/CV/project/cv_nxtdrive/src/depth_detection.py", line 161, in merge_contours
    return cls.merge_contours(new_cont)
  File "/home/alex/MAS/CV/project/cv_nxtdrive/src/depth_detection.py", line 161, in merge_contours
    return cls.merge_contours(new_cont)
  File "/home/alex/MAS/CV/project/cv_nxtdrive/src/depth_detection.py", line 156, in merge_contours
    i, j, i_pos, j_pos = cls.find_close_conts(cont)
  File "/home/alex/MAS/CV/project/cv_nxtdrive/src/depth_detection.py", line 140, in find_close_conts
    np.save('debug', np.array([list(x.shape) for x in cont]))
ValueError: setting an array element with a sequence.

[rosout][ERROR] 2012-12-15 18:13:25,744: bad callback: <bound method DepthDetector.depth_cb of <__main__.DepthDetector instance at 0x397da28>>
Traceback (most recent call last):
  File "/opt/ros/electric/stacks/ros_comm/clients/rospy/src/rospy/topics.py", line 581, in _invoke_callback
    cb(msg)
  File "/home/alex/MAS/CV/project/cv_nxtdrive/src/depth_detection.py", line 282, in depth_cb
    (contours, img_contours) = self.get_contours(img_fore)
  File "/home/alex/MAS/CV/project/cv_nxtdrive/src/depth_detection.py", line 107, in get_contours
    cont[0] = DepthDetector.merge_contours(cont[0])
  File "/home/alex/MAS/CV/project/cv_nxtdrive/src/depth_detection.py", line 161, in merge_contours
    return cls.merge_contours(new_cont)
  File "/home/alex/MAS/CV/project/cv_nxtdrive/src/depth_detection.py", line 156, in merge_contours
    i, j, i_pos, j_pos = cls.find_close_conts(cont)
  File "/home/alex/MAS/CV/project/cv_nxtdrive/src/depth_detection.py", line 140, in find_close_conts
    np.save('debug', np.array([list(x.shape) for x in cont]))
ValueError: setting an array element with a sequence.

[rosout][ERROR] 2012-12-15 18:13:25,778: bad callback: <bound method DepthDetector.depth_cb of <__main__.DepthDetector instance at 0x397da28>>
Traceback (most recent call last):
  File "/opt/ros/electric/stacks/ros_comm/clients/rospy/src/rospy/topics.py", line 581, in _invoke_callback
    cb(msg)
  File "/home/alex/MAS/CV/project/cv_nxtdrive/src/depth_detection.py", line 282, in depth_cb
    (contours, img_contours) = self.get_contours(img_fore)
  File "/home/alex/MAS/CV/project/cv_nxtdrive/src/depth_detection.py", line 107, in get_contours
    cont[0] = DepthDetector.merge_contours(cont[0])
  File "/home/alex/MAS/CV/project/cv_nxtdrive/src/depth_detection.py", line 161, in merge_contours
    return cls.merge_contours(new_cont)
  File "/home/alex/MAS/CV/project/cv_nxtdrive/src/depth_detection.py", line 156, in merge_contours
    i, j, i_pos, j_pos = cls.find_close_conts(cont)
  File "/home/alex/MAS/CV/project/cv_nxtdrive/src/depth_detection.py", line 140, in find_close_conts
    np.save('debug', np.array([list(x.shape) for x in cont]))
ValueError: setting an array element with a sequence.

[rosout][ERROR] 2012-12-15 18:13:25,811: bad callback: <bound method DepthDetector.depth_cb of <__main__.DepthDetector instance at 0x397da28>>
Traceback (most recent call last):
  File "/opt/ros/electric/stacks/ros_comm/clients/rospy/src/rospy/topics.py", line 581, in _invoke_callback
    cb(msg)
  File "/home/alex/MAS/CV/project/cv_nxtdrive/src/depth_detection.py", line 282, in depth_cb
    (contours, img_contours) = self.get_contours(img_fore)
  File "/home/alex/MAS/CV/project/cv_nxtdrive/src/depth_detection.py", line 107, in get_contours
    cont[0] = DepthDetector.merge_contours(cont[0])
  File "/home/alex/MAS/CV/project/cv_nxtdrive/src/depth_detection.py", line 161, in merge_contours
    return cls.merge_contours(new_cont)
  File "/home/alex/MAS/CV/project/cv_nxtdrive/src/depth_detection.py", line 156, in merge_contours
    i, j, i_pos, j_pos = cls.find_close_conts(cont)
  File "/home/alex/MAS/CV/project/cv_nxtdrive/src/depth_detection.py", line 140, in find_close_conts
    np.save('debug', np.array([list(x.shape) for x in cont]))
ValueError: setting an array element with a sequence.

[rosout][ERROR] 2012-12-15 18:13:25,844: bad callback: <bound method DepthDetector.depth_cb of <__main__.DepthDetector instance at 0x397da28>>
Traceback (most recent call last):
  File "/opt/ros/electric/stacks/ros_comm/clients/rospy/src/rospy/topics.py", line 581, in _invoke_callback
    cb(msg)
  File "/home/alex/MAS/CV/project/cv_nxtdrive/src/depth_detection.py", line 282, in depth_cb
    (contours, img_contours) = self.get_contours(img_fore)
  File "/home/alex/MAS/CV/project/cv_nxtdrive/src/depth_detection.py", line 107, in get_contours
    cont[0] = DepthDetector.merge_contours(cont[0])
  File "/home/alex/MAS/CV/project/cv_nxtdrive/src/depth_detection.py", line 161, in merge_contours
    return cls.merge_contours(new_cont)
  File "/home/alex/MAS/CV/project/cv_nxtdrive/src/depth_detection.py", line 156, in merge_contours
    i, j, i_pos, j_pos = cls.find_close_conts(cont)
  File "/home/alex/MAS/CV/project/cv_nxtdrive/src/depth_detection.py", line 140, in find_close_conts
    np.save('debug', np.array([list(x.shape) for x in cont]))
ValueError: setting an array element with a sequence.

[rosout][ERROR] 2012-12-15 18:13:25,887: bad callback: <bound method DepthDetector.depth_cb of <__main__.DepthDetector instance at 0x397da28>>
Traceback (most recent call last):
  File "/opt/ros/electric/stacks/ros_comm/clients/rospy/src/rospy/topics.py", line 581, in _invoke_callback
    cb(msg)
  File "/home/alex/MAS/CV/project/cv_nxtdrive/src/depth_detection.py", line 282, in depth_cb
    (contours, img_contours) = self.get_contours(img_fore)
  File "/home/alex/MAS/CV/project/cv_nxtdrive/src/depth_detection.py", line 107, in get_contours
    cont[0] = DepthDetector.merge_contours(cont[0])
  File "/home/alex/MAS/CV/project/cv_nxtdrive/src/depth_detection.py", line 161, in merge_contours
    return cls.merge_contours(new_cont)
  File "/home/alex/MAS/CV/project/cv_nxtdrive/src/depth_detection.py", line 156, in merge_contours
    i, j, i_pos, j_pos = cls.find_close_conts(cont)
  File "/home/alex/MAS/CV/project/cv_nxtdrive/src/depth_detection.py", line 140, in find_close_conts
    np.save('debug', np.array([list(x.shape) for x in cont]))
ValueError: setting an array element with a sequence.

[rosout][ERROR] 2012-12-15 18:13:25,921: bad callback: <bound method DepthDetector.depth_cb of <__main__.DepthDetector instance at 0x397da28>>
Traceback (most recent call last):
  File "/opt/ros/electric/stacks/ros_comm/clients/rospy/src/rospy/topics.py", line 581, in _invoke_callback
    cb(msg)
  File "/home/alex/MAS/CV/project/cv_nxtdrive/src/depth_detection.py", line 282, in depth_cb
    (contours, img_contours) = self.get_contours(img_fore)
  File "/home/alex/MAS/CV/project/cv_nxtdrive/src/depth_detection.py", line 107, in get_contours
    cont[0] = DepthDetector.merge_contours(cont[0])
  File "/home/alex/MAS/CV/project/cv_nxtdrive/src/depth_detection.py", line 161, in merge_contours
    return cls.merge_contours(new_cont)
  File "/home/alex/MAS/CV/project/cv_nxtdrive/src/depth_detection.py", line 156, in merge_contours
    i, j, i_pos, j_pos = cls.find_close_conts(cont)
  File "/home/alex/MAS/CV/project/cv_nxtdrive/src/depth_detection.py", line 140, in find_close_conts
    np.save('debug', np.array([list(x.shape) for x in cont]))
ValueError: setting an array element with a sequence.

[rosout][ERROR] 2012-12-15 18:13:25,955: bad callback: <bound method DepthDetector.depth_cb of <__main__.DepthDetector instance at 0x397da28>>
Traceback (most recent call last):
  File "/opt/ros/electric/stacks/ros_comm/clients/rospy/src/rospy/topics.py", line 581, in _invoke_callback
    cb(msg)
  File "/home/alex/MAS/CV/project/cv_nxtdrive/src/depth_detection.py", line 282, in depth_cb
    (contours, img_contours) = self.get_contours(img_fore)
  File "/home/alex/MAS/CV/project/cv_nxtdrive/src/depth_detection.py", line 107, in get_contours
    cont[0] = DepthDetector.merge_contours(cont[0])
  File "/home/alex/MAS/CV/project/cv_nxtdrive/src/depth_detection.py", line 161, in merge_contours
    return cls.merge_contours(new_cont)
  File "/home/alex/MAS/CV/project/cv_nxtdrive/src/depth_detection.py", line 156, in merge_contours
    i, j, i_pos, j_pos = cls.find_close_conts(cont)
  File "/home/alex/MAS/CV/project/cv_nxtdrive/src/depth_detection.py", line 140, in find_close_conts
    np.save('debug', np.array([list(x.shape) for x in cont]))
ValueError: setting an array element with a sequence.

[rosout][ERROR] 2012-12-15 18:13:25,988: bad callback: <bound method DepthDetector.depth_cb of <__main__.DepthDetector instance at 0x397da28>>
Traceback (most recent call last):
  File "/opt/ros/electric/stacks/ros_comm/clients/rospy/src/rospy/topics.py", line 581, in _invoke_callback
    cb(msg)
  File "/home/alex/MAS/CV/project/cv_nxtdrive/src/depth_detection.py", line 282, in depth_cb
    (contours, img_contours) = self.get_contours(img_fore)
  File "/home/alex/MAS/CV/project/cv_nxtdrive/src/depth_detection.py", line 107, in get_contours
    cont[0] = DepthDetector.merge_contours(cont[0])
  File "/home/alex/MAS/CV/project/cv_nxtdrive/src/depth_detection.py", line 161, in merge_contours
    return cls.merge_contours(new_cont)
  File "/home/alex/MAS/CV/project/cv_nxtdrive/src/depth_detection.py", line 156, in merge_contours
    i, j, i_pos, j_pos = cls.find_close_conts(cont)
  File "/home/alex/MAS/CV/project/cv_nxtdrive/src/depth_detection.py", line 140, in find_close_conts
    np.save('debug', np.array([list(x.shape) for x in cont]))
ValueError: setting an array element with a sequence.

[rosout][ERROR] 2012-12-15 18:13:26,022: bad callback: <bound method DepthDetector.depth_cb of <__main__.DepthDetector instance at 0x397da28>>
Traceback (most recent call last):
  File "/opt/ros/electric/stacks/ros_comm/clients/rospy/src/rospy/topics.py", line 581, in _invoke_callback
    cb(msg)
  File "/home/alex/MAS/CV/project/cv_nxtdrive/src/depth_detection.py", line 282, in depth_cb
    (contours, img_contours) = self.get_contours(img_fore)
  File "/home/alex/MAS/CV/project/cv_nxtdrive/src/depth_detection.py", line 107, in get_contours
    cont[0] = DepthDetector.merge_contours(cont[0])
  File "/home/alex/MAS/CV/project/cv_nxtdrive/src/depth_detection.py", line 161, in merge_contours
    return cls.merge_contours(new_cont)
  File "/home/alex/MAS/CV/project/cv_nxtdrive/src/depth_detection.py", line 156, in merge_contours
    i, j, i_pos, j_pos = cls.find_close_conts(cont)
  File "/home/alex/MAS/CV/project/cv_nxtdrive/src/depth_detection.py", line 140, in find_close_conts
    np.save('debug', np.array([list(x.shape) for x in cont]))
ValueError: setting an array element with a sequence.

[rosout][ERROR] 2012-12-15 18:13:26,056: bad callback: <bound method DepthDetector.depth_cb of <__main__.DepthDetector instance at 0x397da28>>
Traceback (most recent call last):
  File "/opt/ros/electric/stacks/ros_comm/clients/rospy/src/rospy/topics.py", line 581, in _invoke_callback
    cb(msg)
  File "/home/alex/MAS/CV/project/cv_nxtdrive/src/depth_detection.py", line 282, in depth_cb
    (contours, img_contours) = self.get_contours(img_fore)
  File "/home/alex/MAS/CV/project/cv_nxtdrive/src/depth_detection.py", line 107, in get_contours
    cont[0] = DepthDetector.merge_contours(cont[0])
  File "/home/alex/MAS/CV/project/cv_nxtdrive/src/depth_detection.py", line 161, in merge_contours
    return cls.merge_contours(new_cont)
  File "/home/alex/MAS/CV/project/cv_nxtdrive/src/depth_detection.py", line 156, in merge_contours
    i, j, i_pos, j_pos = cls.find_close_conts(cont)
  File "/home/alex/MAS/CV/project/cv_nxtdrive/src/depth_detection.py", line 140, in find_close_conts
    np.save('debug', np.array([list(x.shape) for x in cont]))
ValueError: setting an array element with a sequence.

[rosout][ERROR] 2012-12-15 18:13:26,091: bad callback: <bound method DepthDetector.depth_cb of <__main__.DepthDetector instance at 0x397da28>>
Traceback (most recent call last):
  File "/opt/ros/electric/stacks/ros_comm/clients/rospy/src/rospy/topics.py", line 581, in _invoke_callback
    cb(msg)
  File "/home/alex/MAS/CV/project/cv_nxtdrive/src/depth_detection.py", line 282, in depth_cb
    (contours, img_contours) = self.get_contours(img_fore)
  File "/home/alex/MAS/CV/project/cv_nxtdrive/src/depth_detection.py", line 107, in get_contours
    cont[0] = DepthDetector.merge_contours(cont[0])
  File "/home/alex/MAS/CV/project/cv_nxtdrive/src/depth_detection.py", line 161, in merge_contours
    return cls.merge_contours(new_cont)
  File "/home/alex/MAS/CV/project/cv_nxtdrive/src/depth_detection.py", line 161, in merge_contours
    return cls.merge_contours(new_cont)
  File "/home/alex/MAS/CV/project/cv_nxtdrive/src/depth_detection.py", line 161, in merge_contours
    return cls.merge_contours(new_cont)
  File "/home/alex/MAS/CV/project/cv_nxtdrive/src/depth_detection.py", line 156, in merge_contours
    i, j, i_pos, j_pos = cls.find_close_conts(cont)
  File "/home/alex/MAS/CV/project/cv_nxtdrive/src/depth_detection.py", line 140, in find_close_conts
    np.save('debug', np.array([list(x.shape) for x in cont]))
ValueError: setting an array element with a sequence.

[rosout][ERROR] 2012-12-15 18:13:26,126: bad callback: <bound method DepthDetector.depth_cb of <__main__.DepthDetector instance at 0x397da28>>
Traceback (most recent call last):
  File "/opt/ros/electric/stacks/ros_comm/clients/rospy/src/rospy/topics.py", line 581, in _invoke_callback
    cb(msg)
  File "/home/alex/MAS/CV/project/cv_nxtdrive/src/depth_detection.py", line 282, in depth_cb
    (contours, img_contours) = self.get_contours(img_fore)
  File "/home/alex/MAS/CV/project/cv_nxtdrive/src/depth_detection.py", line 107, in get_contours
    cont[0] = DepthDetector.merge_contours(cont[0])
  File "/home/alex/MAS/CV/project/cv_nxtdrive/src/depth_detection.py", line 161, in merge_contours
    return cls.merge_contours(new_cont)
  File "/home/alex/MAS/CV/project/cv_nxtdrive/src/depth_detection.py", line 156, in merge_contours
    i, j, i_pos, j_pos = cls.find_close_conts(cont)
  File "/home/alex/MAS/CV/project/cv_nxtdrive/src/depth_detection.py", line 140, in find_close_conts
    np.save('debug', np.array([list(x.shape) for x in cont]))
ValueError: setting an array element with a sequence.

[rosout][ERROR] 2012-12-15 18:13:26,168: bad callback: <bound method DepthDetector.depth_cb of <__main__.DepthDetector instance at 0x397da28>>
Traceback (most recent call last):
  File "/opt/ros/electric/stacks/ros_comm/clients/rospy/src/rospy/topics.py", line 581, in _invoke_callback
    cb(msg)
  File "/home/alex/MAS/CV/project/cv_nxtdrive/src/depth_detection.py", line 282, in depth_cb
    (contours, img_contours) = self.get_contours(img_fore)
  File "/home/alex/MAS/CV/project/cv_nxtdrive/src/depth_detection.py", line 107, in get_contours
    cont[0] = DepthDetector.merge_contours(cont[0])
  File "/home/alex/MAS/CV/project/cv_nxtdrive/src/depth_detection.py", line 161, in merge_contours
    return cls.merge_contours(new_cont)
  File "/home/alex/MAS/CV/project/cv_nxtdrive/src/depth_detection.py", line 156, in merge_contours
    i, j, i_pos, j_pos = cls.find_close_conts(cont)
  File "/home/alex/MAS/CV/project/cv_nxtdrive/src/depth_detection.py", line 140, in find_close_conts
    np.save('debug', np.array([list(x.shape) for x in cont]))
ValueError: setting an array element with a sequence.

[rosout][ERROR] 2012-12-15 18:13:26,202: bad callback: <bound method DepthDetector.depth_cb of <__main__.DepthDetector instance at 0x397da28>>
Traceback (most recent call last):
  File "/opt/ros/electric/stacks/ros_comm/clients/rospy/src/rospy/topics.py", line 581, in _invoke_callback
    cb(msg)
  File "/home/alex/MAS/CV/project/cv_nxtdrive/src/depth_detection.py", line 282, in depth_cb
    (contours, img_contours) = self.get_contours(img_fore)
  File "/home/alex/MAS/CV/project/cv_nxtdrive/src/depth_detection.py", line 107, in get_contours
    cont[0] = DepthDetector.merge_contours(cont[0])
  File "/home/alex/MAS/CV/project/cv_nxtdrive/src/depth_detection.py", line 161, in merge_contours
    return cls.merge_contours(new_cont)
  File "/home/alex/MAS/CV/project/cv_nxtdrive/src/depth_detection.py", line 161, in merge_contours
    return cls.merge_contours(new_cont)
  File "/home/alex/MAS/CV/project/cv_nxtdrive/src/depth_detection.py", line 161, in merge_contours
    return cls.merge_contours(new_cont)
  File "/home/alex/MAS/CV/project/cv_nxtdrive/src/depth_detection.py", line 161, in merge_contours
    return cls.merge_contours(new_cont)
  File "/home/alex/MAS/CV/project/cv_nxtdrive/src/depth_detection.py", line 156, in merge_contours
    i, j, i_pos, j_pos = cls.find_close_conts(cont)
  File "/home/alex/MAS/CV/project/cv_nxtdrive/src/depth_detection.py", line 140, in find_close_conts
    np.save('debug', np.array([list(x.shape) for x in cont]))
ValueError: setting an array element with a sequence.

[rosout][ERROR] 2012-12-15 18:13:26,238: bad callback: <bound method DepthDetector.depth_cb of <__main__.DepthDetector instance at 0x397da28>>
Traceback (most recent call last):
  File "/opt/ros/electric/stacks/ros_comm/clients/rospy/src/rospy/topics.py", line 581, in _invoke_callback
    cb(msg)
  File "/home/alex/MAS/CV/project/cv_nxtdrive/src/depth_detection.py", line 282, in depth_cb
    (contours, img_contours) = self.get_contours(img_fore)
  File "/home/alex/MAS/CV/project/cv_nxtdrive/src/depth_detection.py", line 107, in get_contours
    cont[0] = DepthDetector.merge_contours(cont[0])
  File "/home/alex/MAS/CV/project/cv_nxtdrive/src/depth_detection.py", line 161, in merge_contours
    return cls.merge_contours(new_cont)
  File "/home/alex/MAS/CV/project/cv_nxtdrive/src/depth_detection.py", line 156, in merge_contours
    i, j, i_pos, j_pos = cls.find_close_conts(cont)
  File "/home/alex/MAS/CV/project/cv_nxtdrive/src/depth_detection.py", line 140, in find_close_conts
    np.save('debug', np.array([list(x.shape) for x in cont]))
ValueError: setting an array element with a sequence.

[rosout][ERROR] 2012-12-15 18:13:26,273: bad callback: <bound method DepthDetector.depth_cb of <__main__.DepthDetector instance at 0x397da28>>
Traceback (most recent call last):
  File "/opt/ros/electric/stacks/ros_comm/clients/rospy/src/rospy/topics.py", line 581, in _invoke_callback
    cb(msg)
  File "/home/alex/MAS/CV/project/cv_nxtdrive/src/depth_detection.py", line 282, in depth_cb
    (contours, img_contours) = self.get_contours(img_fore)
  File "/home/alex/MAS/CV/project/cv_nxtdrive/src/depth_detection.py", line 107, in get_contours
    cont[0] = DepthDetector.merge_contours(cont[0])
  File "/home/alex/MAS/CV/project/cv_nxtdrive/src/depth_detection.py", line 161, in merge_contours
    return cls.merge_contours(new_cont)
  File "/home/alex/MAS/CV/project/cv_nxtdrive/src/depth_detection.py", line 156, in merge_contours
    i, j, i_pos, j_pos = cls.find_close_conts(cont)
  File "/home/alex/MAS/CV/project/cv_nxtdrive/src/depth_detection.py", line 140, in find_close_conts
    np.save('debug', np.array([list(x.shape) for x in cont]))
ValueError: setting an array element with a sequence.

[rosout][ERROR] 2012-12-15 18:13:26,315: bad callback: <bound method DepthDetector.depth_cb of <__main__.DepthDetector instance at 0x397da28>>
Traceback (most recent call last):
  File "/opt/ros/electric/stacks/ros_comm/clients/rospy/src/rospy/topics.py", line 581, in _invoke_callback
    cb(msg)
  File "/home/alex/MAS/CV/project/cv_nxtdrive/src/depth_detection.py", line 282, in depth_cb
    (contours, img_contours) = self.get_contours(img_fore)
  File "/home/alex/MAS/CV/project/cv_nxtdrive/src/depth_detection.py", line 107, in get_contours
    cont[0] = DepthDetector.merge_contours(cont[0])
  File "/home/alex/MAS/CV/project/cv_nxtdrive/src/depth_detection.py", line 161, in merge_contours
    return cls.merge_contours(new_cont)
  File "/home/alex/MAS/CV/project/cv_nxtdrive/src/depth_detection.py", line 156, in merge_contours
    i, j, i_pos, j_pos = cls.find_close_conts(cont)
  File "/home/alex/MAS/CV/project/cv_nxtdrive/src/depth_detection.py", line 140, in find_close_conts
    np.save('debug', np.array([list(x.shape) for x in cont]))
ValueError: setting an array element with a sequence.

[rosout][ERROR] 2012-12-15 18:13:26,352: bad callback: <bound method DepthDetector.depth_cb of <__main__.DepthDetector instance at 0x397da28>>
Traceback (most recent call last):
  File "/opt/ros/electric/stacks/ros_comm/clients/rospy/src/rospy/topics.py", line 581, in _invoke_callback
    cb(msg)
  File "/home/alex/MAS/CV/project/cv_nxtdrive/src/depth_detection.py", line 282, in depth_cb
    (contours, img_contours) = self.get_contours(img_fore)
  File "/home/alex/MAS/CV/project/cv_nxtdrive/src/depth_detection.py", line 107, in get_contours
    cont[0] = DepthDetector.merge_contours(cont[0])
  File "/home/alex/MAS/CV/project/cv_nxtdrive/src/depth_detection.py", line 161, in merge_contours
    return cls.merge_contours(new_cont)
  File "/home/alex/MAS/CV/project/cv_nxtdrive/src/depth_detection.py", line 156, in merge_contours
    i, j, i_pos, j_pos = cls.find_close_conts(cont)
  File "/home/alex/MAS/CV/project/cv_nxtdrive/src/depth_detection.py", line 140, in find_close_conts
    np.save('debug', np.array([list(x.shape) for x in cont]))
ValueError: setting an array element with a sequence.

[rosout][ERROR] 2012-12-15 18:13:26,387: bad callback: <bound method DepthDetector.depth_cb of <__main__.DepthDetector instance at 0x397da28>>
Traceback (most recent call last):
  File "/opt/ros/electric/stacks/ros_comm/clients/rospy/src/rospy/topics.py", line 581, in _invoke_callback
    cb(msg)
  File "/home/alex/MAS/CV/project/cv_nxtdrive/src/depth_detection.py", line 282, in depth_cb
    (contours, img_contours) = self.get_contours(img_fore)
  File "/home/alex/MAS/CV/project/cv_nxtdrive/src/depth_detection.py", line 107, in get_contours
    cont[0] = DepthDetector.merge_contours(cont[0])
  File "/home/alex/MAS/CV/project/cv_nxtdrive/src/depth_detection.py", line 161, in merge_contours
    return cls.merge_contours(new_cont)
  File "/home/alex/MAS/CV/project/cv_nxtdrive/src/depth_detection.py", line 156, in merge_contours
    i, j, i_pos, j_pos = cls.find_close_conts(cont)
  File "/home/alex/MAS/CV/project/cv_nxtdrive/src/depth_detection.py", line 140, in find_close_conts
    np.save('debug', np.array([list(x.shape) for x in cont]))
ValueError: setting an array element with a sequence.

[rosout][ERROR] 2012-12-15 18:13:26,423: bad callback: <bound method DepthDetector.depth_cb of <__main__.DepthDetector instance at 0x397da28>>
Traceback (most recent call last):
  File "/opt/ros/electric/stacks/ros_comm/clients/rospy/src/rospy/topics.py", line 581, in _invoke_callback
    cb(msg)
  File "/home/alex/MAS/CV/project/cv_nxtdrive/src/depth_detection.py", line 282, in depth_cb
    (contours, img_contours) = self.get_contours(img_fore)
  File "/home/alex/MAS/CV/project/cv_nxtdrive/src/depth_detection.py", line 107, in get_contours
    cont[0] = DepthDetector.merge_contours(cont[0])
  File "/home/alex/MAS/CV/project/cv_nxtdrive/src/depth_detection.py", line 161, in merge_contours
    return cls.merge_contours(new_cont)
  File "/home/alex/MAS/CV/project/cv_nxtdrive/src/depth_detection.py", line 156, in merge_contours
    i, j, i_pos, j_pos = cls.find_close_conts(cont)
  File "/home/alex/MAS/CV/project/cv_nxtdrive/src/depth_detection.py", line 140, in find_close_conts
    np.save('debug', np.array([list(x.shape) for x in cont]))
ValueError: setting an array element with a sequence.

[rosout][ERROR] 2012-12-15 18:13:26,456: bad callback: <bound method DepthDetector.depth_cb of <__main__.DepthDetector instance at 0x397da28>>
Traceback (most recent call last):
  File "/opt/ros/electric/stacks/ros_comm/clients/rospy/src/rospy/topics.py", line 581, in _invoke_callback
    cb(msg)
  File "/home/alex/MAS/CV/project/cv_nxtdrive/src/depth_detection.py", line 282, in depth_cb
    (contours, img_contours) = self.get_contours(img_fore)
  File "/home/alex/MAS/CV/project/cv_nxtdrive/src/depth_detection.py", line 107, in get_contours
    cont[0] = DepthDetector.merge_contours(cont[0])
  File "/home/alex/MAS/CV/project/cv_nxtdrive/src/depth_detection.py", line 161, in merge_contours
    return cls.merge_contours(new_cont)
  File "/home/alex/MAS/CV/project/cv_nxtdrive/src/depth_detection.py", line 156, in merge_contours
    i, j, i_pos, j_pos = cls.find_close_conts(cont)
  File "/home/alex/MAS/CV/project/cv_nxtdrive/src/depth_detection.py", line 140, in find_close_conts
    np.save('debug', np.array([list(x.shape) for x in cont]))
ValueError: setting an array element with a sequence.

[rosout][ERROR] 2012-12-15 18:13:26,489: bad callback: <bound method DepthDetector.depth_cb of <__main__.DepthDetector instance at 0x397da28>>
Traceback (most recent call last):
  File "/opt/ros/electric/stacks/ros_comm/clients/rospy/src/rospy/topics.py", line 581, in _invoke_callback
    cb(msg)
  File "/home/alex/MAS/CV/project/cv_nxtdrive/src/depth_detection.py", line 282, in depth_cb
    (contours, img_contours) = self.get_contours(img_fore)
  File "/home/alex/MAS/CV/project/cv_nxtdrive/src/depth_detection.py", line 107, in get_contours
    cont[0] = DepthDetector.merge_contours(cont[0])
  File "/home/alex/MAS/CV/project/cv_nxtdrive/src/depth_detection.py", line 161, in merge_contours
    return cls.merge_contours(new_cont)
  File "/home/alex/MAS/CV/project/cv_nxtdrive/src/depth_detection.py", line 156, in merge_contours
    i, j, i_pos, j_pos = cls.find_close_conts(cont)
  File "/home/alex/MAS/CV/project/cv_nxtdrive/src/depth_detection.py", line 140, in find_close_conts
    np.save('debug', np.array([list(x.shape) for x in cont]))
ValueError: setting an array element with a sequence.

[rosout][ERROR] 2012-12-15 18:13:26,524: bad callback: <bound method DepthDetector.depth_cb of <__main__.DepthDetector instance at 0x397da28>>
Traceback (most recent call last):
  File "/opt/ros/electric/stacks/ros_comm/clients/rospy/src/rospy/topics.py", line 581, in _invoke_callback
    cb(msg)
  File "/home/alex/MAS/CV/project/cv_nxtdrive/src/depth_detection.py", line 282, in depth_cb
    (contours, img_contours) = self.get_contours(img_fore)
  File "/home/alex/MAS/CV/project/cv_nxtdrive/src/depth_detection.py", line 107, in get_contours
    cont[0] = DepthDetector.merge_contours(cont[0])
  File "/home/alex/MAS/CV/project/cv_nxtdrive/src/depth_detection.py", line 161, in merge_contours
    return cls.merge_contours(new_cont)
  File "/home/alex/MAS/CV/project/cv_nxtdrive/src/depth_detection.py", line 156, in merge_contours
    i, j, i_pos, j_pos = cls.find_close_conts(cont)
  File "/home/alex/MAS/CV/project/cv_nxtdrive/src/depth_detection.py", line 140, in find_close_conts
    np.save('debug', np.array([list(x.shape) for x in cont]))
ValueError: setting an array element with a sequence.

[rosout][ERROR] 2012-12-15 18:13:26,559: bad callback: <bound method DepthDetector.depth_cb of <__main__.DepthDetector instance at 0x397da28>>
Traceback (most recent call last):
  File "/opt/ros/electric/stacks/ros_comm/clients/rospy/src/rospy/topics.py", line 581, in _invoke_callback
    cb(msg)
  File "/home/alex/MAS/CV/project/cv_nxtdrive/src/depth_detection.py", line 282, in depth_cb
    (contours, img_contours) = self.get_contours(img_fore)
  File "/home/alex/MAS/CV/project/cv_nxtdrive/src/depth_detection.py", line 107, in get_contours
    cont[0] = DepthDetector.merge_contours(cont[0])
  File "/home/alex/MAS/CV/project/cv_nxtdrive/src/depth_detection.py", line 161, in merge_contours
    return cls.merge_contours(new_cont)
  File "/home/alex/MAS/CV/project/cv_nxtdrive/src/depth_detection.py", line 156, in merge_contours
    i, j, i_pos, j_pos = cls.find_close_conts(cont)
  File "/home/alex/MAS/CV/project/cv_nxtdrive/src/depth_detection.py", line 140, in find_close_conts
    np.save('debug', np.array([list(x.shape) for x in cont]))
ValueError: setting an array element with a sequence.

[rosout][ERROR] 2012-12-15 18:13:26,597: bad callback: <bound method DepthDetector.depth_cb of <__main__.DepthDetector instance at 0x397da28>>
Traceback (most recent call last):
  File "/opt/ros/electric/stacks/ros_comm/clients/rospy/src/rospy/topics.py", line 581, in _invoke_callback
    cb(msg)
  File "/home/alex/MAS/CV/project/cv_nxtdrive/src/depth_detection.py", line 282, in depth_cb
    (contours, img_contours) = self.get_contours(img_fore)
  File "/home/alex/MAS/CV/project/cv_nxtdrive/src/depth_detection.py", line 107, in get_contours
    cont[0] = DepthDetector.merge_contours(cont[0])
  File "/home/alex/MAS/CV/project/cv_nxtdrive/src/depth_detection.py", line 161, in merge_contours
    return cls.merge_contours(new_cont)
  File "/home/alex/MAS/CV/project/cv_nxtdrive/src/depth_detection.py", line 156, in merge_contours
    i, j, i_pos, j_pos = cls.find_close_conts(cont)
  File "/home/alex/MAS/CV/project/cv_nxtdrive/src/depth_detection.py", line 140, in find_close_conts
    np.save('debug', np.array([list(x.shape) for x in cont]))
ValueError: setting an array element with a sequence.

[rosout][ERROR] 2012-12-15 18:13:26,636: bad callback: <bound method DepthDetector.depth_cb of <__main__.DepthDetector instance at 0x397da28>>
Traceback (most recent call last):
  File "/opt/ros/electric/stacks/ros_comm/clients/rospy/src/rospy/topics.py", line 581, in _invoke_callback
    cb(msg)
  File "/home/alex/MAS/CV/project/cv_nxtdrive/src/depth_detection.py", line 282, in depth_cb
    (contours, img_contours) = self.get_contours(img_fore)
  File "/home/alex/MAS/CV/project/cv_nxtdrive/src/depth_detection.py", line 107, in get_contours
    cont[0] = DepthDetector.merge_contours(cont[0])
  File "/home/alex/MAS/CV/project/cv_nxtdrive/src/depth_detection.py", line 161, in merge_contours
    return cls.merge_contours(new_cont)
  File "/home/alex/MAS/CV/project/cv_nxtdrive/src/depth_detection.py", line 156, in merge_contours
    i, j, i_pos, j_pos = cls.find_close_conts(cont)
  File "/home/alex/MAS/CV/project/cv_nxtdrive/src/depth_detection.py", line 140, in find_close_conts
    np.save('debug', np.array([list(x.shape) for x in cont]))
ValueError: setting an array element with a sequence.

[rosout][ERROR] 2012-12-15 18:13:26,685: bad callback: <bound method DepthDetector.depth_cb of <__main__.DepthDetector instance at 0x397da28>>
Traceback (most recent call last):
  File "/opt/ros/electric/stacks/ros_comm/clients/rospy/src/rospy/topics.py", line 581, in _invoke_callback
    cb(msg)
  File "/home/alex/MAS/CV/project/cv_nxtdrive/src/depth_detection.py", line 282, in depth_cb
    (contours, img_contours) = self.get_contours(img_fore)
  File "/home/alex/MAS/CV/project/cv_nxtdrive/src/depth_detection.py", line 107, in get_contours
    cont[0] = DepthDetector.merge_contours(cont[0])
  File "/home/alex/MAS/CV/project/cv_nxtdrive/src/depth_detection.py", line 161, in merge_contours
    return cls.merge_contours(new_cont)
  File "/home/alex/MAS/CV/project/cv_nxtdrive/src/depth_detection.py", line 161, in merge_contours
    return cls.merge_contours(new_cont)
  File "/home/alex/MAS/CV/project/cv_nxtdrive/src/depth_detection.py", line 156, in merge_contours
    i, j, i_pos, j_pos = cls.find_close_conts(cont)
  File "/home/alex/MAS/CV/project/cv_nxtdrive/src/depth_detection.py", line 140, in find_close_conts
    np.save('debug', np.array([list(x.shape) for x in cont]))
ValueError: setting an array element with a sequence.

[rosout][ERROR] 2012-12-15 18:13:26,716: bad callback: <bound method DepthDetector.depth_cb of <__main__.DepthDetector instance at 0x397da28>>
Traceback (most recent call last):
  File "/opt/ros/electric/stacks/ros_comm/clients/rospy/src/rospy/topics.py", line 581, in _invoke_callback
    cb(msg)
  File "/home/alex/MAS/CV/project/cv_nxtdrive/src/depth_detection.py", line 282, in depth_cb
    (contours, img_contours) = self.get_contours(img_fore)
  File "/home/alex/MAS/CV/project/cv_nxtdrive/src/depth_detection.py", line 107, in get_contours
    cont[0] = DepthDetector.merge_contours(cont[0])
  File "/home/alex/MAS/CV/project/cv_nxtdrive/src/depth_detection.py", line 161, in merge_contours
    return cls.merge_contours(new_cont)
  File "/home/alex/MAS/CV/project/cv_nxtdrive/src/depth_detection.py", line 156, in merge_contours
    i, j, i_pos, j_pos = cls.find_close_conts(cont)
  File "/home/alex/MAS/CV/project/cv_nxtdrive/src/depth_detection.py", line 140, in find_close_conts
    np.save('debug', np.array([list(x.shape) for x in cont]))
ValueError: setting an array element with a sequence.

[rosout][ERROR] 2012-12-15 18:13:26,753: bad callback: <bound method DepthDetector.depth_cb of <__main__.DepthDetector instance at 0x397da28>>
Traceback (most recent call last):
  File "/opt/ros/electric/stacks/ros_comm/clients/rospy/src/rospy/topics.py", line 581, in _invoke_callback
    cb(msg)
  File "/home/alex/MAS/CV/project/cv_nxtdrive/src/depth_detection.py", line 282, in depth_cb
    (contours, img_contours) = self.get_contours(img_fore)
  File "/home/alex/MAS/CV/project/cv_nxtdrive/src/depth_detection.py", line 107, in get_contours
    cont[0] = DepthDetector.merge_contours(cont[0])
  File "/home/alex/MAS/CV/project/cv_nxtdrive/src/depth_detection.py", line 161, in merge_contours
    return cls.merge_contours(new_cont)
  File "/home/alex/MAS/CV/project/cv_nxtdrive/src/depth_detection.py", line 156, in merge_contours
    i, j, i_pos, j_pos = cls.find_close_conts(cont)
  File "/home/alex/MAS/CV/project/cv_nxtdrive/src/depth_detection.py", line 140, in find_close_conts
    np.save('debug', np.array([list(x.shape) for x in cont]))
ValueError: setting an array element with a sequence.

[rosout][ERROR] 2012-12-15 18:13:26,790: bad callback: <bound method DepthDetector.depth_cb of <__main__.DepthDetector instance at 0x397da28>>
Traceback (most recent call last):
  File "/opt/ros/electric/stacks/ros_comm/clients/rospy/src/rospy/topics.py", line 581, in _invoke_callback
    cb(msg)
  File "/home/alex/MAS/CV/project/cv_nxtdrive/src/depth_detection.py", line 282, in depth_cb
    (contours, img_contours) = self.get_contours(img_fore)
  File "/home/alex/MAS/CV/project/cv_nxtdrive/src/depth_detection.py", line 107, in get_contours
    cont[0] = DepthDetector.merge_contours(cont[0])
  File "/home/alex/MAS/CV/project/cv_nxtdrive/src/depth_detection.py", line 161, in merge_contours
    return cls.merge_contours(new_cont)
  File "/home/alex/MAS/CV/project/cv_nxtdrive/src/depth_detection.py", line 156, in merge_contours
    i, j, i_pos, j_pos = cls.find_close_conts(cont)
  File "/home/alex/MAS/CV/project/cv_nxtdrive/src/depth_detection.py", line 140, in find_close_conts
    np.save('debug', np.array([list(x.shape) for x in cont]))
ValueError: setting an array element with a sequence.

[rosout][ERROR] 2012-12-15 18:13:26,825: bad callback: <bound method DepthDetector.depth_cb of <__main__.DepthDetector instance at 0x397da28>>
Traceback (most recent call last):
  File "/opt/ros/electric/stacks/ros_comm/clients/rospy/src/rospy/topics.py", line 581, in _invoke_callback
    cb(msg)
  File "/home/alex/MAS/CV/project/cv_nxtdrive/src/depth_detection.py", line 282, in depth_cb
    (contours, img_contours) = self.get_contours(img_fore)
  File "/home/alex/MAS/CV/project/cv_nxtdrive/src/depth_detection.py", line 107, in get_contours
    cont[0] = DepthDetector.merge_contours(cont[0])
  File "/home/alex/MAS/CV/project/cv_nxtdrive/src/depth_detection.py", line 161, in merge_contours
    return cls.merge_contours(new_cont)
  File "/home/alex/MAS/CV/project/cv_nxtdrive/src/depth_detection.py", line 156, in merge_contours
    i, j, i_pos, j_pos = cls.find_close_conts(cont)
  File "/home/alex/MAS/CV/project/cv_nxtdrive/src/depth_detection.py", line 140, in find_close_conts
    np.save('debug', np.array([list(x.shape) for x in cont]))
ValueError: setting an array element with a sequence.

[rosout][ERROR] 2012-12-15 18:13:26,856: bad callback: <bound method DepthDetector.depth_cb of <__main__.DepthDetector instance at 0x397da28>>
Traceback (most recent call last):
  File "/opt/ros/electric/stacks/ros_comm/clients/rospy/src/rospy/topics.py", line 581, in _invoke_callback
    cb(msg)
  File "/home/alex/MAS/CV/project/cv_nxtdrive/src/depth_detection.py", line 282, in depth_cb
    (contours, img_contours) = self.get_contours(img_fore)
  File "/home/alex/MAS/CV/project/cv_nxtdrive/src/depth_detection.py", line 107, in get_contours
    cont[0] = DepthDetector.merge_contours(cont[0])
  File "/home/alex/MAS/CV/project/cv_nxtdrive/src/depth_detection.py", line 161, in merge_contours
    return cls.merge_contours(new_cont)
  File "/home/alex/MAS/CV/project/cv_nxtdrive/src/depth_detection.py", line 156, in merge_contours
    i, j, i_pos, j_pos = cls.find_close_conts(cont)
  File "/home/alex/MAS/CV/project/cv_nxtdrive/src/depth_detection.py", line 140, in find_close_conts
    np.save('debug', np.array([list(x.shape) for x in cont]))
ValueError: setting an array element with a sequence.

[rosout][ERROR] 2012-12-15 18:13:26,893: bad callback: <bound method DepthDetector.depth_cb of <__main__.DepthDetector instance at 0x397da28>>
Traceback (most recent call last):
  File "/opt/ros/electric/stacks/ros_comm/clients/rospy/src/rospy/topics.py", line 581, in _invoke_callback
    cb(msg)
  File "/home/alex/MAS/CV/project/cv_nxtdrive/src/depth_detection.py", line 282, in depth_cb
    (contours, img_contours) = self.get_contours(img_fore)
  File "/home/alex/MAS/CV/project/cv_nxtdrive/src/depth_detection.py", line 107, in get_contours
    cont[0] = DepthDetector.merge_contours(cont[0])
  File "/home/alex/MAS/CV/project/cv_nxtdrive/src/depth_detection.py", line 161, in merge_contours
    return cls.merge_contours(new_cont)
  File "/home/alex/MAS/CV/project/cv_nxtdrive/src/depth_detection.py", line 156, in merge_contours
    i, j, i_pos, j_pos = cls.find_close_conts(cont)
  File "/home/alex/MAS/CV/project/cv_nxtdrive/src/depth_detection.py", line 140, in find_close_conts
    np.save('debug', np.array([list(x.shape) for x in cont]))
ValueError: setting an array element with a sequence.

[rosout][ERROR] 2012-12-15 18:13:26,927: bad callback: <bound method DepthDetector.depth_cb of <__main__.DepthDetector instance at 0x397da28>>
Traceback (most recent call last):
  File "/opt/ros/electric/stacks/ros_comm/clients/rospy/src/rospy/topics.py", line 581, in _invoke_callback
    cb(msg)
  File "/home/alex/MAS/CV/project/cv_nxtdrive/src/depth_detection.py", line 282, in depth_cb
    (contours, img_contours) = self.get_contours(img_fore)
  File "/home/alex/MAS/CV/project/cv_nxtdrive/src/depth_detection.py", line 107, in get_contours
    cont[0] = DepthDetector.merge_contours(cont[0])
  File "/home/alex/MAS/CV/project/cv_nxtdrive/src/depth_detection.py", line 161, in merge_contours
    return cls.merge_contours(new_cont)
  File "/home/alex/MAS/CV/project/cv_nxtdrive/src/depth_detection.py", line 156, in merge_contours
    i, j, i_pos, j_pos = cls.find_close_conts(cont)
  File "/home/alex/MAS/CV/project/cv_nxtdrive/src/depth_detection.py", line 140, in find_close_conts
    np.save('debug', np.array([list(x.shape) for x in cont]))
ValueError: setting an array element with a sequence.

[rosout][ERROR] 2012-12-15 18:13:26,959: bad callback: <bound method DepthDetector.depth_cb of <__main__.DepthDetector instance at 0x397da28>>
Traceback (most recent call last):
  File "/opt/ros/electric/stacks/ros_comm/clients/rospy/src/rospy/topics.py", line 581, in _invoke_callback
    cb(msg)
  File "/home/alex/MAS/CV/project/cv_nxtdrive/src/depth_detection.py", line 282, in depth_cb
    (contours, img_contours) = self.get_contours(img_fore)
  File "/home/alex/MAS/CV/project/cv_nxtdrive/src/depth_detection.py", line 107, in get_contours
    cont[0] = DepthDetector.merge_contours(cont[0])
  File "/home/alex/MAS/CV/project/cv_nxtdrive/src/depth_detection.py", line 161, in merge_contours
    return cls.merge_contours(new_cont)
  File "/home/alex/MAS/CV/project/cv_nxtdrive/src/depth_detection.py", line 156, in merge_contours
    i, j, i_pos, j_pos = cls.find_close_conts(cont)
  File "/home/alex/MAS/CV/project/cv_nxtdrive/src/depth_detection.py", line 140, in find_close_conts
    np.save('debug', np.array([list(x.shape) for x in cont]))
ValueError: setting an array element with a sequence.

[rosout][ERROR] 2012-12-15 18:13:26,991: bad callback: <bound method DepthDetector.depth_cb of <__main__.DepthDetector instance at 0x397da28>>
Traceback (most recent call last):
  File "/opt/ros/electric/stacks/ros_comm/clients/rospy/src/rospy/topics.py", line 581, in _invoke_callback
    cb(msg)
  File "/home/alex/MAS/CV/project/cv_nxtdrive/src/depth_detection.py", line 282, in depth_cb
    (contours, img_contours) = self.get_contours(img_fore)
  File "/home/alex/MAS/CV/project/cv_nxtdrive/src/depth_detection.py", line 107, in get_contours
    cont[0] = DepthDetector.merge_contours(cont[0])
  File "/home/alex/MAS/CV/project/cv_nxtdrive/src/depth_detection.py", line 161, in merge_contours
    return cls.merge_contours(new_cont)
  File "/home/alex/MAS/CV/project/cv_nxtdrive/src/depth_detection.py", line 156, in merge_contours
    i, j, i_pos, j_pos = cls.find_close_conts(cont)
  File "/home/alex/MAS/CV/project/cv_nxtdrive/src/depth_detection.py", line 140, in find_close_conts
    np.save('debug', np.array([list(x.shape) for x in cont]))
ValueError: setting an array element with a sequence.

[rosout][ERROR] 2012-12-15 18:13:27,024: bad callback: <bound method DepthDetector.depth_cb of <__main__.DepthDetector instance at 0x397da28>>
Traceback (most recent call last):
  File "/opt/ros/electric/stacks/ros_comm/clients/rospy/src/rospy/topics.py", line 581, in _invoke_callback
    cb(msg)
  File "/home/alex/MAS/CV/project/cv_nxtdrive/src/depth_detection.py", line 282, in depth_cb
    (contours, img_contours) = self.get_contours(img_fore)
  File "/home/alex/MAS/CV/project/cv_nxtdrive/src/depth_detection.py", line 107, in get_contours
    cont[0] = DepthDetector.merge_contours(cont[0])
  File "/home/alex/MAS/CV/project/cv_nxtdrive/src/depth_detection.py", line 161, in merge_contours
    return cls.merge_contours(new_cont)
  File "/home/alex/MAS/CV/project/cv_nxtdrive/src/depth_detection.py", line 156, in merge_contours
    i, j, i_pos, j_pos = cls.find_close_conts(cont)
  File "/home/alex/MAS/CV/project/cv_nxtdrive/src/depth_detection.py", line 140, in find_close_conts
    np.save('debug', np.array([list(x.shape) for x in cont]))
ValueError: setting an array element with a sequence.

[rosout][ERROR] 2012-12-15 18:13:27,055: bad callback: <bound method DepthDetector.depth_cb of <__main__.DepthDetector instance at 0x397da28>>
Traceback (most recent call last):
  File "/opt/ros/electric/stacks/ros_comm/clients/rospy/src/rospy/topics.py", line 581, in _invoke_callback
    cb(msg)
  File "/home/alex/MAS/CV/project/cv_nxtdrive/src/depth_detection.py", line 282, in depth_cb
    (contours, img_contours) = self.get_contours(img_fore)
  File "/home/alex/MAS/CV/project/cv_nxtdrive/src/depth_detection.py", line 107, in get_contours
    cont[0] = DepthDetector.merge_contours(cont[0])
  File "/home/alex/MAS/CV/project/cv_nxtdrive/src/depth_detection.py", line 161, in merge_contours
    return cls.merge_contours(new_cont)
  File "/home/alex/MAS/CV/project/cv_nxtdrive/src/depth_detection.py", line 156, in merge_contours
    i, j, i_pos, j_pos = cls.find_close_conts(cont)
  File "/home/alex/MAS/CV/project/cv_nxtdrive/src/depth_detection.py", line 140, in find_close_conts
    np.save('debug', np.array([list(x.shape) for x in cont]))
ValueError: setting an array element with a sequence.

[rosout][ERROR] 2012-12-15 18:13:27,087: bad callback: <bound method DepthDetector.depth_cb of <__main__.DepthDetector instance at 0x397da28>>
Traceback (most recent call last):
  File "/opt/ros/electric/stacks/ros_comm/clients/rospy/src/rospy/topics.py", line 581, in _invoke_callback
    cb(msg)
  File "/home/alex/MAS/CV/project/cv_nxtdrive/src/depth_detection.py", line 282, in depth_cb
    (contours, img_contours) = self.get_contours(img_fore)
  File "/home/alex/MAS/CV/project/cv_nxtdrive/src/depth_detection.py", line 107, in get_contours
    cont[0] = DepthDetector.merge_contours(cont[0])
  File "/home/alex/MAS/CV/project/cv_nxtdrive/src/depth_detection.py", line 161, in merge_contours
    return cls.merge_contours(new_cont)
  File "/home/alex/MAS/CV/project/cv_nxtdrive/src/depth_detection.py", line 156, in merge_contours
    i, j, i_pos, j_pos = cls.find_close_conts(cont)
  File "/home/alex/MAS/CV/project/cv_nxtdrive/src/depth_detection.py", line 140, in find_close_conts
    np.save('debug', np.array([list(x.shape) for x in cont]))
ValueError: setting an array element with a sequence.

[rosout][ERROR] 2012-12-15 18:13:27,117: bad callback: <bound method DepthDetector.depth_cb of <__main__.DepthDetector instance at 0x397da28>>
Traceback (most recent call last):
  File "/opt/ros/electric/stacks/ros_comm/clients/rospy/src/rospy/topics.py", line 581, in _invoke_callback
    cb(msg)
  File "/home/alex/MAS/CV/project/cv_nxtdrive/src/depth_detection.py", line 282, in depth_cb
    (contours, img_contours) = self.get_contours(img_fore)
  File "/home/alex/MAS/CV/project/cv_nxtdrive/src/depth_detection.py", line 107, in get_contours
    cont[0] = DepthDetector.merge_contours(cont[0])
  File "/home/alex/MAS/CV/project/cv_nxtdrive/src/depth_detection.py", line 161, in merge_contours
    return cls.merge_contours(new_cont)
  File "/home/alex/MAS/CV/project/cv_nxtdrive/src/depth_detection.py", line 161, in merge_contours
    return cls.merge_contours(new_cont)
  File "/home/alex/MAS/CV/project/cv_nxtdrive/src/depth_detection.py", line 156, in merge_contours
    i, j, i_pos, j_pos = cls.find_close_conts(cont)
  File "/home/alex/MAS/CV/project/cv_nxtdrive/src/depth_detection.py", line 140, in find_close_conts
    np.save('debug', np.array([list(x.shape) for x in cont]))
ValueError: setting an array element with a sequence.

[rosout][ERROR] 2012-12-15 18:13:27,158: bad callback: <bound method DepthDetector.depth_cb of <__main__.DepthDetector instance at 0x397da28>>
Traceback (most recent call last):
  File "/opt/ros/electric/stacks/ros_comm/clients/rospy/src/rospy/topics.py", line 581, in _invoke_callback
    cb(msg)
  File "/home/alex/MAS/CV/project/cv_nxtdrive/src/depth_detection.py", line 282, in depth_cb
    (contours, img_contours) = self.get_contours(img_fore)
  File "/home/alex/MAS/CV/project/cv_nxtdrive/src/depth_detection.py", line 107, in get_contours
    cont[0] = DepthDetector.merge_contours(cont[0])
  File "/home/alex/MAS/CV/project/cv_nxtdrive/src/depth_detection.py", line 161, in merge_contours
    return cls.merge_contours(new_cont)
  File "/home/alex/MAS/CV/project/cv_nxtdrive/src/depth_detection.py", line 156, in merge_contours
    i, j, i_pos, j_pos = cls.find_close_conts(cont)
  File "/home/alex/MAS/CV/project/cv_nxtdrive/src/depth_detection.py", line 140, in find_close_conts
    np.save('debug', np.array([list(x.shape) for x in cont]))
ValueError: setting an array element with a sequence.

[rosout][ERROR] 2012-12-15 18:13:27,190: bad callback: <bound method DepthDetector.depth_cb of <__main__.DepthDetector instance at 0x397da28>>
Traceback (most recent call last):
  File "/opt/ros/electric/stacks/ros_comm/clients/rospy/src/rospy/topics.py", line 581, in _invoke_callback
    cb(msg)
  File "/home/alex/MAS/CV/project/cv_nxtdrive/src/depth_detection.py", line 282, in depth_cb
    (contours, img_contours) = self.get_contours(img_fore)
  File "/home/alex/MAS/CV/project/cv_nxtdrive/src/depth_detection.py", line 107, in get_contours
    cont[0] = DepthDetector.merge_contours(cont[0])
  File "/home/alex/MAS/CV/project/cv_nxtdrive/src/depth_detection.py", line 161, in merge_contours
    return cls.merge_contours(new_cont)
  File "/home/alex/MAS/CV/project/cv_nxtdrive/src/depth_detection.py", line 156, in merge_contours
    i, j, i_pos, j_pos = cls.find_close_conts(cont)
  File "/home/alex/MAS/CV/project/cv_nxtdrive/src/depth_detection.py", line 140, in find_close_conts
    np.save('debug', np.array([list(x.shape) for x in cont]))
ValueError: setting an array element with a sequence.

[rosout][ERROR] 2012-12-15 18:13:27,223: bad callback: <bound method DepthDetector.depth_cb of <__main__.DepthDetector instance at 0x397da28>>
Traceback (most recent call last):
  File "/opt/ros/electric/stacks/ros_comm/clients/rospy/src/rospy/topics.py", line 581, in _invoke_callback
    cb(msg)
  File "/home/alex/MAS/CV/project/cv_nxtdrive/src/depth_detection.py", line 282, in depth_cb
    (contours, img_contours) = self.get_contours(img_fore)
  File "/home/alex/MAS/CV/project/cv_nxtdrive/src/depth_detection.py", line 107, in get_contours
    cont[0] = DepthDetector.merge_contours(cont[0])
  File "/home/alex/MAS/CV/project/cv_nxtdrive/src/depth_detection.py", line 161, in merge_contours
    return cls.merge_contours(new_cont)
  File "/home/alex/MAS/CV/project/cv_nxtdrive/src/depth_detection.py", line 156, in merge_contours
    i, j, i_pos, j_pos = cls.find_close_conts(cont)
  File "/home/alex/MAS/CV/project/cv_nxtdrive/src/depth_detection.py", line 140, in find_close_conts
    np.save('debug', np.array([list(x.shape) for x in cont]))
ValueError: setting an array element with a sequence.

[rosout][ERROR] 2012-12-15 18:13:27,253: bad callback: <bound method DepthDetector.depth_cb of <__main__.DepthDetector instance at 0x397da28>>
Traceback (most recent call last):
  File "/opt/ros/electric/stacks/ros_comm/clients/rospy/src/rospy/topics.py", line 581, in _invoke_callback
    cb(msg)
  File "/home/alex/MAS/CV/project/cv_nxtdrive/src/depth_detection.py", line 282, in depth_cb
    (contours, img_contours) = self.get_contours(img_fore)
  File "/home/alex/MAS/CV/project/cv_nxtdrive/src/depth_detection.py", line 107, in get_contours
    cont[0] = DepthDetector.merge_contours(cont[0])
  File "/home/alex/MAS/CV/project/cv_nxtdrive/src/depth_detection.py", line 161, in merge_contours
    return cls.merge_contours(new_cont)
  File "/home/alex/MAS/CV/project/cv_nxtdrive/src/depth_detection.py", line 156, in merge_contours
    i, j, i_pos, j_pos = cls.find_close_conts(cont)
  File "/home/alex/MAS/CV/project/cv_nxtdrive/src/depth_detection.py", line 140, in find_close_conts
    np.save('debug', np.array([list(x.shape) for x in cont]))
ValueError: setting an array element with a sequence.

[rosout][ERROR] 2012-12-15 18:13:27,289: bad callback: <bound method DepthDetector.depth_cb of <__main__.DepthDetector instance at 0x397da28>>
Traceback (most recent call last):
  File "/opt/ros/electric/stacks/ros_comm/clients/rospy/src/rospy/topics.py", line 581, in _invoke_callback
    cb(msg)
  File "/home/alex/MAS/CV/project/cv_nxtdrive/src/depth_detection.py", line 282, in depth_cb
    (contours, img_contours) = self.get_contours(img_fore)
  File "/home/alex/MAS/CV/project/cv_nxtdrive/src/depth_detection.py", line 107, in get_contours
    cont[0] = DepthDetector.merge_contours(cont[0])
  File "/home/alex/MAS/CV/project/cv_nxtdrive/src/depth_detection.py", line 161, in merge_contours
    return cls.merge_contours(new_cont)
  File "/home/alex/MAS/CV/project/cv_nxtdrive/src/depth_detection.py", line 156, in merge_contours
    i, j, i_pos, j_pos = cls.find_close_conts(cont)
  File "/home/alex/MAS/CV/project/cv_nxtdrive/src/depth_detection.py", line 140, in find_close_conts
    np.save('debug', np.array([list(x.shape) for x in cont]))
ValueError: setting an array element with a sequence.

[rosout][ERROR] 2012-12-15 18:13:27,325: bad callback: <bound method DepthDetector.depth_cb of <__main__.DepthDetector instance at 0x397da28>>
Traceback (most recent call last):
  File "/opt/ros/electric/stacks/ros_comm/clients/rospy/src/rospy/topics.py", line 581, in _invoke_callback
    cb(msg)
  File "/home/alex/MAS/CV/project/cv_nxtdrive/src/depth_detection.py", line 282, in depth_cb
    (contours, img_contours) = self.get_contours(img_fore)
  File "/home/alex/MAS/CV/project/cv_nxtdrive/src/depth_detection.py", line 107, in get_contours
    cont[0] = DepthDetector.merge_contours(cont[0])
  File "/home/alex/MAS/CV/project/cv_nxtdrive/src/depth_detection.py", line 161, in merge_contours
    return cls.merge_contours(new_cont)
  File "/home/alex/MAS/CV/project/cv_nxtdrive/src/depth_detection.py", line 156, in merge_contours
    i, j, i_pos, j_pos = cls.find_close_conts(cont)
  File "/home/alex/MAS/CV/project/cv_nxtdrive/src/depth_detection.py", line 140, in find_close_conts
    np.save('debug', np.array([list(x.shape) for x in cont]))
ValueError: setting an array element with a sequence.

[rosout][ERROR] 2012-12-15 18:13:27,359: bad callback: <bound method DepthDetector.depth_cb of <__main__.DepthDetector instance at 0x397da28>>
Traceback (most recent call last):
  File "/opt/ros/electric/stacks/ros_comm/clients/rospy/src/rospy/topics.py", line 581, in _invoke_callback
    cb(msg)
  File "/home/alex/MAS/CV/project/cv_nxtdrive/src/depth_detection.py", line 282, in depth_cb
    (contours, img_contours) = self.get_contours(img_fore)
  File "/home/alex/MAS/CV/project/cv_nxtdrive/src/depth_detection.py", line 107, in get_contours
    cont[0] = DepthDetector.merge_contours(cont[0])
  File "/home/alex/MAS/CV/project/cv_nxtdrive/src/depth_detection.py", line 161, in merge_contours
    return cls.merge_contours(new_cont)
  File "/home/alex/MAS/CV/project/cv_nxtdrive/src/depth_detection.py", line 161, in merge_contours
    return cls.merge_contours(new_cont)
  File "/home/alex/MAS/CV/project/cv_nxtdrive/src/depth_detection.py", line 156, in merge_contours
    i, j, i_pos, j_pos = cls.find_close_conts(cont)
  File "/home/alex/MAS/CV/project/cv_nxtdrive/src/depth_detection.py", line 140, in find_close_conts
    np.save('debug', np.array([list(x.shape) for x in cont]))
ValueError: setting an array element with a sequence.

[rosout][ERROR] 2012-12-15 18:13:27,394: bad callback: <bound method DepthDetector.depth_cb of <__main__.DepthDetector instance at 0x397da28>>
Traceback (most recent call last):
  File "/opt/ros/electric/stacks/ros_comm/clients/rospy/src/rospy/topics.py", line 581, in _invoke_callback
    cb(msg)
  File "/home/alex/MAS/CV/project/cv_nxtdrive/src/depth_detection.py", line 282, in depth_cb
    (contours, img_contours) = self.get_contours(img_fore)
  File "/home/alex/MAS/CV/project/cv_nxtdrive/src/depth_detection.py", line 107, in get_contours
    cont[0] = DepthDetector.merge_contours(cont[0])
  File "/home/alex/MAS/CV/project/cv_nxtdrive/src/depth_detection.py", line 161, in merge_contours
    return cls.merge_contours(new_cont)
  File "/home/alex/MAS/CV/project/cv_nxtdrive/src/depth_detection.py", line 156, in merge_contours
    i, j, i_pos, j_pos = cls.find_close_conts(cont)
  File "/home/alex/MAS/CV/project/cv_nxtdrive/src/depth_detection.py", line 140, in find_close_conts
    np.save('debug', np.array([list(x.shape) for x in cont]))
ValueError: setting an array element with a sequence.

[rosout][ERROR] 2012-12-15 18:13:27,429: bad callback: <bound method DepthDetector.depth_cb of <__main__.DepthDetector instance at 0x397da28>>
Traceback (most recent call last):
  File "/opt/ros/electric/stacks/ros_comm/clients/rospy/src/rospy/topics.py", line 581, in _invoke_callback
    cb(msg)
  File "/home/alex/MAS/CV/project/cv_nxtdrive/src/depth_detection.py", line 282, in depth_cb
    (contours, img_contours) = self.get_contours(img_fore)
  File "/home/alex/MAS/CV/project/cv_nxtdrive/src/depth_detection.py", line 107, in get_contours
    cont[0] = DepthDetector.merge_contours(cont[0])
  File "/home/alex/MAS/CV/project/cv_nxtdrive/src/depth_detection.py", line 161, in merge_contours
    return cls.merge_contours(new_cont)
  File "/home/alex/MAS/CV/project/cv_nxtdrive/src/depth_detection.py", line 161, in merge_contours
    return cls.merge_contours(new_cont)
  File "/home/alex/MAS/CV/project/cv_nxtdrive/src/depth_detection.py", line 156, in merge_contours
    i, j, i_pos, j_pos = cls.find_close_conts(cont)
  File "/home/alex/MAS/CV/project/cv_nxtdrive/src/depth_detection.py", line 140, in find_close_conts
    np.save('debug', np.array([list(x.shape) for x in cont]))
ValueError: setting an array element with a sequence.

[rosout][ERROR] 2012-12-15 18:13:27,468: bad callback: <bound method DepthDetector.depth_cb of <__main__.DepthDetector instance at 0x397da28>>
Traceback (most recent call last):
  File "/opt/ros/electric/stacks/ros_comm/clients/rospy/src/rospy/topics.py", line 581, in _invoke_callback
    cb(msg)
  File "/home/alex/MAS/CV/project/cv_nxtdrive/src/depth_detection.py", line 282, in depth_cb
    (contours, img_contours) = self.get_contours(img_fore)
  File "/home/alex/MAS/CV/project/cv_nxtdrive/src/depth_detection.py", line 107, in get_contours
    cont[0] = DepthDetector.merge_contours(cont[0])
  File "/home/alex/MAS/CV/project/cv_nxtdrive/src/depth_detection.py", line 161, in merge_contours
    return cls.merge_contours(new_cont)
  File "/home/alex/MAS/CV/project/cv_nxtdrive/src/depth_detection.py", line 156, in merge_contours
    i, j, i_pos, j_pos = cls.find_close_conts(cont)
  File "/home/alex/MAS/CV/project/cv_nxtdrive/src/depth_detection.py", line 140, in find_close_conts
    np.save('debug', np.array([list(x.shape) for x in cont]))
ValueError: setting an array element with a sequence.

[rosout][ERROR] 2012-12-15 18:13:27,505: bad callback: <bound method DepthDetector.depth_cb of <__main__.DepthDetector instance at 0x397da28>>
Traceback (most recent call last):
  File "/opt/ros/electric/stacks/ros_comm/clients/rospy/src/rospy/topics.py", line 581, in _invoke_callback
    cb(msg)
  File "/home/alex/MAS/CV/project/cv_nxtdrive/src/depth_detection.py", line 282, in depth_cb
    (contours, img_contours) = self.get_contours(img_fore)
  File "/home/alex/MAS/CV/project/cv_nxtdrive/src/depth_detection.py", line 107, in get_contours
    cont[0] = DepthDetector.merge_contours(cont[0])
  File "/home/alex/MAS/CV/project/cv_nxtdrive/src/depth_detection.py", line 161, in merge_contours
    return cls.merge_contours(new_cont)
  File "/home/alex/MAS/CV/project/cv_nxtdrive/src/depth_detection.py", line 156, in merge_contours
    i, j, i_pos, j_pos = cls.find_close_conts(cont)
  File "/home/alex/MAS/CV/project/cv_nxtdrive/src/depth_detection.py", line 140, in find_close_conts
    np.save('debug', np.array([list(x.shape) for x in cont]))
ValueError: setting an array element with a sequence.

[rosout][ERROR] 2012-12-15 18:13:27,536: bad callback: <bound method DepthDetector.depth_cb of <__main__.DepthDetector instance at 0x397da28>>
Traceback (most recent call last):
  File "/opt/ros/electric/stacks/ros_comm/clients/rospy/src/rospy/topics.py", line 581, in _invoke_callback
    cb(msg)
  File "/home/alex/MAS/CV/project/cv_nxtdrive/src/depth_detection.py", line 282, in depth_cb
    (contours, img_contours) = self.get_contours(img_fore)
  File "/home/alex/MAS/CV/project/cv_nxtdrive/src/depth_detection.py", line 107, in get_contours
    cont[0] = DepthDetector.merge_contours(cont[0])
  File "/home/alex/MAS/CV/project/cv_nxtdrive/src/depth_detection.py", line 161, in merge_contours
    return cls.merge_contours(new_cont)
  File "/home/alex/MAS/CV/project/cv_nxtdrive/src/depth_detection.py", line 161, in merge_contours
    return cls.merge_contours(new_cont)
  File "/home/alex/MAS/CV/project/cv_nxtdrive/src/depth_detection.py", line 156, in merge_contours
    i, j, i_pos, j_pos = cls.find_close_conts(cont)
  File "/home/alex/MAS/CV/project/cv_nxtdrive/src/depth_detection.py", line 140, in find_close_conts
    np.save('debug', np.array([list(x.shape) for x in cont]))
ValueError: setting an array element with a sequence.

[rosout][ERROR] 2012-12-15 18:13:27,568: bad callback: <bound method DepthDetector.depth_cb of <__main__.DepthDetector instance at 0x397da28>>
Traceback (most recent call last):
  File "/opt/ros/electric/stacks/ros_comm/clients/rospy/src/rospy/topics.py", line 581, in _invoke_callback
    cb(msg)
  File "/home/alex/MAS/CV/project/cv_nxtdrive/src/depth_detection.py", line 282, in depth_cb
    (contours, img_contours) = self.get_contours(img_fore)
  File "/home/alex/MAS/CV/project/cv_nxtdrive/src/depth_detection.py", line 107, in get_contours
    cont[0] = DepthDetector.merge_contours(cont[0])
  File "/home/alex/MAS/CV/project/cv_nxtdrive/src/depth_detection.py", line 161, in merge_contours
    return cls.merge_contours(new_cont)
  File "/home/alex/MAS/CV/project/cv_nxtdrive/src/depth_detection.py", line 156, in merge_contours
    i, j, i_pos, j_pos = cls.find_close_conts(cont)
  File "/home/alex/MAS/CV/project/cv_nxtdrive/src/depth_detection.py", line 140, in find_close_conts
    np.save('debug', np.array([list(x.shape) for x in cont]))
ValueError: setting an array element with a sequence.

[rosout][ERROR] 2012-12-15 18:13:27,602: bad callback: <bound method DepthDetector.depth_cb of <__main__.DepthDetector instance at 0x397da28>>
Traceback (most recent call last):
  File "/opt/ros/electric/stacks/ros_comm/clients/rospy/src/rospy/topics.py", line 581, in _invoke_callback
    cb(msg)
  File "/home/alex/MAS/CV/project/cv_nxtdrive/src/depth_detection.py", line 282, in depth_cb
    (contours, img_contours) = self.get_contours(img_fore)
  File "/home/alex/MAS/CV/project/cv_nxtdrive/src/depth_detection.py", line 107, in get_contours
    cont[0] = DepthDetector.merge_contours(cont[0])
  File "/home/alex/MAS/CV/project/cv_nxtdrive/src/depth_detection.py", line 161, in merge_contours
    return cls.merge_contours(new_cont)
  File "/home/alex/MAS/CV/project/cv_nxtdrive/src/depth_detection.py", line 156, in merge_contours
    i, j, i_pos, j_pos = cls.find_close_conts(cont)
  File "/home/alex/MAS/CV/project/cv_nxtdrive/src/depth_detection.py", line 140, in find_close_conts
    np.save('debug', np.array([list(x.shape) for x in cont]))
ValueError: setting an array element with a sequence.

[rosout][ERROR] 2012-12-15 18:13:27,634: bad callback: <bound method DepthDetector.depth_cb of <__main__.DepthDetector instance at 0x397da28>>
Traceback (most recent call last):
  File "/opt/ros/electric/stacks/ros_comm/clients/rospy/src/rospy/topics.py", line 581, in _invoke_callback
    cb(msg)
  File "/home/alex/MAS/CV/project/cv_nxtdrive/src/depth_detection.py", line 282, in depth_cb
    (contours, img_contours) = self.get_contours(img_fore)
  File "/home/alex/MAS/CV/project/cv_nxtdrive/src/depth_detection.py", line 107, in get_contours
    cont[0] = DepthDetector.merge_contours(cont[0])
  File "/home/alex/MAS/CV/project/cv_nxtdrive/src/depth_detection.py", line 161, in merge_contours
    return cls.merge_contours(new_cont)
  File "/home/alex/MAS/CV/project/cv_nxtdrive/src/depth_detection.py", line 156, in merge_contours
    i, j, i_pos, j_pos = cls.find_close_conts(cont)
  File "/home/alex/MAS/CV/project/cv_nxtdrive/src/depth_detection.py", line 140, in find_close_conts
    np.save('debug', np.array([list(x.shape) for x in cont]))
ValueError: setting an array element with a sequence.

[rosout][ERROR] 2012-12-15 18:13:27,667: bad callback: <bound method DepthDetector.depth_cb of <__main__.DepthDetector instance at 0x397da28>>
Traceback (most recent call last):
  File "/opt/ros/electric/stacks/ros_comm/clients/rospy/src/rospy/topics.py", line 581, in _invoke_callback
    cb(msg)
  File "/home/alex/MAS/CV/project/cv_nxtdrive/src/depth_detection.py", line 282, in depth_cb
    (contours, img_contours) = self.get_contours(img_fore)
  File "/home/alex/MAS/CV/project/cv_nxtdrive/src/depth_detection.py", line 107, in get_contours
    cont[0] = DepthDetector.merge_contours(cont[0])
  File "/home/alex/MAS/CV/project/cv_nxtdrive/src/depth_detection.py", line 161, in merge_contours
    return cls.merge_contours(new_cont)
  File "/home/alex/MAS/CV/project/cv_nxtdrive/src/depth_detection.py", line 156, in merge_contours
    i, j, i_pos, j_pos = cls.find_close_conts(cont)
  File "/home/alex/MAS/CV/project/cv_nxtdrive/src/depth_detection.py", line 140, in find_close_conts
    np.save('debug', np.array([list(x.shape) for x in cont]))
ValueError: setting an array element with a sequence.

[rospy.core][INFO] 2012-12-15 18:13:27,692: signal_shutdown [signal-2]
[rospy.impl.masterslave][INFO] 2012-12-15 18:13:27,704: signal-2
[rospy.topics][WARNING] 2012-12-15 18:13:27,709: during shutdown, bad callback: <bound method DepthDetector.depth_cb of <__main__.DepthDetector instance at 0x397da28>>
Traceback (most recent call last):
  File "/opt/ros/electric/stacks/ros_comm/clients/rospy/src/rospy/topics.py", line 581, in _invoke_callback
    cb(msg)
  File "/home/alex/MAS/CV/project/cv_nxtdrive/src/depth_detection.py", line 282, in depth_cb
    (contours, img_contours) = self.get_contours(img_fore)
  File "/home/alex/MAS/CV/project/cv_nxtdrive/src/depth_detection.py", line 107, in get_contours
    cont[0] = DepthDetector.merge_contours(cont[0])
  File "/home/alex/MAS/CV/project/cv_nxtdrive/src/depth_detection.py", line 161, in merge_contours
    return cls.merge_contours(new_cont)
  File "/home/alex/MAS/CV/project/cv_nxtdrive/src/depth_detection.py", line 156, in merge_contours
    i, j, i_pos, j_pos = cls.find_close_conts(cont)
  File "/home/alex/MAS/CV/project/cv_nxtdrive/src/depth_detection.py", line 140, in find_close_conts
    np.save('debug', np.array([list(x.shape) for x in cont]))
ValueError: setting an array element with a sequence.

[rospy.core][INFO] 2012-12-15 18:13:27,821: signal_shutdown [atexit]
