[rospy.client][INFO] 2012-12-15 18:10:56,958: init_node, name[/depth_detection], pid[22765]
[xmlrpc][INFO] 2012-12-15 18:10:56,958: XML-RPC server binding to 0.0.0.0
[xmlrpc][INFO] 2012-12-15 18:10:56,959: Started XML-RPC server [http://pc:50141/]
[rospy.init][INFO] 2012-12-15 18:10:56,959: ROS Slave URI: [http://pc:50141/]
[rospy.impl.masterslave][INFO] 2012-12-15 18:10:56,959: _ready: http://pc:50141/
[rospy.registration][INFO] 2012-12-15 18:10:56,960: Registering with master node http://localhost:11311
[xmlrpc][INFO] 2012-12-15 18:10:56,960: xml rpc node: starting XML-RPC server
[rospy.init][INFO] 2012-12-15 18:10:57,059: registered with master
[rospy.rosout][INFO] 2012-12-15 18:10:57,108: initializing /rosout core topic
[rospy.rosout][INFO] 2012-12-15 18:10:57,111: connected to core topic /rosout
[rospy.simtime][INFO] 2012-12-15 18:10:57,113: /use_sim_time is not set, will not subscribe to simulated time [/clock] topic
[rosout][ERROR] 2012-12-15 18:11:07,806: bad callback: <bound method DepthDetector.depth_cb of <__main__.DepthDetector instance at 0x327aa28>>
Traceback (most recent call last):
  File "/opt/ros/electric/stacks/ros_comm/clients/rospy/src/rospy/topics.py", line 581, in _invoke_callback
    cb(msg)
  File "/home/alex/MAS/CV/project/cv_nxtdrive/src/depth_detection.py", line 282, in depth_cb
    (contours, img_contours) = self.get_contours(img_fore)
  File "/home/alex/MAS/CV/project/cv_nxtdrive/src/depth_detection.py", line 107, in get_contours
    cont[0] = DepthDetector.merge_contours(cont[0])
  File "/home/alex/MAS/CV/project/cv_nxtdrive/src/depth_detection.py", line 161, in merge_contours
    return cls.merge_contours(new_cont)
  File "/home/alex/MAS/CV/project/cv_nxtdrive/src/depth_detection.py", line 156, in merge_contours
    i, j, i_pos, j_pos = cls.find_close_conts(cont)
  File "/home/alex/MAS/CV/project/cv_nxtdrive/src/depth_detection.py", line 140, in find_close_conts
    np.save('debug', np.array( [x.shape for x in cont]))
ValueError: setting an array element with a sequence.

[rosout][ERROR] 2012-12-15 18:11:07,841: bad callback: <bound method DepthDetector.depth_cb of <__main__.DepthDetector instance at 0x327aa28>>
Traceback (most recent call last):
  File "/opt/ros/electric/stacks/ros_comm/clients/rospy/src/rospy/topics.py", line 581, in _invoke_callback
    cb(msg)
  File "/home/alex/MAS/CV/project/cv_nxtdrive/src/depth_detection.py", line 282, in depth_cb
    (contours, img_contours) = self.get_contours(img_fore)
  File "/home/alex/MAS/CV/project/cv_nxtdrive/src/depth_detection.py", line 107, in get_contours
    cont[0] = DepthDetector.merge_contours(cont[0])
  File "/home/alex/MAS/CV/project/cv_nxtdrive/src/depth_detection.py", line 161, in merge_contours
    return cls.merge_contours(new_cont)
  File "/home/alex/MAS/CV/project/cv_nxtdrive/src/depth_detection.py", line 156, in merge_contours
    i, j, i_pos, j_pos = cls.find_close_conts(cont)
  File "/home/alex/MAS/CV/project/cv_nxtdrive/src/depth_detection.py", line 140, in find_close_conts
    np.save('debug', np.array( [x.shape for x in cont]))
ValueError: setting an array element with a sequence.

[rosout][ERROR] 2012-12-15 18:11:07,879: bad callback: <bound method DepthDetector.depth_cb of <__main__.DepthDetector instance at 0x327aa28>>
Traceback (most recent call last):
  File "/opt/ros/electric/stacks/ros_comm/clients/rospy/src/rospy/topics.py", line 581, in _invoke_callback
    cb(msg)
  File "/home/alex/MAS/CV/project/cv_nxtdrive/src/depth_detection.py", line 282, in depth_cb
    (contours, img_contours) = self.get_contours(img_fore)
  File "/home/alex/MAS/CV/project/cv_nxtdrive/src/depth_detection.py", line 107, in get_contours
    cont[0] = DepthDetector.merge_contours(cont[0])
  File "/home/alex/MAS/CV/project/cv_nxtdrive/src/depth_detection.py", line 161, in merge_contours
    return cls.merge_contours(new_cont)
  File "/home/alex/MAS/CV/project/cv_nxtdrive/src/depth_detection.py", line 156, in merge_contours
    i, j, i_pos, j_pos = cls.find_close_conts(cont)
  File "/home/alex/MAS/CV/project/cv_nxtdrive/src/depth_detection.py", line 140, in find_close_conts
    np.save('debug', np.array( [x.shape for x in cont]))
ValueError: setting an array element with a sequence.

[rosout][ERROR] 2012-12-15 18:11:07,915: bad callback: <bound method DepthDetector.depth_cb of <__main__.DepthDetector instance at 0x327aa28>>
Traceback (most recent call last):
  File "/opt/ros/electric/stacks/ros_comm/clients/rospy/src/rospy/topics.py", line 581, in _invoke_callback
    cb(msg)
  File "/home/alex/MAS/CV/project/cv_nxtdrive/src/depth_detection.py", line 282, in depth_cb
    (contours, img_contours) = self.get_contours(img_fore)
  File "/home/alex/MAS/CV/project/cv_nxtdrive/src/depth_detection.py", line 107, in get_contours
    cont[0] = DepthDetector.merge_contours(cont[0])
  File "/home/alex/MAS/CV/project/cv_nxtdrive/src/depth_detection.py", line 161, in merge_contours
    return cls.merge_contours(new_cont)
  File "/home/alex/MAS/CV/project/cv_nxtdrive/src/depth_detection.py", line 161, in merge_contours
    return cls.merge_contours(new_cont)
  File "/home/alex/MAS/CV/project/cv_nxtdrive/src/depth_detection.py", line 156, in merge_contours
    i, j, i_pos, j_pos = cls.find_close_conts(cont)
  File "/home/alex/MAS/CV/project/cv_nxtdrive/src/depth_detection.py", line 140, in find_close_conts
    np.save('debug', np.array( [x.shape for x in cont]))
ValueError: setting an array element with a sequence.

[rosout][ERROR] 2012-12-15 18:11:07,951: bad callback: <bound method DepthDetector.depth_cb of <__main__.DepthDetector instance at 0x327aa28>>
Traceback (most recent call last):
  File "/opt/ros/electric/stacks/ros_comm/clients/rospy/src/rospy/topics.py", line 581, in _invoke_callback
    cb(msg)
  File "/home/alex/MAS/CV/project/cv_nxtdrive/src/depth_detection.py", line 282, in depth_cb
    (contours, img_contours) = self.get_contours(img_fore)
  File "/home/alex/MAS/CV/project/cv_nxtdrive/src/depth_detection.py", line 107, in get_contours
    cont[0] = DepthDetector.merge_contours(cont[0])
  File "/home/alex/MAS/CV/project/cv_nxtdrive/src/depth_detection.py", line 161, in merge_contours
    return cls.merge_contours(new_cont)
  File "/home/alex/MAS/CV/project/cv_nxtdrive/src/depth_detection.py", line 156, in merge_contours
    i, j, i_pos, j_pos = cls.find_close_conts(cont)
  File "/home/alex/MAS/CV/project/cv_nxtdrive/src/depth_detection.py", line 140, in find_close_conts
    np.save('debug', np.array( [x.shape for x in cont]))
ValueError: setting an array element with a sequence.

[rosout][ERROR] 2012-12-15 18:11:07,984: bad callback: <bound method DepthDetector.depth_cb of <__main__.DepthDetector instance at 0x327aa28>>
Traceback (most recent call last):
  File "/opt/ros/electric/stacks/ros_comm/clients/rospy/src/rospy/topics.py", line 581, in _invoke_callback
    cb(msg)
  File "/home/alex/MAS/CV/project/cv_nxtdrive/src/depth_detection.py", line 282, in depth_cb
    (contours, img_contours) = self.get_contours(img_fore)
  File "/home/alex/MAS/CV/project/cv_nxtdrive/src/depth_detection.py", line 107, in get_contours
    cont[0] = DepthDetector.merge_contours(cont[0])
  File "/home/alex/MAS/CV/project/cv_nxtdrive/src/depth_detection.py", line 161, in merge_contours
    return cls.merge_contours(new_cont)
  File "/home/alex/MAS/CV/project/cv_nxtdrive/src/depth_detection.py", line 156, in merge_contours
    i, j, i_pos, j_pos = cls.find_close_conts(cont)
  File "/home/alex/MAS/CV/project/cv_nxtdrive/src/depth_detection.py", line 140, in find_close_conts
    np.save('debug', np.array( [x.shape for x in cont]))
ValueError: setting an array element with a sequence.

[rosout][ERROR] 2012-12-15 18:11:08,016: bad callback: <bound method DepthDetector.depth_cb of <__main__.DepthDetector instance at 0x327aa28>>
Traceback (most recent call last):
  File "/opt/ros/electric/stacks/ros_comm/clients/rospy/src/rospy/topics.py", line 581, in _invoke_callback
    cb(msg)
  File "/home/alex/MAS/CV/project/cv_nxtdrive/src/depth_detection.py", line 282, in depth_cb
    (contours, img_contours) = self.get_contours(img_fore)
  File "/home/alex/MAS/CV/project/cv_nxtdrive/src/depth_detection.py", line 107, in get_contours
    cont[0] = DepthDetector.merge_contours(cont[0])
  File "/home/alex/MAS/CV/project/cv_nxtdrive/src/depth_detection.py", line 161, in merge_contours
    return cls.merge_contours(new_cont)
  File "/home/alex/MAS/CV/project/cv_nxtdrive/src/depth_detection.py", line 161, in merge_contours
    return cls.merge_contours(new_cont)
  File "/home/alex/MAS/CV/project/cv_nxtdrive/src/depth_detection.py", line 156, in merge_contours
    i, j, i_pos, j_pos = cls.find_close_conts(cont)
  File "/home/alex/MAS/CV/project/cv_nxtdrive/src/depth_detection.py", line 140, in find_close_conts
    np.save('debug', np.array( [x.shape for x in cont]))
ValueError: setting an array element with a sequence.

[rosout][ERROR] 2012-12-15 18:11:08,044: bad callback: <bound method DepthDetector.depth_cb of <__main__.DepthDetector instance at 0x327aa28>>
Traceback (most recent call last):
  File "/opt/ros/electric/stacks/ros_comm/clients/rospy/src/rospy/topics.py", line 581, in _invoke_callback
    cb(msg)
  File "/home/alex/MAS/CV/project/cv_nxtdrive/src/depth_detection.py", line 282, in depth_cb
    (contours, img_contours) = self.get_contours(img_fore)
  File "/home/alex/MAS/CV/project/cv_nxtdrive/src/depth_detection.py", line 107, in get_contours
    cont[0] = DepthDetector.merge_contours(cont[0])
  File "/home/alex/MAS/CV/project/cv_nxtdrive/src/depth_detection.py", line 161, in merge_contours
    return cls.merge_contours(new_cont)
  File "/home/alex/MAS/CV/project/cv_nxtdrive/src/depth_detection.py", line 156, in merge_contours
    i, j, i_pos, j_pos = cls.find_close_conts(cont)
  File "/home/alex/MAS/CV/project/cv_nxtdrive/src/depth_detection.py", line 140, in find_close_conts
    np.save('debug', np.array( [x.shape for x in cont]))
ValueError: setting an array element with a sequence.

[rosout][ERROR] 2012-12-15 18:11:08,079: bad callback: <bound method DepthDetector.depth_cb of <__main__.DepthDetector instance at 0x327aa28>>
Traceback (most recent call last):
  File "/opt/ros/electric/stacks/ros_comm/clients/rospy/src/rospy/topics.py", line 581, in _invoke_callback
    cb(msg)
  File "/home/alex/MAS/CV/project/cv_nxtdrive/src/depth_detection.py", line 282, in depth_cb
    (contours, img_contours) = self.get_contours(img_fore)
  File "/home/alex/MAS/CV/project/cv_nxtdrive/src/depth_detection.py", line 107, in get_contours
    cont[0] = DepthDetector.merge_contours(cont[0])
  File "/home/alex/MAS/CV/project/cv_nxtdrive/src/depth_detection.py", line 161, in merge_contours
    return cls.merge_contours(new_cont)
  File "/home/alex/MAS/CV/project/cv_nxtdrive/src/depth_detection.py", line 156, in merge_contours
    i, j, i_pos, j_pos = cls.find_close_conts(cont)
  File "/home/alex/MAS/CV/project/cv_nxtdrive/src/depth_detection.py", line 140, in find_close_conts
    np.save('debug', np.array( [x.shape for x in cont]))
ValueError: setting an array element with a sequence.

[rosout][ERROR] 2012-12-15 18:11:08,111: bad callback: <bound method DepthDetector.depth_cb of <__main__.DepthDetector instance at 0x327aa28>>
Traceback (most recent call last):
  File "/opt/ros/electric/stacks/ros_comm/clients/rospy/src/rospy/topics.py", line 581, in _invoke_callback
    cb(msg)
  File "/home/alex/MAS/CV/project/cv_nxtdrive/src/depth_detection.py", line 282, in depth_cb
    (contours, img_contours) = self.get_contours(img_fore)
  File "/home/alex/MAS/CV/project/cv_nxtdrive/src/depth_detection.py", line 107, in get_contours
    cont[0] = DepthDetector.merge_contours(cont[0])
  File "/home/alex/MAS/CV/project/cv_nxtdrive/src/depth_detection.py", line 161, in merge_contours
    return cls.merge_contours(new_cont)
  File "/home/alex/MAS/CV/project/cv_nxtdrive/src/depth_detection.py", line 156, in merge_contours
    i, j, i_pos, j_pos = cls.find_close_conts(cont)
  File "/home/alex/MAS/CV/project/cv_nxtdrive/src/depth_detection.py", line 140, in find_close_conts
    np.save('debug', np.array( [x.shape for x in cont]))
ValueError: setting an array element with a sequence.

[rosout][ERROR] 2012-12-15 18:11:08,144: bad callback: <bound method DepthDetector.depth_cb of <__main__.DepthDetector instance at 0x327aa28>>
Traceback (most recent call last):
  File "/opt/ros/electric/stacks/ros_comm/clients/rospy/src/rospy/topics.py", line 581, in _invoke_callback
    cb(msg)
  File "/home/alex/MAS/CV/project/cv_nxtdrive/src/depth_detection.py", line 282, in depth_cb
    (contours, img_contours) = self.get_contours(img_fore)
  File "/home/alex/MAS/CV/project/cv_nxtdrive/src/depth_detection.py", line 107, in get_contours
    cont[0] = DepthDetector.merge_contours(cont[0])
  File "/home/alex/MAS/CV/project/cv_nxtdrive/src/depth_detection.py", line 161, in merge_contours
    return cls.merge_contours(new_cont)
  File "/home/alex/MAS/CV/project/cv_nxtdrive/src/depth_detection.py", line 156, in merge_contours
    i, j, i_pos, j_pos = cls.find_close_conts(cont)
  File "/home/alex/MAS/CV/project/cv_nxtdrive/src/depth_detection.py", line 140, in find_close_conts
    np.save('debug', np.array( [x.shape for x in cont]))
ValueError: setting an array element with a sequence.

[rosout][ERROR] 2012-12-15 18:11:08,175: bad callback: <bound method DepthDetector.depth_cb of <__main__.DepthDetector instance at 0x327aa28>>
Traceback (most recent call last):
  File "/opt/ros/electric/stacks/ros_comm/clients/rospy/src/rospy/topics.py", line 581, in _invoke_callback
    cb(msg)
  File "/home/alex/MAS/CV/project/cv_nxtdrive/src/depth_detection.py", line 282, in depth_cb
    (contours, img_contours) = self.get_contours(img_fore)
  File "/home/alex/MAS/CV/project/cv_nxtdrive/src/depth_detection.py", line 107, in get_contours
    cont[0] = DepthDetector.merge_contours(cont[0])
  File "/home/alex/MAS/CV/project/cv_nxtdrive/src/depth_detection.py", line 161, in merge_contours
    return cls.merge_contours(new_cont)
  File "/home/alex/MAS/CV/project/cv_nxtdrive/src/depth_detection.py", line 156, in merge_contours
    i, j, i_pos, j_pos = cls.find_close_conts(cont)
  File "/home/alex/MAS/CV/project/cv_nxtdrive/src/depth_detection.py", line 140, in find_close_conts
    np.save('debug', np.array( [x.shape for x in cont]))
ValueError: setting an array element with a sequence.

[rosout][ERROR] 2012-12-15 18:11:08,212: bad callback: <bound method DepthDetector.depth_cb of <__main__.DepthDetector instance at 0x327aa28>>
Traceback (most recent call last):
  File "/opt/ros/electric/stacks/ros_comm/clients/rospy/src/rospy/topics.py", line 581, in _invoke_callback
    cb(msg)
  File "/home/alex/MAS/CV/project/cv_nxtdrive/src/depth_detection.py", line 282, in depth_cb
    (contours, img_contours) = self.get_contours(img_fore)
  File "/home/alex/MAS/CV/project/cv_nxtdrive/src/depth_detection.py", line 107, in get_contours
    cont[0] = DepthDetector.merge_contours(cont[0])
  File "/home/alex/MAS/CV/project/cv_nxtdrive/src/depth_detection.py", line 161, in merge_contours
    return cls.merge_contours(new_cont)
  File "/home/alex/MAS/CV/project/cv_nxtdrive/src/depth_detection.py", line 156, in merge_contours
    i, j, i_pos, j_pos = cls.find_close_conts(cont)
  File "/home/alex/MAS/CV/project/cv_nxtdrive/src/depth_detection.py", line 140, in find_close_conts
    np.save('debug', np.array( [x.shape for x in cont]))
ValueError: setting an array element with a sequence.

[rosout][ERROR] 2012-12-15 18:11:08,247: bad callback: <bound method DepthDetector.depth_cb of <__main__.DepthDetector instance at 0x327aa28>>
Traceback (most recent call last):
  File "/opt/ros/electric/stacks/ros_comm/clients/rospy/src/rospy/topics.py", line 581, in _invoke_callback
    cb(msg)
  File "/home/alex/MAS/CV/project/cv_nxtdrive/src/depth_detection.py", line 282, in depth_cb
    (contours, img_contours) = self.get_contours(img_fore)
  File "/home/alex/MAS/CV/project/cv_nxtdrive/src/depth_detection.py", line 107, in get_contours
    cont[0] = DepthDetector.merge_contours(cont[0])
  File "/home/alex/MAS/CV/project/cv_nxtdrive/src/depth_detection.py", line 161, in merge_contours
    return cls.merge_contours(new_cont)
  File "/home/alex/MAS/CV/project/cv_nxtdrive/src/depth_detection.py", line 156, in merge_contours
    i, j, i_pos, j_pos = cls.find_close_conts(cont)
  File "/home/alex/MAS/CV/project/cv_nxtdrive/src/depth_detection.py", line 140, in find_close_conts
    np.save('debug', np.array( [x.shape for x in cont]))
ValueError: setting an array element with a sequence.

[rosout][ERROR] 2012-12-15 18:11:08,287: bad callback: <bound method DepthDetector.depth_cb of <__main__.DepthDetector instance at 0x327aa28>>
Traceback (most recent call last):
  File "/opt/ros/electric/stacks/ros_comm/clients/rospy/src/rospy/topics.py", line 581, in _invoke_callback
    cb(msg)
  File "/home/alex/MAS/CV/project/cv_nxtdrive/src/depth_detection.py", line 282, in depth_cb
    (contours, img_contours) = self.get_contours(img_fore)
  File "/home/alex/MAS/CV/project/cv_nxtdrive/src/depth_detection.py", line 107, in get_contours
    cont[0] = DepthDetector.merge_contours(cont[0])
  File "/home/alex/MAS/CV/project/cv_nxtdrive/src/depth_detection.py", line 161, in merge_contours
    return cls.merge_contours(new_cont)
  File "/home/alex/MAS/CV/project/cv_nxtdrive/src/depth_detection.py", line 156, in merge_contours
    i, j, i_pos, j_pos = cls.find_close_conts(cont)
  File "/home/alex/MAS/CV/project/cv_nxtdrive/src/depth_detection.py", line 140, in find_close_conts
    np.save('debug', np.array( [x.shape for x in cont]))
ValueError: setting an array element with a sequence.

[rosout][ERROR] 2012-12-15 18:11:08,322: bad callback: <bound method DepthDetector.depth_cb of <__main__.DepthDetector instance at 0x327aa28>>
Traceback (most recent call last):
  File "/opt/ros/electric/stacks/ros_comm/clients/rospy/src/rospy/topics.py", line 581, in _invoke_callback
    cb(msg)
  File "/home/alex/MAS/CV/project/cv_nxtdrive/src/depth_detection.py", line 282, in depth_cb
    (contours, img_contours) = self.get_contours(img_fore)
  File "/home/alex/MAS/CV/project/cv_nxtdrive/src/depth_detection.py", line 107, in get_contours
    cont[0] = DepthDetector.merge_contours(cont[0])
  File "/home/alex/MAS/CV/project/cv_nxtdrive/src/depth_detection.py", line 161, in merge_contours
    return cls.merge_contours(new_cont)
  File "/home/alex/MAS/CV/project/cv_nxtdrive/src/depth_detection.py", line 156, in merge_contours
    i, j, i_pos, j_pos = cls.find_close_conts(cont)
  File "/home/alex/MAS/CV/project/cv_nxtdrive/src/depth_detection.py", line 140, in find_close_conts
    np.save('debug', np.array( [x.shape for x in cont]))
ValueError: setting an array element with a sequence.

[rosout][ERROR] 2012-12-15 18:11:08,356: bad callback: <bound method DepthDetector.depth_cb of <__main__.DepthDetector instance at 0x327aa28>>
Traceback (most recent call last):
  File "/opt/ros/electric/stacks/ros_comm/clients/rospy/src/rospy/topics.py", line 581, in _invoke_callback
    cb(msg)
  File "/home/alex/MAS/CV/project/cv_nxtdrive/src/depth_detection.py", line 282, in depth_cb
    (contours, img_contours) = self.get_contours(img_fore)
  File "/home/alex/MAS/CV/project/cv_nxtdrive/src/depth_detection.py", line 107, in get_contours
    cont[0] = DepthDetector.merge_contours(cont[0])
  File "/home/alex/MAS/CV/project/cv_nxtdrive/src/depth_detection.py", line 161, in merge_contours
    return cls.merge_contours(new_cont)
  File "/home/alex/MAS/CV/project/cv_nxtdrive/src/depth_detection.py", line 156, in merge_contours
    i, j, i_pos, j_pos = cls.find_close_conts(cont)
  File "/home/alex/MAS/CV/project/cv_nxtdrive/src/depth_detection.py", line 140, in find_close_conts
    np.save('debug', np.array( [x.shape for x in cont]))
ValueError: setting an array element with a sequence.

[rosout][ERROR] 2012-12-15 18:11:08,397: bad callback: <bound method DepthDetector.depth_cb of <__main__.DepthDetector instance at 0x327aa28>>
Traceback (most recent call last):
  File "/opt/ros/electric/stacks/ros_comm/clients/rospy/src/rospy/topics.py", line 581, in _invoke_callback
    cb(msg)
  File "/home/alex/MAS/CV/project/cv_nxtdrive/src/depth_detection.py", line 282, in depth_cb
    (contours, img_contours) = self.get_contours(img_fore)
  File "/home/alex/MAS/CV/project/cv_nxtdrive/src/depth_detection.py", line 107, in get_contours
    cont[0] = DepthDetector.merge_contours(cont[0])
  File "/home/alex/MAS/CV/project/cv_nxtdrive/src/depth_detection.py", line 161, in merge_contours
    return cls.merge_contours(new_cont)
  File "/home/alex/MAS/CV/project/cv_nxtdrive/src/depth_detection.py", line 156, in merge_contours
    i, j, i_pos, j_pos = cls.find_close_conts(cont)
  File "/home/alex/MAS/CV/project/cv_nxtdrive/src/depth_detection.py", line 140, in find_close_conts
    np.save('debug', np.array( [x.shape for x in cont]))
ValueError: setting an array element with a sequence.

[rosout][ERROR] 2012-12-15 18:11:08,437: bad callback: <bound method DepthDetector.depth_cb of <__main__.DepthDetector instance at 0x327aa28>>
Traceback (most recent call last):
  File "/opt/ros/electric/stacks/ros_comm/clients/rospy/src/rospy/topics.py", line 581, in _invoke_callback
    cb(msg)
  File "/home/alex/MAS/CV/project/cv_nxtdrive/src/depth_detection.py", line 282, in depth_cb
    (contours, img_contours) = self.get_contours(img_fore)
  File "/home/alex/MAS/CV/project/cv_nxtdrive/src/depth_detection.py", line 107, in get_contours
    cont[0] = DepthDetector.merge_contours(cont[0])
  File "/home/alex/MAS/CV/project/cv_nxtdrive/src/depth_detection.py", line 161, in merge_contours
    return cls.merge_contours(new_cont)
  File "/home/alex/MAS/CV/project/cv_nxtdrive/src/depth_detection.py", line 156, in merge_contours
    i, j, i_pos, j_pos = cls.find_close_conts(cont)
  File "/home/alex/MAS/CV/project/cv_nxtdrive/src/depth_detection.py", line 140, in find_close_conts
    np.save('debug', np.array( [x.shape for x in cont]))
ValueError: setting an array element with a sequence.

[rosout][ERROR] 2012-12-15 18:11:08,472: bad callback: <bound method DepthDetector.depth_cb of <__main__.DepthDetector instance at 0x327aa28>>
Traceback (most recent call last):
  File "/opt/ros/electric/stacks/ros_comm/clients/rospy/src/rospy/topics.py", line 581, in _invoke_callback
    cb(msg)
  File "/home/alex/MAS/CV/project/cv_nxtdrive/src/depth_detection.py", line 282, in depth_cb
    (contours, img_contours) = self.get_contours(img_fore)
  File "/home/alex/MAS/CV/project/cv_nxtdrive/src/depth_detection.py", line 107, in get_contours
    cont[0] = DepthDetector.merge_contours(cont[0])
  File "/home/alex/MAS/CV/project/cv_nxtdrive/src/depth_detection.py", line 161, in merge_contours
    return cls.merge_contours(new_cont)
  File "/home/alex/MAS/CV/project/cv_nxtdrive/src/depth_detection.py", line 156, in merge_contours
    i, j, i_pos, j_pos = cls.find_close_conts(cont)
  File "/home/alex/MAS/CV/project/cv_nxtdrive/src/depth_detection.py", line 140, in find_close_conts
    np.save('debug', np.array( [x.shape for x in cont]))
ValueError: setting an array element with a sequence.

[rosout][ERROR] 2012-12-15 18:11:08,504: bad callback: <bound method DepthDetector.depth_cb of <__main__.DepthDetector instance at 0x327aa28>>
Traceback (most recent call last):
  File "/opt/ros/electric/stacks/ros_comm/clients/rospy/src/rospy/topics.py", line 581, in _invoke_callback
    cb(msg)
  File "/home/alex/MAS/CV/project/cv_nxtdrive/src/depth_detection.py", line 282, in depth_cb
    (contours, img_contours) = self.get_contours(img_fore)
  File "/home/alex/MAS/CV/project/cv_nxtdrive/src/depth_detection.py", line 107, in get_contours
    cont[0] = DepthDetector.merge_contours(cont[0])
  File "/home/alex/MAS/CV/project/cv_nxtdrive/src/depth_detection.py", line 161, in merge_contours
    return cls.merge_contours(new_cont)
  File "/home/alex/MAS/CV/project/cv_nxtdrive/src/depth_detection.py", line 156, in merge_contours
    i, j, i_pos, j_pos = cls.find_close_conts(cont)
  File "/home/alex/MAS/CV/project/cv_nxtdrive/src/depth_detection.py", line 140, in find_close_conts
    np.save('debug', np.array( [x.shape for x in cont]))
ValueError: setting an array element with a sequence.

[rosout][ERROR] 2012-12-15 18:11:08,537: bad callback: <bound method DepthDetector.depth_cb of <__main__.DepthDetector instance at 0x327aa28>>
Traceback (most recent call last):
  File "/opt/ros/electric/stacks/ros_comm/clients/rospy/src/rospy/topics.py", line 581, in _invoke_callback
    cb(msg)
  File "/home/alex/MAS/CV/project/cv_nxtdrive/src/depth_detection.py", line 282, in depth_cb
    (contours, img_contours) = self.get_contours(img_fore)
  File "/home/alex/MAS/CV/project/cv_nxtdrive/src/depth_detection.py", line 107, in get_contours
    cont[0] = DepthDetector.merge_contours(cont[0])
  File "/home/alex/MAS/CV/project/cv_nxtdrive/src/depth_detection.py", line 161, in merge_contours
    return cls.merge_contours(new_cont)
  File "/home/alex/MAS/CV/project/cv_nxtdrive/src/depth_detection.py", line 156, in merge_contours
    i, j, i_pos, j_pos = cls.find_close_conts(cont)
  File "/home/alex/MAS/CV/project/cv_nxtdrive/src/depth_detection.py", line 140, in find_close_conts
    np.save('debug', np.array( [x.shape for x in cont]))
ValueError: setting an array element with a sequence.

[rosout][ERROR] 2012-12-15 18:11:08,570: bad callback: <bound method DepthDetector.depth_cb of <__main__.DepthDetector instance at 0x327aa28>>
Traceback (most recent call last):
  File "/opt/ros/electric/stacks/ros_comm/clients/rospy/src/rospy/topics.py", line 581, in _invoke_callback
    cb(msg)
  File "/home/alex/MAS/CV/project/cv_nxtdrive/src/depth_detection.py", line 282, in depth_cb
    (contours, img_contours) = self.get_contours(img_fore)
  File "/home/alex/MAS/CV/project/cv_nxtdrive/src/depth_detection.py", line 107, in get_contours
    cont[0] = DepthDetector.merge_contours(cont[0])
  File "/home/alex/MAS/CV/project/cv_nxtdrive/src/depth_detection.py", line 161, in merge_contours
    return cls.merge_contours(new_cont)
  File "/home/alex/MAS/CV/project/cv_nxtdrive/src/depth_detection.py", line 156, in merge_contours
    i, j, i_pos, j_pos = cls.find_close_conts(cont)
  File "/home/alex/MAS/CV/project/cv_nxtdrive/src/depth_detection.py", line 140, in find_close_conts
    np.save('debug', np.array( [x.shape for x in cont]))
ValueError: setting an array element with a sequence.

[rosout][ERROR] 2012-12-15 18:11:08,604: bad callback: <bound method DepthDetector.depth_cb of <__main__.DepthDetector instance at 0x327aa28>>
Traceback (most recent call last):
  File "/opt/ros/electric/stacks/ros_comm/clients/rospy/src/rospy/topics.py", line 581, in _invoke_callback
    cb(msg)
  File "/home/alex/MAS/CV/project/cv_nxtdrive/src/depth_detection.py", line 282, in depth_cb
    (contours, img_contours) = self.get_contours(img_fore)
  File "/home/alex/MAS/CV/project/cv_nxtdrive/src/depth_detection.py", line 107, in get_contours
    cont[0] = DepthDetector.merge_contours(cont[0])
  File "/home/alex/MAS/CV/project/cv_nxtdrive/src/depth_detection.py", line 161, in merge_contours
    return cls.merge_contours(new_cont)
  File "/home/alex/MAS/CV/project/cv_nxtdrive/src/depth_detection.py", line 156, in merge_contours
    i, j, i_pos, j_pos = cls.find_close_conts(cont)
  File "/home/alex/MAS/CV/project/cv_nxtdrive/src/depth_detection.py", line 140, in find_close_conts
    np.save('debug', np.array( [x.shape for x in cont]))
ValueError: setting an array element with a sequence.

[rosout][ERROR] 2012-12-15 18:11:08,646: bad callback: <bound method DepthDetector.depth_cb of <__main__.DepthDetector instance at 0x327aa28>>
Traceback (most recent call last):
  File "/opt/ros/electric/stacks/ros_comm/clients/rospy/src/rospy/topics.py", line 581, in _invoke_callback
    cb(msg)
  File "/home/alex/MAS/CV/project/cv_nxtdrive/src/depth_detection.py", line 282, in depth_cb
    (contours, img_contours) = self.get_contours(img_fore)
  File "/home/alex/MAS/CV/project/cv_nxtdrive/src/depth_detection.py", line 107, in get_contours
    cont[0] = DepthDetector.merge_contours(cont[0])
  File "/home/alex/MAS/CV/project/cv_nxtdrive/src/depth_detection.py", line 161, in merge_contours
    return cls.merge_contours(new_cont)
  File "/home/alex/MAS/CV/project/cv_nxtdrive/src/depth_detection.py", line 156, in merge_contours
    i, j, i_pos, j_pos = cls.find_close_conts(cont)
  File "/home/alex/MAS/CV/project/cv_nxtdrive/src/depth_detection.py", line 140, in find_close_conts
    np.save('debug', np.array( [x.shape for x in cont]))
ValueError: setting an array element with a sequence.

[rosout][ERROR] 2012-12-15 18:11:08,680: bad callback: <bound method DepthDetector.depth_cb of <__main__.DepthDetector instance at 0x327aa28>>
Traceback (most recent call last):
  File "/opt/ros/electric/stacks/ros_comm/clients/rospy/src/rospy/topics.py", line 581, in _invoke_callback
    cb(msg)
  File "/home/alex/MAS/CV/project/cv_nxtdrive/src/depth_detection.py", line 282, in depth_cb
    (contours, img_contours) = self.get_contours(img_fore)
  File "/home/alex/MAS/CV/project/cv_nxtdrive/src/depth_detection.py", line 107, in get_contours
    cont[0] = DepthDetector.merge_contours(cont[0])
  File "/home/alex/MAS/CV/project/cv_nxtdrive/src/depth_detection.py", line 161, in merge_contours
    return cls.merge_contours(new_cont)
  File "/home/alex/MAS/CV/project/cv_nxtdrive/src/depth_detection.py", line 156, in merge_contours
    i, j, i_pos, j_pos = cls.find_close_conts(cont)
  File "/home/alex/MAS/CV/project/cv_nxtdrive/src/depth_detection.py", line 140, in find_close_conts
    np.save('debug', np.array( [x.shape for x in cont]))
ValueError: setting an array element with a sequence.

[rosout][ERROR] 2012-12-15 18:11:08,715: bad callback: <bound method DepthDetector.depth_cb of <__main__.DepthDetector instance at 0x327aa28>>
Traceback (most recent call last):
  File "/opt/ros/electric/stacks/ros_comm/clients/rospy/src/rospy/topics.py", line 581, in _invoke_callback
    cb(msg)
  File "/home/alex/MAS/CV/project/cv_nxtdrive/src/depth_detection.py", line 282, in depth_cb
    (contours, img_contours) = self.get_contours(img_fore)
  File "/home/alex/MAS/CV/project/cv_nxtdrive/src/depth_detection.py", line 107, in get_contours
    cont[0] = DepthDetector.merge_contours(cont[0])
  File "/home/alex/MAS/CV/project/cv_nxtdrive/src/depth_detection.py", line 161, in merge_contours
    return cls.merge_contours(new_cont)
  File "/home/alex/MAS/CV/project/cv_nxtdrive/src/depth_detection.py", line 156, in merge_contours
    i, j, i_pos, j_pos = cls.find_close_conts(cont)
  File "/home/alex/MAS/CV/project/cv_nxtdrive/src/depth_detection.py", line 140, in find_close_conts
    np.save('debug', np.array( [x.shape for x in cont]))
ValueError: setting an array element with a sequence.

[rosout][ERROR] 2012-12-15 18:11:08,749: bad callback: <bound method DepthDetector.depth_cb of <__main__.DepthDetector instance at 0x327aa28>>
Traceback (most recent call last):
  File "/opt/ros/electric/stacks/ros_comm/clients/rospy/src/rospy/topics.py", line 581, in _invoke_callback
    cb(msg)
  File "/home/alex/MAS/CV/project/cv_nxtdrive/src/depth_detection.py", line 282, in depth_cb
    (contours, img_contours) = self.get_contours(img_fore)
  File "/home/alex/MAS/CV/project/cv_nxtdrive/src/depth_detection.py", line 107, in get_contours
    cont[0] = DepthDetector.merge_contours(cont[0])
  File "/home/alex/MAS/CV/project/cv_nxtdrive/src/depth_detection.py", line 161, in merge_contours
    return cls.merge_contours(new_cont)
  File "/home/alex/MAS/CV/project/cv_nxtdrive/src/depth_detection.py", line 161, in merge_contours
    return cls.merge_contours(new_cont)
  File "/home/alex/MAS/CV/project/cv_nxtdrive/src/depth_detection.py", line 156, in merge_contours
    i, j, i_pos, j_pos = cls.find_close_conts(cont)
  File "/home/alex/MAS/CV/project/cv_nxtdrive/src/depth_detection.py", line 140, in find_close_conts
    np.save('debug', np.array( [x.shape for x in cont]))
ValueError: setting an array element with a sequence.

[rosout][ERROR] 2012-12-15 18:11:08,784: bad callback: <bound method DepthDetector.depth_cb of <__main__.DepthDetector instance at 0x327aa28>>
Traceback (most recent call last):
  File "/opt/ros/electric/stacks/ros_comm/clients/rospy/src/rospy/topics.py", line 581, in _invoke_callback
    cb(msg)
  File "/home/alex/MAS/CV/project/cv_nxtdrive/src/depth_detection.py", line 282, in depth_cb
    (contours, img_contours) = self.get_contours(img_fore)
  File "/home/alex/MAS/CV/project/cv_nxtdrive/src/depth_detection.py", line 107, in get_contours
    cont[0] = DepthDetector.merge_contours(cont[0])
  File "/home/alex/MAS/CV/project/cv_nxtdrive/src/depth_detection.py", line 161, in merge_contours
    return cls.merge_contours(new_cont)
  File "/home/alex/MAS/CV/project/cv_nxtdrive/src/depth_detection.py", line 161, in merge_contours
    return cls.merge_contours(new_cont)
  File "/home/alex/MAS/CV/project/cv_nxtdrive/src/depth_detection.py", line 156, in merge_contours
    i, j, i_pos, j_pos = cls.find_close_conts(cont)
  File "/home/alex/MAS/CV/project/cv_nxtdrive/src/depth_detection.py", line 140, in find_close_conts
    np.save('debug', np.array( [x.shape for x in cont]))
ValueError: setting an array element with a sequence.

[rosout][ERROR] 2012-12-15 18:11:08,820: bad callback: <bound method DepthDetector.depth_cb of <__main__.DepthDetector instance at 0x327aa28>>
Traceback (most recent call last):
  File "/opt/ros/electric/stacks/ros_comm/clients/rospy/src/rospy/topics.py", line 581, in _invoke_callback
    cb(msg)
  File "/home/alex/MAS/CV/project/cv_nxtdrive/src/depth_detection.py", line 282, in depth_cb
    (contours, img_contours) = self.get_contours(img_fore)
  File "/home/alex/MAS/CV/project/cv_nxtdrive/src/depth_detection.py", line 107, in get_contours
    cont[0] = DepthDetector.merge_contours(cont[0])
  File "/home/alex/MAS/CV/project/cv_nxtdrive/src/depth_detection.py", line 161, in merge_contours
    return cls.merge_contours(new_cont)
  File "/home/alex/MAS/CV/project/cv_nxtdrive/src/depth_detection.py", line 156, in merge_contours
    i, j, i_pos, j_pos = cls.find_close_conts(cont)
  File "/home/alex/MAS/CV/project/cv_nxtdrive/src/depth_detection.py", line 140, in find_close_conts
    np.save('debug', np.array( [x.shape for x in cont]))
ValueError: setting an array element with a sequence.

[rosout][ERROR] 2012-12-15 18:11:08,856: bad callback: <bound method DepthDetector.depth_cb of <__main__.DepthDetector instance at 0x327aa28>>
Traceback (most recent call last):
  File "/opt/ros/electric/stacks/ros_comm/clients/rospy/src/rospy/topics.py", line 581, in _invoke_callback
    cb(msg)
  File "/home/alex/MAS/CV/project/cv_nxtdrive/src/depth_detection.py", line 282, in depth_cb
    (contours, img_contours) = self.get_contours(img_fore)
  File "/home/alex/MAS/CV/project/cv_nxtdrive/src/depth_detection.py", line 107, in get_contours
    cont[0] = DepthDetector.merge_contours(cont[0])
  File "/home/alex/MAS/CV/project/cv_nxtdrive/src/depth_detection.py", line 161, in merge_contours
    return cls.merge_contours(new_cont)
  File "/home/alex/MAS/CV/project/cv_nxtdrive/src/depth_detection.py", line 156, in merge_contours
    i, j, i_pos, j_pos = cls.find_close_conts(cont)
  File "/home/alex/MAS/CV/project/cv_nxtdrive/src/depth_detection.py", line 140, in find_close_conts
    np.save('debug', np.array( [x.shape for x in cont]))
ValueError: setting an array element with a sequence.

[rosout][ERROR] 2012-12-15 18:11:08,887: bad callback: <bound method DepthDetector.depth_cb of <__main__.DepthDetector instance at 0x327aa28>>
Traceback (most recent call last):
  File "/opt/ros/electric/stacks/ros_comm/clients/rospy/src/rospy/topics.py", line 581, in _invoke_callback
    cb(msg)
  File "/home/alex/MAS/CV/project/cv_nxtdrive/src/depth_detection.py", line 282, in depth_cb
    (contours, img_contours) = self.get_contours(img_fore)
  File "/home/alex/MAS/CV/project/cv_nxtdrive/src/depth_detection.py", line 107, in get_contours
    cont[0] = DepthDetector.merge_contours(cont[0])
  File "/home/alex/MAS/CV/project/cv_nxtdrive/src/depth_detection.py", line 161, in merge_contours
    return cls.merge_contours(new_cont)
  File "/home/alex/MAS/CV/project/cv_nxtdrive/src/depth_detection.py", line 156, in merge_contours
    i, j, i_pos, j_pos = cls.find_close_conts(cont)
  File "/home/alex/MAS/CV/project/cv_nxtdrive/src/depth_detection.py", line 140, in find_close_conts
    np.save('debug', np.array( [x.shape for x in cont]))
ValueError: setting an array element with a sequence.

[rosout][ERROR] 2012-12-15 18:11:08,919: bad callback: <bound method DepthDetector.depth_cb of <__main__.DepthDetector instance at 0x327aa28>>
Traceback (most recent call last):
  File "/opt/ros/electric/stacks/ros_comm/clients/rospy/src/rospy/topics.py", line 581, in _invoke_callback
    cb(msg)
  File "/home/alex/MAS/CV/project/cv_nxtdrive/src/depth_detection.py", line 282, in depth_cb
    (contours, img_contours) = self.get_contours(img_fore)
  File "/home/alex/MAS/CV/project/cv_nxtdrive/src/depth_detection.py", line 107, in get_contours
    cont[0] = DepthDetector.merge_contours(cont[0])
  File "/home/alex/MAS/CV/project/cv_nxtdrive/src/depth_detection.py", line 161, in merge_contours
    return cls.merge_contours(new_cont)
  File "/home/alex/MAS/CV/project/cv_nxtdrive/src/depth_detection.py", line 156, in merge_contours
    i, j, i_pos, j_pos = cls.find_close_conts(cont)
  File "/home/alex/MAS/CV/project/cv_nxtdrive/src/depth_detection.py", line 140, in find_close_conts
    np.save('debug', np.array( [x.shape for x in cont]))
ValueError: setting an array element with a sequence.

[rosout][ERROR] 2012-12-15 18:11:08,962: bad callback: <bound method DepthDetector.depth_cb of <__main__.DepthDetector instance at 0x327aa28>>
Traceback (most recent call last):
  File "/opt/ros/electric/stacks/ros_comm/clients/rospy/src/rospy/topics.py", line 581, in _invoke_callback
    cb(msg)
  File "/home/alex/MAS/CV/project/cv_nxtdrive/src/depth_detection.py", line 282, in depth_cb
    (contours, img_contours) = self.get_contours(img_fore)
  File "/home/alex/MAS/CV/project/cv_nxtdrive/src/depth_detection.py", line 107, in get_contours
    cont[0] = DepthDetector.merge_contours(cont[0])
  File "/home/alex/MAS/CV/project/cv_nxtdrive/src/depth_detection.py", line 161, in merge_contours
    return cls.merge_contours(new_cont)
  File "/home/alex/MAS/CV/project/cv_nxtdrive/src/depth_detection.py", line 156, in merge_contours
    i, j, i_pos, j_pos = cls.find_close_conts(cont)
  File "/home/alex/MAS/CV/project/cv_nxtdrive/src/depth_detection.py", line 140, in find_close_conts
    np.save('debug', np.array( [x.shape for x in cont]))
ValueError: setting an array element with a sequence.

[rosout][ERROR] 2012-12-15 18:11:08,995: bad callback: <bound method DepthDetector.depth_cb of <__main__.DepthDetector instance at 0x327aa28>>
Traceback (most recent call last):
  File "/opt/ros/electric/stacks/ros_comm/clients/rospy/src/rospy/topics.py", line 581, in _invoke_callback
    cb(msg)
  File "/home/alex/MAS/CV/project/cv_nxtdrive/src/depth_detection.py", line 282, in depth_cb
    (contours, img_contours) = self.get_contours(img_fore)
  File "/home/alex/MAS/CV/project/cv_nxtdrive/src/depth_detection.py", line 107, in get_contours
    cont[0] = DepthDetector.merge_contours(cont[0])
  File "/home/alex/MAS/CV/project/cv_nxtdrive/src/depth_detection.py", line 161, in merge_contours
    return cls.merge_contours(new_cont)
  File "/home/alex/MAS/CV/project/cv_nxtdrive/src/depth_detection.py", line 156, in merge_contours
    i, j, i_pos, j_pos = cls.find_close_conts(cont)
  File "/home/alex/MAS/CV/project/cv_nxtdrive/src/depth_detection.py", line 140, in find_close_conts
    np.save('debug', np.array( [x.shape for x in cont]))
ValueError: setting an array element with a sequence.

[rosout][ERROR] 2012-12-15 18:11:09,027: bad callback: <bound method DepthDetector.depth_cb of <__main__.DepthDetector instance at 0x327aa28>>
Traceback (most recent call last):
  File "/opt/ros/electric/stacks/ros_comm/clients/rospy/src/rospy/topics.py", line 581, in _invoke_callback
    cb(msg)
  File "/home/alex/MAS/CV/project/cv_nxtdrive/src/depth_detection.py", line 282, in depth_cb
    (contours, img_contours) = self.get_contours(img_fore)
  File "/home/alex/MAS/CV/project/cv_nxtdrive/src/depth_detection.py", line 107, in get_contours
    cont[0] = DepthDetector.merge_contours(cont[0])
  File "/home/alex/MAS/CV/project/cv_nxtdrive/src/depth_detection.py", line 161, in merge_contours
    return cls.merge_contours(new_cont)
  File "/home/alex/MAS/CV/project/cv_nxtdrive/src/depth_detection.py", line 161, in merge_contours
    return cls.merge_contours(new_cont)
  File "/home/alex/MAS/CV/project/cv_nxtdrive/src/depth_detection.py", line 156, in merge_contours
    i, j, i_pos, j_pos = cls.find_close_conts(cont)
  File "/home/alex/MAS/CV/project/cv_nxtdrive/src/depth_detection.py", line 140, in find_close_conts
    np.save('debug', np.array( [x.shape for x in cont]))
ValueError: setting an array element with a sequence.

[rosout][ERROR] 2012-12-15 18:11:09,072: bad callback: <bound method DepthDetector.depth_cb of <__main__.DepthDetector instance at 0x327aa28>>
Traceback (most recent call last):
  File "/opt/ros/electric/stacks/ros_comm/clients/rospy/src/rospy/topics.py", line 581, in _invoke_callback
    cb(msg)
  File "/home/alex/MAS/CV/project/cv_nxtdrive/src/depth_detection.py", line 282, in depth_cb
    (contours, img_contours) = self.get_contours(img_fore)
  File "/home/alex/MAS/CV/project/cv_nxtdrive/src/depth_detection.py", line 107, in get_contours
    cont[0] = DepthDetector.merge_contours(cont[0])
  File "/home/alex/MAS/CV/project/cv_nxtdrive/src/depth_detection.py", line 161, in merge_contours
    return cls.merge_contours(new_cont)
  File "/home/alex/MAS/CV/project/cv_nxtdrive/src/depth_detection.py", line 156, in merge_contours
    i, j, i_pos, j_pos = cls.find_close_conts(cont)
  File "/home/alex/MAS/CV/project/cv_nxtdrive/src/depth_detection.py", line 140, in find_close_conts
    np.save('debug', np.array( [x.shape for x in cont]))
ValueError: setting an array element with a sequence.

[rospy.core][INFO] 2012-12-15 18:11:09,099: signal_shutdown [signal-2]
[rospy.impl.masterslave][INFO] 2012-12-15 18:11:09,109: signal-2
[rospy.topics][WARNING] 2012-12-15 18:11:09,112: during shutdown, bad callback: <bound method DepthDetector.depth_cb of <__main__.DepthDetector instance at 0x327aa28>>
Traceback (most recent call last):
  File "/opt/ros/electric/stacks/ros_comm/clients/rospy/src/rospy/topics.py", line 581, in _invoke_callback
    cb(msg)
  File "/home/alex/MAS/CV/project/cv_nxtdrive/src/depth_detection.py", line 282, in depth_cb
    (contours, img_contours) = self.get_contours(img_fore)
  File "/home/alex/MAS/CV/project/cv_nxtdrive/src/depth_detection.py", line 107, in get_contours
    cont[0] = DepthDetector.merge_contours(cont[0])
  File "/home/alex/MAS/CV/project/cv_nxtdrive/src/depth_detection.py", line 161, in merge_contours
    return cls.merge_contours(new_cont)
  File "/home/alex/MAS/CV/project/cv_nxtdrive/src/depth_detection.py", line 156, in merge_contours
    i, j, i_pos, j_pos = cls.find_close_conts(cont)
  File "/home/alex/MAS/CV/project/cv_nxtdrive/src/depth_detection.py", line 140, in find_close_conts
    np.save('debug', np.array( [x.shape for x in cont]))
ValueError: setting an array element with a sequence.

[rospy.core][INFO] 2012-12-15 18:11:09,725: signal_shutdown [atexit]
