[rospy.client][INFO] 2012-12-15 18:01:43,097: init_node, name[/depth_detection], pid[11598]
[xmlrpc][INFO] 2012-12-15 18:01:43,097: XML-RPC server binding to 0.0.0.0
[xmlrpc][INFO] 2012-12-15 18:01:43,098: Started XML-RPC server [http://pc:40266/]
[rospy.init][INFO] 2012-12-15 18:01:43,098: ROS Slave URI: [http://pc:40266/]
[rospy.impl.masterslave][INFO] 2012-12-15 18:01:43,098: _ready: http://pc:40266/
[xmlrpc][INFO] 2012-12-15 18:01:43,099: xml rpc node: starting XML-RPC server
[rospy.registration][INFO] 2012-12-15 18:01:43,099: Registering with master node http://localhost:11311
[rospy.init][INFO] 2012-12-15 18:01:43,198: registered with master
[rospy.rosout][INFO] 2012-12-15 18:01:43,246: initializing /rosout core topic
[rospy.rosout][INFO] 2012-12-15 18:01:43,249: connected to core topic /rosout
[rospy.simtime][INFO] 2012-12-15 18:01:43,252: /use_sim_time is not set, will not subscribe to simulated time [/clock] topic
[rosout][ERROR] 2012-12-15 18:01:52,927: bad callback: <bound method DepthDetector.depth_cb of <__main__.DepthDetector instance at 0x2ad4a70>>
Traceback (most recent call last):
  File "/opt/ros/electric/stacks/ros_comm/clients/rospy/src/rospy/topics.py", line 581, in _invoke_callback
    cb(msg)
  File "/home/alex/MAS/CV/project/cv_nxtdrive/src/depth_detection.py", line 282, in depth_cb
    (contours, img_contours) = self.get_contours(img_fore)
  File "/home/alex/MAS/CV/project/cv_nxtdrive/src/depth_detection.py", line 107, in get_contours
    cont[0] = DepthDetector.merge_contours(cont[0])
TypeError: 'tuple' object does not support item assignment

[rosout][ERROR] 2012-12-15 18:01:53,064: bad callback: <bound method DepthDetector.depth_cb of <__main__.DepthDetector instance at 0x2ad4a70>>
Traceback (most recent call last):
  File "/opt/ros/electric/stacks/ros_comm/clients/rospy/src/rospy/topics.py", line 581, in _invoke_callback
    cb(msg)
  File "/home/alex/MAS/CV/project/cv_nxtdrive/src/depth_detection.py", line 282, in depth_cb
    (contours, img_contours) = self.get_contours(img_fore)
  File "/home/alex/MAS/CV/project/cv_nxtdrive/src/depth_detection.py", line 107, in get_contours
    cont[0] = DepthDetector.merge_contours(cont[0])
  File "/home/alex/MAS/CV/project/cv_nxtdrive/src/depth_detection.py", line 161, in merge_contours
    return cls.merge_contours(new_cont)
  File "/home/alex/MAS/CV/project/cv_nxtdrive/src/depth_detection.py", line 161, in merge_contours
    return cls.merge_contours(new_cont)
  File "/home/alex/MAS/CV/project/cv_nxtdrive/src/depth_detection.py", line 161, in merge_contours
    return cls.merge_contours(new_cont)
  File "/home/alex/MAS/CV/project/cv_nxtdrive/src/depth_detection.py", line 161, in merge_contours
    return cls.merge_contours(new_cont)
  File "/home/alex/MAS/CV/project/cv_nxtdrive/src/depth_detection.py", line 161, in merge_contours
    return cls.merge_contours(new_cont)
  File "/home/alex/MAS/CV/project/cv_nxtdrive/src/depth_detection.py", line 161, in merge_contours
    return cls.merge_contours(new_cont)
  File "/home/alex/MAS/CV/project/cv_nxtdrive/src/depth_detection.py", line 161, in merge_contours
    return cls.merge_contours(new_cont)
  File "/home/alex/MAS/CV/project/cv_nxtdrive/src/depth_detection.py", line 161, in merge_contours
    return cls.merge_contours(new_cont)
  File "/home/alex/MAS/CV/project/cv_nxtdrive/src/depth_detection.py", line 161, in merge_contours
    return cls.merge_contours(new_cont)
  File "/home/alex/MAS/CV/project/cv_nxtdrive/src/depth_detection.py", line 161, in merge_contours
    return cls.merge_contours(new_cont)
  File "/home/alex/MAS/CV/project/cv_nxtdrive/src/depth_detection.py", line 161, in merge_contours
    return cls.merge_contours(new_cont)
  File "/home/alex/MAS/CV/project/cv_nxtdrive/src/depth_detection.py", line 161, in merge_contours
    return cls.merge_contours(new_cont)
  File "/home/alex/MAS/CV/project/cv_nxtdrive/src/depth_detection.py", line 161, in merge_contours
    return cls.merge_contours(new_cont)
  File "/home/alex/MAS/CV/project/cv_nxtdrive/src/depth_detection.py", line 161, in merge_contours
    return cls.merge_contours(new_cont)
  File "/home/alex/MAS/CV/project/cv_nxtdrive/src/depth_detection.py", line 156, in merge_contours
    i, j, i_pos, j_pos = cls.find_close_conts(cont)
  File "/home/alex/MAS/CV/project/cv_nxtdrive/src/depth_detection.py", line 140, in find_close_conts
    cont[36]
IndexError: list index out of range

[rosout][ERROR] 2012-12-15 18:01:53,159: bad callback: <bound method DepthDetector.depth_cb of <__main__.DepthDetector instance at 0x2ad4a70>>
Traceback (most recent call last):
  File "/opt/ros/electric/stacks/ros_comm/clients/rospy/src/rospy/topics.py", line 581, in _invoke_callback
    cb(msg)
  File "/home/alex/MAS/CV/project/cv_nxtdrive/src/depth_detection.py", line 282, in depth_cb
    (contours, img_contours) = self.get_contours(img_fore)
  File "/home/alex/MAS/CV/project/cv_nxtdrive/src/depth_detection.py", line 107, in get_contours
    cont[0] = DepthDetector.merge_contours(cont[0])
  File "/home/alex/MAS/CV/project/cv_nxtdrive/src/depth_detection.py", line 161, in merge_contours
    return cls.merge_contours(new_cont)
  File "/home/alex/MAS/CV/project/cv_nxtdrive/src/depth_detection.py", line 161, in merge_contours
    return cls.merge_contours(new_cont)
  File "/home/alex/MAS/CV/project/cv_nxtdrive/src/depth_detection.py", line 161, in merge_contours
    return cls.merge_contours(new_cont)
  File "/home/alex/MAS/CV/project/cv_nxtdrive/src/depth_detection.py", line 161, in merge_contours
    return cls.merge_contours(new_cont)
  File "/home/alex/MAS/CV/project/cv_nxtdrive/src/depth_detection.py", line 161, in merge_contours
    return cls.merge_contours(new_cont)
  File "/home/alex/MAS/CV/project/cv_nxtdrive/src/depth_detection.py", line 161, in merge_contours
    return cls.merge_contours(new_cont)
  File "/home/alex/MAS/CV/project/cv_nxtdrive/src/depth_detection.py", line 161, in merge_contours
    return cls.merge_contours(new_cont)
  File "/home/alex/MAS/CV/project/cv_nxtdrive/src/depth_detection.py", line 161, in merge_contours
    return cls.merge_contours(new_cont)
  File "/home/alex/MAS/CV/project/cv_nxtdrive/src/depth_detection.py", line 161, in merge_contours
    return cls.merge_contours(new_cont)
  File "/home/alex/MAS/CV/project/cv_nxtdrive/src/depth_detection.py", line 156, in merge_contours
    i, j, i_pos, j_pos = cls.find_close_conts(cont)
  File "/home/alex/MAS/CV/project/cv_nxtdrive/src/depth_detection.py", line 140, in find_close_conts
    cont[36]
IndexError: list index out of range

[rosout][ERROR] 2012-12-15 18:01:53,305: bad callback: <bound method DepthDetector.depth_cb of <__main__.DepthDetector instance at 0x2ad4a70>>
Traceback (most recent call last):
  File "/opt/ros/electric/stacks/ros_comm/clients/rospy/src/rospy/topics.py", line 581, in _invoke_callback
    cb(msg)
  File "/home/alex/MAS/CV/project/cv_nxtdrive/src/depth_detection.py", line 282, in depth_cb
    (contours, img_contours) = self.get_contours(img_fore)
  File "/home/alex/MAS/CV/project/cv_nxtdrive/src/depth_detection.py", line 107, in get_contours
    cont[0] = DepthDetector.merge_contours(cont[0])
TypeError: 'tuple' object does not support item assignment

[rosout][ERROR] 2012-12-15 18:01:53,429: bad callback: <bound method DepthDetector.depth_cb of <__main__.DepthDetector instance at 0x2ad4a70>>
Traceback (most recent call last):
  File "/opt/ros/electric/stacks/ros_comm/clients/rospy/src/rospy/topics.py", line 581, in _invoke_callback
    cb(msg)
  File "/home/alex/MAS/CV/project/cv_nxtdrive/src/depth_detection.py", line 282, in depth_cb
    (contours, img_contours) = self.get_contours(img_fore)
  File "/home/alex/MAS/CV/project/cv_nxtdrive/src/depth_detection.py", line 107, in get_contours
    cont[0] = DepthDetector.merge_contours(cont[0])
  File "/home/alex/MAS/CV/project/cv_nxtdrive/src/depth_detection.py", line 161, in merge_contours
    return cls.merge_contours(new_cont)
  File "/home/alex/MAS/CV/project/cv_nxtdrive/src/depth_detection.py", line 161, in merge_contours
    return cls.merge_contours(new_cont)
  File "/home/alex/MAS/CV/project/cv_nxtdrive/src/depth_detection.py", line 161, in merge_contours
    return cls.merge_contours(new_cont)
  File "/home/alex/MAS/CV/project/cv_nxtdrive/src/depth_detection.py", line 161, in merge_contours
    return cls.merge_contours(new_cont)
  File "/home/alex/MAS/CV/project/cv_nxtdrive/src/depth_detection.py", line 161, in merge_contours
    return cls.merge_contours(new_cont)
  File "/home/alex/MAS/CV/project/cv_nxtdrive/src/depth_detection.py", line 161, in merge_contours
    return cls.merge_contours(new_cont)
  File "/home/alex/MAS/CV/project/cv_nxtdrive/src/depth_detection.py", line 161, in merge_contours
    return cls.merge_contours(new_cont)
  File "/home/alex/MAS/CV/project/cv_nxtdrive/src/depth_detection.py", line 161, in merge_contours
    return cls.merge_contours(new_cont)
  File "/home/alex/MAS/CV/project/cv_nxtdrive/src/depth_detection.py", line 161, in merge_contours
    return cls.merge_contours(new_cont)
  File "/home/alex/MAS/CV/project/cv_nxtdrive/src/depth_detection.py", line 161, in merge_contours
    return cls.merge_contours(new_cont)
  File "/home/alex/MAS/CV/project/cv_nxtdrive/src/depth_detection.py", line 161, in merge_contours
    return cls.merge_contours(new_cont)
  File "/home/alex/MAS/CV/project/cv_nxtdrive/src/depth_detection.py", line 156, in merge_contours
    i, j, i_pos, j_pos = cls.find_close_conts(cont)
  File "/home/alex/MAS/CV/project/cv_nxtdrive/src/depth_detection.py", line 140, in find_close_conts
    cont[36]
IndexError: list index out of range

[rosout][ERROR] 2012-12-15 18:01:53,520: bad callback: <bound method DepthDetector.depth_cb of <__main__.DepthDetector instance at 0x2ad4a70>>
Traceback (most recent call last):
  File "/opt/ros/electric/stacks/ros_comm/clients/rospy/src/rospy/topics.py", line 581, in _invoke_callback
    cb(msg)
  File "/home/alex/MAS/CV/project/cv_nxtdrive/src/depth_detection.py", line 282, in depth_cb
    (contours, img_contours) = self.get_contours(img_fore)
  File "/home/alex/MAS/CV/project/cv_nxtdrive/src/depth_detection.py", line 107, in get_contours
    cont[0] = DepthDetector.merge_contours(cont[0])
  File "/home/alex/MAS/CV/project/cv_nxtdrive/src/depth_detection.py", line 161, in merge_contours
    return cls.merge_contours(new_cont)
  File "/home/alex/MAS/CV/project/cv_nxtdrive/src/depth_detection.py", line 161, in merge_contours
    return cls.merge_contours(new_cont)
  File "/home/alex/MAS/CV/project/cv_nxtdrive/src/depth_detection.py", line 161, in merge_contours
    return cls.merge_contours(new_cont)
  File "/home/alex/MAS/CV/project/cv_nxtdrive/src/depth_detection.py", line 161, in merge_contours
    return cls.merge_contours(new_cont)
  File "/home/alex/MAS/CV/project/cv_nxtdrive/src/depth_detection.py", line 161, in merge_contours
    return cls.merge_contours(new_cont)
  File "/home/alex/MAS/CV/project/cv_nxtdrive/src/depth_detection.py", line 161, in merge_contours
    return cls.merge_contours(new_cont)
  File "/home/alex/MAS/CV/project/cv_nxtdrive/src/depth_detection.py", line 161, in merge_contours
    return cls.merge_contours(new_cont)
  File "/home/alex/MAS/CV/project/cv_nxtdrive/src/depth_detection.py", line 161, in merge_contours
    return cls.merge_contours(new_cont)
  File "/home/alex/MAS/CV/project/cv_nxtdrive/src/depth_detection.py", line 156, in merge_contours
    i, j, i_pos, j_pos = cls.find_close_conts(cont)
  File "/home/alex/MAS/CV/project/cv_nxtdrive/src/depth_detection.py", line 140, in find_close_conts
    cont[36]
IndexError: list index out of range

[rosout][ERROR] 2012-12-15 18:01:53,669: bad callback: <bound method DepthDetector.depth_cb of <__main__.DepthDetector instance at 0x2ad4a70>>
Traceback (most recent call last):
  File "/opt/ros/electric/stacks/ros_comm/clients/rospy/src/rospy/topics.py", line 581, in _invoke_callback
    cb(msg)
  File "/home/alex/MAS/CV/project/cv_nxtdrive/src/depth_detection.py", line 282, in depth_cb
    (contours, img_contours) = self.get_contours(img_fore)
  File "/home/alex/MAS/CV/project/cv_nxtdrive/src/depth_detection.py", line 107, in get_contours
    cont[0] = DepthDetector.merge_contours(cont[0])
TypeError: 'tuple' object does not support item assignment

[rosout][ERROR] 2012-12-15 18:01:53,741: bad callback: <bound method DepthDetector.depth_cb of <__main__.DepthDetector instance at 0x2ad4a70>>
Traceback (most recent call last):
  File "/opt/ros/electric/stacks/ros_comm/clients/rospy/src/rospy/topics.py", line 581, in _invoke_callback
    cb(msg)
  File "/home/alex/MAS/CV/project/cv_nxtdrive/src/depth_detection.py", line 282, in depth_cb
    (contours, img_contours) = self.get_contours(img_fore)
  File "/home/alex/MAS/CV/project/cv_nxtdrive/src/depth_detection.py", line 107, in get_contours
    cont[0] = DepthDetector.merge_contours(cont[0])
  File "/home/alex/MAS/CV/project/cv_nxtdrive/src/depth_detection.py", line 161, in merge_contours
    return cls.merge_contours(new_cont)
  File "/home/alex/MAS/CV/project/cv_nxtdrive/src/depth_detection.py", line 161, in merge_contours
    return cls.merge_contours(new_cont)
  File "/home/alex/MAS/CV/project/cv_nxtdrive/src/depth_detection.py", line 161, in merge_contours
    return cls.merge_contours(new_cont)
  File "/home/alex/MAS/CV/project/cv_nxtdrive/src/depth_detection.py", line 161, in merge_contours
    return cls.merge_contours(new_cont)
  File "/home/alex/MAS/CV/project/cv_nxtdrive/src/depth_detection.py", line 161, in merge_contours
    return cls.merge_contours(new_cont)
  File "/home/alex/MAS/CV/project/cv_nxtdrive/src/depth_detection.py", line 161, in merge_contours
    return cls.merge_contours(new_cont)
  File "/home/alex/MAS/CV/project/cv_nxtdrive/src/depth_detection.py", line 161, in merge_contours
    return cls.merge_contours(new_cont)
  File "/home/alex/MAS/CV/project/cv_nxtdrive/src/depth_detection.py", line 156, in merge_contours
    i, j, i_pos, j_pos = cls.find_close_conts(cont)
  File "/home/alex/MAS/CV/project/cv_nxtdrive/src/depth_detection.py", line 140, in find_close_conts
    cont[36]
IndexError: list index out of range

[rosout][ERROR] 2012-12-15 18:01:53,785: bad callback: <bound method DepthDetector.depth_cb of <__main__.DepthDetector instance at 0x2ad4a70>>
Traceback (most recent call last):
  File "/opt/ros/electric/stacks/ros_comm/clients/rospy/src/rospy/topics.py", line 581, in _invoke_callback
    cb(msg)
  File "/home/alex/MAS/CV/project/cv_nxtdrive/src/depth_detection.py", line 282, in depth_cb
    (contours, img_contours) = self.get_contours(img_fore)
  File "/home/alex/MAS/CV/project/cv_nxtdrive/src/depth_detection.py", line 107, in get_contours
    cont[0] = DepthDetector.merge_contours(cont[0])
  File "/home/alex/MAS/CV/project/cv_nxtdrive/src/depth_detection.py", line 161, in merge_contours
    return cls.merge_contours(new_cont)
  File "/home/alex/MAS/CV/project/cv_nxtdrive/src/depth_detection.py", line 161, in merge_contours
    return cls.merge_contours(new_cont)
  File "/home/alex/MAS/CV/project/cv_nxtdrive/src/depth_detection.py", line 161, in merge_contours
    return cls.merge_contours(new_cont)
  File "/home/alex/MAS/CV/project/cv_nxtdrive/src/depth_detection.py", line 156, in merge_contours
    i, j, i_pos, j_pos = cls.find_close_conts(cont)
  File "/home/alex/MAS/CV/project/cv_nxtdrive/src/depth_detection.py", line 140, in find_close_conts
    cont[36]
IndexError: list index out of range

[rosout][ERROR] 2012-12-15 18:01:53,866: bad callback: <bound method DepthDetector.depth_cb of <__main__.DepthDetector instance at 0x2ad4a70>>
Traceback (most recent call last):
  File "/opt/ros/electric/stacks/ros_comm/clients/rospy/src/rospy/topics.py", line 581, in _invoke_callback
    cb(msg)
  File "/home/alex/MAS/CV/project/cv_nxtdrive/src/depth_detection.py", line 282, in depth_cb
    (contours, img_contours) = self.get_contours(img_fore)
  File "/home/alex/MAS/CV/project/cv_nxtdrive/src/depth_detection.py", line 107, in get_contours
    cont[0] = DepthDetector.merge_contours(cont[0])
  File "/home/alex/MAS/CV/project/cv_nxtdrive/src/depth_detection.py", line 161, in merge_contours
    return cls.merge_contours(new_cont)
  File "/home/alex/MAS/CV/project/cv_nxtdrive/src/depth_detection.py", line 161, in merge_contours
    return cls.merge_contours(new_cont)
  File "/home/alex/MAS/CV/project/cv_nxtdrive/src/depth_detection.py", line 161, in merge_contours
    return cls.merge_contours(new_cont)
  File "/home/alex/MAS/CV/project/cv_nxtdrive/src/depth_detection.py", line 161, in merge_contours
    return cls.merge_contours(new_cont)
  File "/home/alex/MAS/CV/project/cv_nxtdrive/src/depth_detection.py", line 161, in merge_contours
    return cls.merge_contours(new_cont)
  File "/home/alex/MAS/CV/project/cv_nxtdrive/src/depth_detection.py", line 161, in merge_contours
    return cls.merge_contours(new_cont)
  File "/home/alex/MAS/CV/project/cv_nxtdrive/src/depth_detection.py", line 161, in merge_contours
    return cls.merge_contours(new_cont)
  File "/home/alex/MAS/CV/project/cv_nxtdrive/src/depth_detection.py", line 161, in merge_contours
    return cls.merge_contours(new_cont)
  File "/home/alex/MAS/CV/project/cv_nxtdrive/src/depth_detection.py", line 161, in merge_contours
    return cls.merge_contours(new_cont)
  File "/home/alex/MAS/CV/project/cv_nxtdrive/src/depth_detection.py", line 161, in merge_contours
    return cls.merge_contours(new_cont)
  File "/home/alex/MAS/CV/project/cv_nxtdrive/src/depth_detection.py", line 161, in merge_contours
    return cls.merge_contours(new_cont)
  File "/home/alex/MAS/CV/project/cv_nxtdrive/src/depth_detection.py", line 156, in merge_contours
    i, j, i_pos, j_pos = cls.find_close_conts(cont)
  File "/home/alex/MAS/CV/project/cv_nxtdrive/src/depth_detection.py", line 140, in find_close_conts
    cont[36]
IndexError: list index out of range

[rosout][ERROR] 2012-12-15 18:01:53,909: bad callback: <bound method DepthDetector.depth_cb of <__main__.DepthDetector instance at 0x2ad4a70>>
Traceback (most recent call last):
  File "/opt/ros/electric/stacks/ros_comm/clients/rospy/src/rospy/topics.py", line 581, in _invoke_callback
    cb(msg)
  File "/home/alex/MAS/CV/project/cv_nxtdrive/src/depth_detection.py", line 282, in depth_cb
    (contours, img_contours) = self.get_contours(img_fore)
  File "/home/alex/MAS/CV/project/cv_nxtdrive/src/depth_detection.py", line 107, in get_contours
    cont[0] = DepthDetector.merge_contours(cont[0])
  File "/home/alex/MAS/CV/project/cv_nxtdrive/src/depth_detection.py", line 161, in merge_contours
    return cls.merge_contours(new_cont)
  File "/home/alex/MAS/CV/project/cv_nxtdrive/src/depth_detection.py", line 161, in merge_contours
    return cls.merge_contours(new_cont)
  File "/home/alex/MAS/CV/project/cv_nxtdrive/src/depth_detection.py", line 161, in merge_contours
    return cls.merge_contours(new_cont)
  File "/home/alex/MAS/CV/project/cv_nxtdrive/src/depth_detection.py", line 161, in merge_contours
    return cls.merge_contours(new_cont)
  File "/home/alex/MAS/CV/project/cv_nxtdrive/src/depth_detection.py", line 161, in merge_contours
    return cls.merge_contours(new_cont)
  File "/home/alex/MAS/CV/project/cv_nxtdrive/src/depth_detection.py", line 156, in merge_contours
    i, j, i_pos, j_pos = cls.find_close_conts(cont)
  File "/home/alex/MAS/CV/project/cv_nxtdrive/src/depth_detection.py", line 140, in find_close_conts
    cont[36]
IndexError: list index out of range

[rosout][ERROR] 2012-12-15 18:01:53,942: bad callback: <bound method DepthDetector.depth_cb of <__main__.DepthDetector instance at 0x2ad4a70>>
Traceback (most recent call last):
  File "/opt/ros/electric/stacks/ros_comm/clients/rospy/src/rospy/topics.py", line 581, in _invoke_callback
    cb(msg)
  File "/home/alex/MAS/CV/project/cv_nxtdrive/src/depth_detection.py", line 282, in depth_cb
    (contours, img_contours) = self.get_contours(img_fore)
  File "/home/alex/MAS/CV/project/cv_nxtdrive/src/depth_detection.py", line 107, in get_contours
    cont[0] = DepthDetector.merge_contours(cont[0])
  File "/home/alex/MAS/CV/project/cv_nxtdrive/src/depth_detection.py", line 161, in merge_contours
    return cls.merge_contours(new_cont)
  File "/home/alex/MAS/CV/project/cv_nxtdrive/src/depth_detection.py", line 156, in merge_contours
    i, j, i_pos, j_pos = cls.find_close_conts(cont)
  File "/home/alex/MAS/CV/project/cv_nxtdrive/src/depth_detection.py", line 140, in find_close_conts
    cont[36]
IndexError: list index out of range

[rosout][ERROR] 2012-12-15 18:01:54,068: bad callback: <bound method DepthDetector.depth_cb of <__main__.DepthDetector instance at 0x2ad4a70>>
Traceback (most recent call last):
  File "/opt/ros/electric/stacks/ros_comm/clients/rospy/src/rospy/topics.py", line 581, in _invoke_callback
    cb(msg)
  File "/home/alex/MAS/CV/project/cv_nxtdrive/src/depth_detection.py", line 282, in depth_cb
    (contours, img_contours) = self.get_contours(img_fore)
  File "/home/alex/MAS/CV/project/cv_nxtdrive/src/depth_detection.py", line 107, in get_contours
    cont[0] = DepthDetector.merge_contours(cont[0])
TypeError: 'tuple' object does not support item assignment

[rosout][ERROR] 2012-12-15 18:01:54,164: bad callback: <bound method DepthDetector.depth_cb of <__main__.DepthDetector instance at 0x2ad4a70>>
Traceback (most recent call last):
  File "/opt/ros/electric/stacks/ros_comm/clients/rospy/src/rospy/topics.py", line 581, in _invoke_callback
    cb(msg)
  File "/home/alex/MAS/CV/project/cv_nxtdrive/src/depth_detection.py", line 282, in depth_cb
    (contours, img_contours) = self.get_contours(img_fore)
  File "/home/alex/MAS/CV/project/cv_nxtdrive/src/depth_detection.py", line 107, in get_contours
    cont[0] = DepthDetector.merge_contours(cont[0])
  File "/home/alex/MAS/CV/project/cv_nxtdrive/src/depth_detection.py", line 161, in merge_contours
    return cls.merge_contours(new_cont)
  File "/home/alex/MAS/CV/project/cv_nxtdrive/src/depth_detection.py", line 161, in merge_contours
    return cls.merge_contours(new_cont)
  File "/home/alex/MAS/CV/project/cv_nxtdrive/src/depth_detection.py", line 161, in merge_contours
    return cls.merge_contours(new_cont)
  File "/home/alex/MAS/CV/project/cv_nxtdrive/src/depth_detection.py", line 161, in merge_contours
    return cls.merge_contours(new_cont)
  File "/home/alex/MAS/CV/project/cv_nxtdrive/src/depth_detection.py", line 161, in merge_contours
    return cls.merge_contours(new_cont)
  File "/home/alex/MAS/CV/project/cv_nxtdrive/src/depth_detection.py", line 161, in merge_contours
    return cls.merge_contours(new_cont)
  File "/home/alex/MAS/CV/project/cv_nxtdrive/src/depth_detection.py", line 161, in merge_contours
    return cls.merge_contours(new_cont)
  File "/home/alex/MAS/CV/project/cv_nxtdrive/src/depth_detection.py", line 161, in merge_contours
    return cls.merge_contours(new_cont)
  File "/home/alex/MAS/CV/project/cv_nxtdrive/src/depth_detection.py", line 161, in merge_contours
    return cls.merge_contours(new_cont)
  File "/home/alex/MAS/CV/project/cv_nxtdrive/src/depth_detection.py", line 156, in merge_contours
    i, j, i_pos, j_pos = cls.find_close_conts(cont)
  File "/home/alex/MAS/CV/project/cv_nxtdrive/src/depth_detection.py", line 140, in find_close_conts
    cont[36]
IndexError: list index out of range

[rosout][ERROR] 2012-12-15 18:01:54,276: bad callback: <bound method DepthDetector.depth_cb of <__main__.DepthDetector instance at 0x2ad4a70>>
Traceback (most recent call last):
  File "/opt/ros/electric/stacks/ros_comm/clients/rospy/src/rospy/topics.py", line 581, in _invoke_callback
    cb(msg)
  File "/home/alex/MAS/CV/project/cv_nxtdrive/src/depth_detection.py", line 282, in depth_cb
    (contours, img_contours) = self.get_contours(img_fore)
  File "/home/alex/MAS/CV/project/cv_nxtdrive/src/depth_detection.py", line 107, in get_contours
    cont[0] = DepthDetector.merge_contours(cont[0])
  File "/home/alex/MAS/CV/project/cv_nxtdrive/src/depth_detection.py", line 161, in merge_contours
    return cls.merge_contours(new_cont)
  File "/home/alex/MAS/CV/project/cv_nxtdrive/src/depth_detection.py", line 161, in merge_contours
    return cls.merge_contours(new_cont)
  File "/home/alex/MAS/CV/project/cv_nxtdrive/src/depth_detection.py", line 161, in merge_contours
    return cls.merge_contours(new_cont)
  File "/home/alex/MAS/CV/project/cv_nxtdrive/src/depth_detection.py", line 161, in merge_contours
    return cls.merge_contours(new_cont)
  File "/home/alex/MAS/CV/project/cv_nxtdrive/src/depth_detection.py", line 161, in merge_contours
    return cls.merge_contours(new_cont)
  File "/home/alex/MAS/CV/project/cv_nxtdrive/src/depth_detection.py", line 161, in merge_contours
    return cls.merge_contours(new_cont)
  File "/home/alex/MAS/CV/project/cv_nxtdrive/src/depth_detection.py", line 161, in merge_contours
    return cls.merge_contours(new_cont)
  File "/home/alex/MAS/CV/project/cv_nxtdrive/src/depth_detection.py", line 156, in merge_contours
    i, j, i_pos, j_pos = cls.find_close_conts(cont)
  File "/home/alex/MAS/CV/project/cv_nxtdrive/src/depth_detection.py", line 140, in find_close_conts
    cont[36]
IndexError: list index out of range

[rosout][ERROR] 2012-12-15 18:01:54,316: bad callback: <bound method DepthDetector.depth_cb of <__main__.DepthDetector instance at 0x2ad4a70>>
Traceback (most recent call last):
  File "/opt/ros/electric/stacks/ros_comm/clients/rospy/src/rospy/topics.py", line 581, in _invoke_callback
    cb(msg)
  File "/home/alex/MAS/CV/project/cv_nxtdrive/src/depth_detection.py", line 282, in depth_cb
    (contours, img_contours) = self.get_contours(img_fore)
  File "/home/alex/MAS/CV/project/cv_nxtdrive/src/depth_detection.py", line 107, in get_contours
    cont[0] = DepthDetector.merge_contours(cont[0])
  File "/home/alex/MAS/CV/project/cv_nxtdrive/src/depth_detection.py", line 161, in merge_contours
    return cls.merge_contours(new_cont)
  File "/home/alex/MAS/CV/project/cv_nxtdrive/src/depth_detection.py", line 156, in merge_contours
    i, j, i_pos, j_pos = cls.find_close_conts(cont)
  File "/home/alex/MAS/CV/project/cv_nxtdrive/src/depth_detection.py", line 140, in find_close_conts
    cont[36]
IndexError: list index out of range

[rosout][ERROR] 2012-12-15 18:01:54,349: bad callback: <bound method DepthDetector.depth_cb of <__main__.DepthDetector instance at 0x2ad4a70>>
Traceback (most recent call last):
  File "/opt/ros/electric/stacks/ros_comm/clients/rospy/src/rospy/topics.py", line 581, in _invoke_callback
    cb(msg)
  File "/home/alex/MAS/CV/project/cv_nxtdrive/src/depth_detection.py", line 282, in depth_cb
    (contours, img_contours) = self.get_contours(img_fore)
  File "/home/alex/MAS/CV/project/cv_nxtdrive/src/depth_detection.py", line 107, in get_contours
    cont[0] = DepthDetector.merge_contours(cont[0])
  File "/home/alex/MAS/CV/project/cv_nxtdrive/src/depth_detection.py", line 161, in merge_contours
    return cls.merge_contours(new_cont)
  File "/home/alex/MAS/CV/project/cv_nxtdrive/src/depth_detection.py", line 156, in merge_contours
    i, j, i_pos, j_pos = cls.find_close_conts(cont)
  File "/home/alex/MAS/CV/project/cv_nxtdrive/src/depth_detection.py", line 140, in find_close_conts
    cont[36]
IndexError: list index out of range

[rosout][ERROR] 2012-12-15 18:01:54,516: bad callback: <bound method DepthDetector.depth_cb of <__main__.DepthDetector instance at 0x2ad4a70>>
Traceback (most recent call last):
  File "/opt/ros/electric/stacks/ros_comm/clients/rospy/src/rospy/topics.py", line 581, in _invoke_callback
    cb(msg)
  File "/home/alex/MAS/CV/project/cv_nxtdrive/src/depth_detection.py", line 282, in depth_cb
    (contours, img_contours) = self.get_contours(img_fore)
  File "/home/alex/MAS/CV/project/cv_nxtdrive/src/depth_detection.py", line 107, in get_contours
    cont[0] = DepthDetector.merge_contours(cont[0])
TypeError: 'tuple' object does not support item assignment

[rosout][ERROR] 2012-12-15 18:01:54,576: bad callback: <bound method DepthDetector.depth_cb of <__main__.DepthDetector instance at 0x2ad4a70>>
Traceback (most recent call last):
  File "/opt/ros/electric/stacks/ros_comm/clients/rospy/src/rospy/topics.py", line 581, in _invoke_callback
    cb(msg)
  File "/home/alex/MAS/CV/project/cv_nxtdrive/src/depth_detection.py", line 282, in depth_cb
    (contours, img_contours) = self.get_contours(img_fore)
  File "/home/alex/MAS/CV/project/cv_nxtdrive/src/depth_detection.py", line 107, in get_contours
    cont[0] = DepthDetector.merge_contours(cont[0])
  File "/home/alex/MAS/CV/project/cv_nxtdrive/src/depth_detection.py", line 161, in merge_contours
    return cls.merge_contours(new_cont)
  File "/home/alex/MAS/CV/project/cv_nxtdrive/src/depth_detection.py", line 161, in merge_contours
    return cls.merge_contours(new_cont)
  File "/home/alex/MAS/CV/project/cv_nxtdrive/src/depth_detection.py", line 161, in merge_contours
    return cls.merge_contours(new_cont)
  File "/home/alex/MAS/CV/project/cv_nxtdrive/src/depth_detection.py", line 161, in merge_contours
    return cls.merge_contours(new_cont)
  File "/home/alex/MAS/CV/project/cv_nxtdrive/src/depth_detection.py", line 161, in merge_contours
    return cls.merge_contours(new_cont)
  File "/home/alex/MAS/CV/project/cv_nxtdrive/src/depth_detection.py", line 161, in merge_contours
    return cls.merge_contours(new_cont)
  File "/home/alex/MAS/CV/project/cv_nxtdrive/src/depth_detection.py", line 161, in merge_contours
    return cls.merge_contours(new_cont)
  File "/home/alex/MAS/CV/project/cv_nxtdrive/src/depth_detection.py", line 156, in merge_contours
    i, j, i_pos, j_pos = cls.find_close_conts(cont)
  File "/home/alex/MAS/CV/project/cv_nxtdrive/src/depth_detection.py", line 140, in find_close_conts
    cont[36]
IndexError: list index out of range

[rosout][ERROR] 2012-12-15 18:01:54,663: bad callback: <bound method DepthDetector.depth_cb of <__main__.DepthDetector instance at 0x2ad4a70>>
Traceback (most recent call last):
  File "/opt/ros/electric/stacks/ros_comm/clients/rospy/src/rospy/topics.py", line 581, in _invoke_callback
    cb(msg)
  File "/home/alex/MAS/CV/project/cv_nxtdrive/src/depth_detection.py", line 282, in depth_cb
    (contours, img_contours) = self.get_contours(img_fore)
  File "/home/alex/MAS/CV/project/cv_nxtdrive/src/depth_detection.py", line 107, in get_contours
    cont[0] = DepthDetector.merge_contours(cont[0])
  File "/home/alex/MAS/CV/project/cv_nxtdrive/src/depth_detection.py", line 161, in merge_contours
    return cls.merge_contours(new_cont)
  File "/home/alex/MAS/CV/project/cv_nxtdrive/src/depth_detection.py", line 161, in merge_contours
    return cls.merge_contours(new_cont)
  File "/home/alex/MAS/CV/project/cv_nxtdrive/src/depth_detection.py", line 161, in merge_contours
    return cls.merge_contours(new_cont)
  File "/home/alex/MAS/CV/project/cv_nxtdrive/src/depth_detection.py", line 161, in merge_contours
    return cls.merge_contours(new_cont)
  File "/home/alex/MAS/CV/project/cv_nxtdrive/src/depth_detection.py", line 161, in merge_contours
    return cls.merge_contours(new_cont)
  File "/home/alex/MAS/CV/project/cv_nxtdrive/src/depth_detection.py", line 161, in merge_contours
    return cls.merge_contours(new_cont)
  File "/home/alex/MAS/CV/project/cv_nxtdrive/src/depth_detection.py", line 161, in merge_contours
    return cls.merge_contours(new_cont)
  File "/home/alex/MAS/CV/project/cv_nxtdrive/src/depth_detection.py", line 161, in merge_contours
    return cls.merge_contours(new_cont)
  File "/home/alex/MAS/CV/project/cv_nxtdrive/src/depth_detection.py", line 161, in merge_contours
    return cls.merge_contours(new_cont)
  File "/home/alex/MAS/CV/project/cv_nxtdrive/src/depth_detection.py", line 161, in merge_contours
    return cls.merge_contours(new_cont)
  File "/home/alex/MAS/CV/project/cv_nxtdrive/src/depth_detection.py", line 161, in merge_contours
    return cls.merge_contours(new_cont)
  File "/home/alex/MAS/CV/project/cv_nxtdrive/src/depth_detection.py", line 156, in merge_contours
    i, j, i_pos, j_pos = cls.find_close_conts(cont)
  File "/home/alex/MAS/CV/project/cv_nxtdrive/src/depth_detection.py", line 140, in find_close_conts
    cont[36]
IndexError: list index out of range

[rosout][ERROR] 2012-12-15 18:01:54,714: bad callback: <bound method DepthDetector.depth_cb of <__main__.DepthDetector instance at 0x2ad4a70>>
Traceback (most recent call last):
  File "/opt/ros/electric/stacks/ros_comm/clients/rospy/src/rospy/topics.py", line 581, in _invoke_callback
    cb(msg)
  File "/home/alex/MAS/CV/project/cv_nxtdrive/src/depth_detection.py", line 282, in depth_cb
    (contours, img_contours) = self.get_contours(img_fore)
  File "/home/alex/MAS/CV/project/cv_nxtdrive/src/depth_detection.py", line 107, in get_contours
    cont[0] = DepthDetector.merge_contours(cont[0])
  File "/home/alex/MAS/CV/project/cv_nxtdrive/src/depth_detection.py", line 161, in merge_contours
    return cls.merge_contours(new_cont)
  File "/home/alex/MAS/CV/project/cv_nxtdrive/src/depth_detection.py", line 161, in merge_contours
    return cls.merge_contours(new_cont)
  File "/home/alex/MAS/CV/project/cv_nxtdrive/src/depth_detection.py", line 161, in merge_contours
    return cls.merge_contours(new_cont)
  File "/home/alex/MAS/CV/project/cv_nxtdrive/src/depth_detection.py", line 161, in merge_contours
    return cls.merge_contours(new_cont)
  File "/home/alex/MAS/CV/project/cv_nxtdrive/src/depth_detection.py", line 161, in merge_contours
    return cls.merge_contours(new_cont)
  File "/home/alex/MAS/CV/project/cv_nxtdrive/src/depth_detection.py", line 156, in merge_contours
    i, j, i_pos, j_pos = cls.find_close_conts(cont)
  File "/home/alex/MAS/CV/project/cv_nxtdrive/src/depth_detection.py", line 140, in find_close_conts
    cont[36]
IndexError: list index out of range

[rosout][ERROR] 2012-12-15 18:01:54,798: bad callback: <bound method DepthDetector.depth_cb of <__main__.DepthDetector instance at 0x2ad4a70>>
Traceback (most recent call last):
  File "/opt/ros/electric/stacks/ros_comm/clients/rospy/src/rospy/topics.py", line 581, in _invoke_callback
    cb(msg)
  File "/home/alex/MAS/CV/project/cv_nxtdrive/src/depth_detection.py", line 282, in depth_cb
    (contours, img_contours) = self.get_contours(img_fore)
  File "/home/alex/MAS/CV/project/cv_nxtdrive/src/depth_detection.py", line 107, in get_contours
    cont[0] = DepthDetector.merge_contours(cont[0])
  File "/home/alex/MAS/CV/project/cv_nxtdrive/src/depth_detection.py", line 161, in merge_contours
    return cls.merge_contours(new_cont)
  File "/home/alex/MAS/CV/project/cv_nxtdrive/src/depth_detection.py", line 161, in merge_contours
    return cls.merge_contours(new_cont)
  File "/home/alex/MAS/CV/project/cv_nxtdrive/src/depth_detection.py", line 161, in merge_contours
    return cls.merge_contours(new_cont)
  File "/home/alex/MAS/CV/project/cv_nxtdrive/src/depth_detection.py", line 161, in merge_contours
    return cls.merge_contours(new_cont)
  File "/home/alex/MAS/CV/project/cv_nxtdrive/src/depth_detection.py", line 161, in merge_contours
    return cls.merge_contours(new_cont)
  File "/home/alex/MAS/CV/project/cv_nxtdrive/src/depth_detection.py", line 161, in merge_contours
    return cls.merge_contours(new_cont)
  File "/home/alex/MAS/CV/project/cv_nxtdrive/src/depth_detection.py", line 161, in merge_contours
    return cls.merge_contours(new_cont)
  File "/home/alex/MAS/CV/project/cv_nxtdrive/src/depth_detection.py", line 161, in merge_contours
    return cls.merge_contours(new_cont)
  File "/home/alex/MAS/CV/project/cv_nxtdrive/src/depth_detection.py", line 161, in merge_contours
    return cls.merge_contours(new_cont)
  File "/home/alex/MAS/CV/project/cv_nxtdrive/src/depth_detection.py", line 161, in merge_contours
    return cls.merge_contours(new_cont)
  File "/home/alex/MAS/CV/project/cv_nxtdrive/src/depth_detection.py", line 156, in merge_contours
    i, j, i_pos, j_pos = cls.find_close_conts(cont)
  File "/home/alex/MAS/CV/project/cv_nxtdrive/src/depth_detection.py", line 140, in find_close_conts
    cont[36]
IndexError: list index out of range

[rosout][ERROR] 2012-12-15 18:01:54,833: bad callback: <bound method DepthDetector.depth_cb of <__main__.DepthDetector instance at 0x2ad4a70>>
Traceback (most recent call last):
  File "/opt/ros/electric/stacks/ros_comm/clients/rospy/src/rospy/topics.py", line 581, in _invoke_callback
    cb(msg)
  File "/home/alex/MAS/CV/project/cv_nxtdrive/src/depth_detection.py", line 282, in depth_cb
    (contours, img_contours) = self.get_contours(img_fore)
  File "/home/alex/MAS/CV/project/cv_nxtdrive/src/depth_detection.py", line 107, in get_contours
    cont[0] = DepthDetector.merge_contours(cont[0])
  File "/home/alex/MAS/CV/project/cv_nxtdrive/src/depth_detection.py", line 161, in merge_contours
    return cls.merge_contours(new_cont)
  File "/home/alex/MAS/CV/project/cv_nxtdrive/src/depth_detection.py", line 156, in merge_contours
    i, j, i_pos, j_pos = cls.find_close_conts(cont)
  File "/home/alex/MAS/CV/project/cv_nxtdrive/src/depth_detection.py", line 140, in find_close_conts
    cont[36]
IndexError: list index out of range

[rosout][ERROR] 2012-12-15 18:01:54,923: bad callback: <bound method DepthDetector.depth_cb of <__main__.DepthDetector instance at 0x2ad4a70>>
Traceback (most recent call last):
  File "/opt/ros/electric/stacks/ros_comm/clients/rospy/src/rospy/topics.py", line 581, in _invoke_callback
    cb(msg)
  File "/home/alex/MAS/CV/project/cv_nxtdrive/src/depth_detection.py", line 282, in depth_cb
    (contours, img_contours) = self.get_contours(img_fore)
  File "/home/alex/MAS/CV/project/cv_nxtdrive/src/depth_detection.py", line 107, in get_contours
    cont[0] = DepthDetector.merge_contours(cont[0])
  File "/home/alex/MAS/CV/project/cv_nxtdrive/src/depth_detection.py", line 161, in merge_contours
    return cls.merge_contours(new_cont)
  File "/home/alex/MAS/CV/project/cv_nxtdrive/src/depth_detection.py", line 161, in merge_contours
    return cls.merge_contours(new_cont)
  File "/home/alex/MAS/CV/project/cv_nxtdrive/src/depth_detection.py", line 161, in merge_contours
    return cls.merge_contours(new_cont)
  File "/home/alex/MAS/CV/project/cv_nxtdrive/src/depth_detection.py", line 161, in merge_contours
    return cls.merge_contours(new_cont)
  File "/home/alex/MAS/CV/project/cv_nxtdrive/src/depth_detection.py", line 161, in merge_contours
    return cls.merge_contours(new_cont)
  File "/home/alex/MAS/CV/project/cv_nxtdrive/src/depth_detection.py", line 161, in merge_contours
    return cls.merge_contours(new_cont)
  File "/home/alex/MAS/CV/project/cv_nxtdrive/src/depth_detection.py", line 161, in merge_contours
    return cls.merge_contours(new_cont)
  File "/home/alex/MAS/CV/project/cv_nxtdrive/src/depth_detection.py", line 161, in merge_contours
    return cls.merge_contours(new_cont)
  File "/home/alex/MAS/CV/project/cv_nxtdrive/src/depth_detection.py", line 161, in merge_contours
    return cls.merge_contours(new_cont)
  File "/home/alex/MAS/CV/project/cv_nxtdrive/src/depth_detection.py", line 161, in merge_contours
    return cls.merge_contours(new_cont)
  File "/home/alex/MAS/CV/project/cv_nxtdrive/src/depth_detection.py", line 156, in merge_contours
    i, j, i_pos, j_pos = cls.find_close_conts(cont)
  File "/home/alex/MAS/CV/project/cv_nxtdrive/src/depth_detection.py", line 140, in find_close_conts
    cont[36]
IndexError: list index out of range

[rosout][ERROR] 2012-12-15 18:01:55,051: bad callback: <bound method DepthDetector.depth_cb of <__main__.DepthDetector instance at 0x2ad4a70>>
Traceback (most recent call last):
  File "/opt/ros/electric/stacks/ros_comm/clients/rospy/src/rospy/topics.py", line 581, in _invoke_callback
    cb(msg)
  File "/home/alex/MAS/CV/project/cv_nxtdrive/src/depth_detection.py", line 282, in depth_cb
    (contours, img_contours) = self.get_contours(img_fore)
  File "/home/alex/MAS/CV/project/cv_nxtdrive/src/depth_detection.py", line 107, in get_contours
    cont[0] = DepthDetector.merge_contours(cont[0])
TypeError: 'tuple' object does not support item assignment

[rosout][ERROR] 2012-12-15 18:01:55,197: bad callback: <bound method DepthDetector.depth_cb of <__main__.DepthDetector instance at 0x2ad4a70>>
Traceback (most recent call last):
  File "/opt/ros/electric/stacks/ros_comm/clients/rospy/src/rospy/topics.py", line 581, in _invoke_callback
    cb(msg)
  File "/home/alex/MAS/CV/project/cv_nxtdrive/src/depth_detection.py", line 282, in depth_cb
    (contours, img_contours) = self.get_contours(img_fore)
  File "/home/alex/MAS/CV/project/cv_nxtdrive/src/depth_detection.py", line 107, in get_contours
    cont[0] = DepthDetector.merge_contours(cont[0])
TypeError: 'tuple' object does not support item assignment

[rosout][ERROR] 2012-12-15 18:01:55,231: bad callback: <bound method DepthDetector.depth_cb of <__main__.DepthDetector instance at 0x2ad4a70>>
Traceback (most recent call last):
  File "/opt/ros/electric/stacks/ros_comm/clients/rospy/src/rospy/topics.py", line 581, in _invoke_callback
    cb(msg)
  File "/home/alex/MAS/CV/project/cv_nxtdrive/src/depth_detection.py", line 282, in depth_cb
    (contours, img_contours) = self.get_contours(img_fore)
  File "/home/alex/MAS/CV/project/cv_nxtdrive/src/depth_detection.py", line 107, in get_contours
    cont[0] = DepthDetector.merge_contours(cont[0])
  File "/home/alex/MAS/CV/project/cv_nxtdrive/src/depth_detection.py", line 161, in merge_contours
    return cls.merge_contours(new_cont)
  File "/home/alex/MAS/CV/project/cv_nxtdrive/src/depth_detection.py", line 156, in merge_contours
    i, j, i_pos, j_pos = cls.find_close_conts(cont)
  File "/home/alex/MAS/CV/project/cv_nxtdrive/src/depth_detection.py", line 140, in find_close_conts
    cont[36]
IndexError: list index out of range

[rosout][ERROR] 2012-12-15 18:01:55,283: bad callback: <bound method DepthDetector.depth_cb of <__main__.DepthDetector instance at 0x2ad4a70>>
Traceback (most recent call last):
  File "/opt/ros/electric/stacks/ros_comm/clients/rospy/src/rospy/topics.py", line 581, in _invoke_callback
    cb(msg)
  File "/home/alex/MAS/CV/project/cv_nxtdrive/src/depth_detection.py", line 282, in depth_cb
    (contours, img_contours) = self.get_contours(img_fore)
  File "/home/alex/MAS/CV/project/cv_nxtdrive/src/depth_detection.py", line 107, in get_contours
    cont[0] = DepthDetector.merge_contours(cont[0])
  File "/home/alex/MAS/CV/project/cv_nxtdrive/src/depth_detection.py", line 161, in merge_contours
    return cls.merge_contours(new_cont)
  File "/home/alex/MAS/CV/project/cv_nxtdrive/src/depth_detection.py", line 161, in merge_contours
    return cls.merge_contours(new_cont)
  File "/home/alex/MAS/CV/project/cv_nxtdrive/src/depth_detection.py", line 161, in merge_contours
    return cls.merge_contours(new_cont)
  File "/home/alex/MAS/CV/project/cv_nxtdrive/src/depth_detection.py", line 156, in merge_contours
    i, j, i_pos, j_pos = cls.find_close_conts(cont)
  File "/home/alex/MAS/CV/project/cv_nxtdrive/src/depth_detection.py", line 140, in find_close_conts
    cont[36]
IndexError: list index out of range

[rosout][ERROR] 2012-12-15 18:01:55,364: bad callback: <bound method DepthDetector.depth_cb of <__main__.DepthDetector instance at 0x2ad4a70>>
Traceback (most recent call last):
  File "/opt/ros/electric/stacks/ros_comm/clients/rospy/src/rospy/topics.py", line 581, in _invoke_callback
    cb(msg)
  File "/home/alex/MAS/CV/project/cv_nxtdrive/src/depth_detection.py", line 282, in depth_cb
    (contours, img_contours) = self.get_contours(img_fore)
  File "/home/alex/MAS/CV/project/cv_nxtdrive/src/depth_detection.py", line 107, in get_contours
    cont[0] = DepthDetector.merge_contours(cont[0])
  File "/home/alex/MAS/CV/project/cv_nxtdrive/src/depth_detection.py", line 161, in merge_contours
    return cls.merge_contours(new_cont)
  File "/home/alex/MAS/CV/project/cv_nxtdrive/src/depth_detection.py", line 161, in merge_contours
    return cls.merge_contours(new_cont)
  File "/home/alex/MAS/CV/project/cv_nxtdrive/src/depth_detection.py", line 161, in merge_contours
    return cls.merge_contours(new_cont)
  File "/home/alex/MAS/CV/project/cv_nxtdrive/src/depth_detection.py", line 161, in merge_contours
    return cls.merge_contours(new_cont)
  File "/home/alex/MAS/CV/project/cv_nxtdrive/src/depth_detection.py", line 161, in merge_contours
    return cls.merge_contours(new_cont)
  File "/home/alex/MAS/CV/project/cv_nxtdrive/src/depth_detection.py", line 161, in merge_contours
    return cls.merge_contours(new_cont)
  File "/home/alex/MAS/CV/project/cv_nxtdrive/src/depth_detection.py", line 156, in merge_contours
    i, j, i_pos, j_pos = cls.find_close_conts(cont)
  File "/home/alex/MAS/CV/project/cv_nxtdrive/src/depth_detection.py", line 140, in find_close_conts
    cont[36]
IndexError: list index out of range

[rosout][ERROR] 2012-12-15 18:01:55,481: bad callback: <bound method DepthDetector.depth_cb of <__main__.DepthDetector instance at 0x2ad4a70>>
Traceback (most recent call last):
  File "/opt/ros/electric/stacks/ros_comm/clients/rospy/src/rospy/topics.py", line 581, in _invoke_callback
    cb(msg)
  File "/home/alex/MAS/CV/project/cv_nxtdrive/src/depth_detection.py", line 282, in depth_cb
    (contours, img_contours) = self.get_contours(img_fore)
  File "/home/alex/MAS/CV/project/cv_nxtdrive/src/depth_detection.py", line 107, in get_contours
    cont[0] = DepthDetector.merge_contours(cont[0])
TypeError: 'tuple' object does not support item assignment

[rosout][ERROR] 2012-12-15 18:01:55,685: bad callback: <bound method DepthDetector.depth_cb of <__main__.DepthDetector instance at 0x2ad4a70>>
Traceback (most recent call last):
  File "/opt/ros/electric/stacks/ros_comm/clients/rospy/src/rospy/topics.py", line 581, in _invoke_callback
    cb(msg)
  File "/home/alex/MAS/CV/project/cv_nxtdrive/src/depth_detection.py", line 282, in depth_cb
    (contours, img_contours) = self.get_contours(img_fore)
  File "/home/alex/MAS/CV/project/cv_nxtdrive/src/depth_detection.py", line 107, in get_contours
    cont[0] = DepthDetector.merge_contours(cont[0])
TypeError: 'tuple' object does not support item assignment

[rosout][ERROR] 2012-12-15 18:01:55,767: bad callback: <bound method DepthDetector.depth_cb of <__main__.DepthDetector instance at 0x2ad4a70>>
Traceback (most recent call last):
  File "/opt/ros/electric/stacks/ros_comm/clients/rospy/src/rospy/topics.py", line 581, in _invoke_callback
    cb(msg)
  File "/home/alex/MAS/CV/project/cv_nxtdrive/src/depth_detection.py", line 282, in depth_cb
    (contours, img_contours) = self.get_contours(img_fore)
  File "/home/alex/MAS/CV/project/cv_nxtdrive/src/depth_detection.py", line 107, in get_contours
    cont[0] = DepthDetector.merge_contours(cont[0])
  File "/home/alex/MAS/CV/project/cv_nxtdrive/src/depth_detection.py", line 161, in merge_contours
    return cls.merge_contours(new_cont)
  File "/home/alex/MAS/CV/project/cv_nxtdrive/src/depth_detection.py", line 161, in merge_contours
    return cls.merge_contours(new_cont)
  File "/home/alex/MAS/CV/project/cv_nxtdrive/src/depth_detection.py", line 161, in merge_contours
    return cls.merge_contours(new_cont)
  File "/home/alex/MAS/CV/project/cv_nxtdrive/src/depth_detection.py", line 161, in merge_contours
    return cls.merge_contours(new_cont)
  File "/home/alex/MAS/CV/project/cv_nxtdrive/src/depth_detection.py", line 161, in merge_contours
    return cls.merge_contours(new_cont)
  File "/home/alex/MAS/CV/project/cv_nxtdrive/src/depth_detection.py", line 161, in merge_contours
    return cls.merge_contours(new_cont)
  File "/home/alex/MAS/CV/project/cv_nxtdrive/src/depth_detection.py", line 161, in merge_contours
    return cls.merge_contours(new_cont)
  File "/home/alex/MAS/CV/project/cv_nxtdrive/src/depth_detection.py", line 161, in merge_contours
    return cls.merge_contours(new_cont)
  File "/home/alex/MAS/CV/project/cv_nxtdrive/src/depth_detection.py", line 156, in merge_contours
    i, j, i_pos, j_pos = cls.find_close_conts(cont)
  File "/home/alex/MAS/CV/project/cv_nxtdrive/src/depth_detection.py", line 140, in find_close_conts
    cont[36]
IndexError: list index out of range

[rosout][ERROR] 2012-12-15 18:01:55,889: bad callback: <bound method DepthDetector.depth_cb of <__main__.DepthDetector instance at 0x2ad4a70>>
Traceback (most recent call last):
  File "/opt/ros/electric/stacks/ros_comm/clients/rospy/src/rospy/topics.py", line 581, in _invoke_callback
    cb(msg)
  File "/home/alex/MAS/CV/project/cv_nxtdrive/src/depth_detection.py", line 282, in depth_cb
    (contours, img_contours) = self.get_contours(img_fore)
  File "/home/alex/MAS/CV/project/cv_nxtdrive/src/depth_detection.py", line 107, in get_contours
    cont[0] = DepthDetector.merge_contours(cont[0])
  File "/home/alex/MAS/CV/project/cv_nxtdrive/src/depth_detection.py", line 161, in merge_contours
    return cls.merge_contours(new_cont)
  File "/home/alex/MAS/CV/project/cv_nxtdrive/src/depth_detection.py", line 161, in merge_contours
    return cls.merge_contours(new_cont)
  File "/home/alex/MAS/CV/project/cv_nxtdrive/src/depth_detection.py", line 161, in merge_contours
    return cls.merge_contours(new_cont)
  File "/home/alex/MAS/CV/project/cv_nxtdrive/src/depth_detection.py", line 161, in merge_contours
    return cls.merge_contours(new_cont)
  File "/home/alex/MAS/CV/project/cv_nxtdrive/src/depth_detection.py", line 161, in merge_contours
    return cls.merge_contours(new_cont)
  File "/home/alex/MAS/CV/project/cv_nxtdrive/src/depth_detection.py", line 161, in merge_contours
    return cls.merge_contours(new_cont)
  File "/home/alex/MAS/CV/project/cv_nxtdrive/src/depth_detection.py", line 161, in merge_contours
    return cls.merge_contours(new_cont)
  File "/home/alex/MAS/CV/project/cv_nxtdrive/src/depth_detection.py", line 161, in merge_contours
    return cls.merge_contours(new_cont)
  File "/home/alex/MAS/CV/project/cv_nxtdrive/src/depth_detection.py", line 161, in merge_contours
    return cls.merge_contours(new_cont)
  File "/home/alex/MAS/CV/project/cv_nxtdrive/src/depth_detection.py", line 161, in merge_contours
    return cls.merge_contours(new_cont)
  File "/home/alex/MAS/CV/project/cv_nxtdrive/src/depth_detection.py", line 161, in merge_contours
    return cls.merge_contours(new_cont)
  File "/home/alex/MAS/CV/project/cv_nxtdrive/src/depth_detection.py", line 156, in merge_contours
    i, j, i_pos, j_pos = cls.find_close_conts(cont)
  File "/home/alex/MAS/CV/project/cv_nxtdrive/src/depth_detection.py", line 140, in find_close_conts
    cont[36]
IndexError: list index out of range

[rosout][ERROR] 2012-12-15 18:01:55,964: bad callback: <bound method DepthDetector.depth_cb of <__main__.DepthDetector instance at 0x2ad4a70>>
Traceback (most recent call last):
  File "/opt/ros/electric/stacks/ros_comm/clients/rospy/src/rospy/topics.py", line 581, in _invoke_callback
    cb(msg)
  File "/home/alex/MAS/CV/project/cv_nxtdrive/src/depth_detection.py", line 282, in depth_cb
    (contours, img_contours) = self.get_contours(img_fore)
  File "/home/alex/MAS/CV/project/cv_nxtdrive/src/depth_detection.py", line 107, in get_contours
    cont[0] = DepthDetector.merge_contours(cont[0])
  File "/home/alex/MAS/CV/project/cv_nxtdrive/src/depth_detection.py", line 161, in merge_contours
    return cls.merge_contours(new_cont)
  File "/home/alex/MAS/CV/project/cv_nxtdrive/src/depth_detection.py", line 161, in merge_contours
    return cls.merge_contours(new_cont)
  File "/home/alex/MAS/CV/project/cv_nxtdrive/src/depth_detection.py", line 161, in merge_contours
    return cls.merge_contours(new_cont)
  File "/home/alex/MAS/CV/project/cv_nxtdrive/src/depth_detection.py", line 161, in merge_contours
    return cls.merge_contours(new_cont)
  File "/home/alex/MAS/CV/project/cv_nxtdrive/src/depth_detection.py", line 161, in merge_contours
    return cls.merge_contours(new_cont)
  File "/home/alex/MAS/CV/project/cv_nxtdrive/src/depth_detection.py", line 161, in merge_contours
    return cls.merge_contours(new_cont)
  File "/home/alex/MAS/CV/project/cv_nxtdrive/src/depth_detection.py", line 161, in merge_contours
    return cls.merge_contours(new_cont)
  File "/home/alex/MAS/CV/project/cv_nxtdrive/src/depth_detection.py", line 161, in merge_contours
    return cls.merge_contours(new_cont)
  File "/home/alex/MAS/CV/project/cv_nxtdrive/src/depth_detection.py", line 161, in merge_contours
    return cls.merge_contours(new_cont)
  File "/home/alex/MAS/CV/project/cv_nxtdrive/src/depth_detection.py", line 156, in merge_contours
    i, j, i_pos, j_pos = cls.find_close_conts(cont)
  File "/home/alex/MAS/CV/project/cv_nxtdrive/src/depth_detection.py", line 140, in find_close_conts
    cont[36]
IndexError: list index out of range

[rosout][ERROR] 2012-12-15 18:01:56,107: bad callback: <bound method DepthDetector.depth_cb of <__main__.DepthDetector instance at 0x2ad4a70>>
Traceback (most recent call last):
  File "/opt/ros/electric/stacks/ros_comm/clients/rospy/src/rospy/topics.py", line 581, in _invoke_callback
    cb(msg)
  File "/home/alex/MAS/CV/project/cv_nxtdrive/src/depth_detection.py", line 282, in depth_cb
    (contours, img_contours) = self.get_contours(img_fore)
  File "/home/alex/MAS/CV/project/cv_nxtdrive/src/depth_detection.py", line 107, in get_contours
    cont[0] = DepthDetector.merge_contours(cont[0])
TypeError: 'tuple' object does not support item assignment

[rosout][ERROR] 2012-12-15 18:01:56,263: bad callback: <bound method DepthDetector.depth_cb of <__main__.DepthDetector instance at 0x2ad4a70>>
Traceback (most recent call last):
  File "/opt/ros/electric/stacks/ros_comm/clients/rospy/src/rospy/topics.py", line 581, in _invoke_callback
    cb(msg)
  File "/home/alex/MAS/CV/project/cv_nxtdrive/src/depth_detection.py", line 282, in depth_cb
    (contours, img_contours) = self.get_contours(img_fore)
  File "/home/alex/MAS/CV/project/cv_nxtdrive/src/depth_detection.py", line 107, in get_contours
    cont[0] = DepthDetector.merge_contours(cont[0])
TypeError: 'tuple' object does not support item assignment

[rosout][ERROR] 2012-12-15 18:01:56,323: bad callback: <bound method DepthDetector.depth_cb of <__main__.DepthDetector instance at 0x2ad4a70>>
Traceback (most recent call last):
  File "/opt/ros/electric/stacks/ros_comm/clients/rospy/src/rospy/topics.py", line 581, in _invoke_callback
    cb(msg)
  File "/home/alex/MAS/CV/project/cv_nxtdrive/src/depth_detection.py", line 282, in depth_cb
    (contours, img_contours) = self.get_contours(img_fore)
  File "/home/alex/MAS/CV/project/cv_nxtdrive/src/depth_detection.py", line 107, in get_contours
    cont[0] = DepthDetector.merge_contours(cont[0])
  File "/home/alex/MAS/CV/project/cv_nxtdrive/src/depth_detection.py", line 161, in merge_contours
    return cls.merge_contours(new_cont)
  File "/home/alex/MAS/CV/project/cv_nxtdrive/src/depth_detection.py", line 161, in merge_contours
    return cls.merge_contours(new_cont)
  File "/home/alex/MAS/CV/project/cv_nxtdrive/src/depth_detection.py", line 161, in merge_contours
    return cls.merge_contours(new_cont)
  File "/home/alex/MAS/CV/project/cv_nxtdrive/src/depth_detection.py", line 161, in merge_contours
    return cls.merge_contours(new_cont)
  File "/home/alex/MAS/CV/project/cv_nxtdrive/src/depth_detection.py", line 156, in merge_contours
    i, j, i_pos, j_pos = cls.find_close_conts(cont)
  File "/home/alex/MAS/CV/project/cv_nxtdrive/src/depth_detection.py", line 140, in find_close_conts
    cont[36]
IndexError: list index out of range

[rosout][ERROR] 2012-12-15 18:01:56,552: bad callback: <bound method DepthDetector.depth_cb of <__main__.DepthDetector instance at 0x2ad4a70>>
Traceback (most recent call last):
  File "/opt/ros/electric/stacks/ros_comm/clients/rospy/src/rospy/topics.py", line 581, in _invoke_callback
    cb(msg)
  File "/home/alex/MAS/CV/project/cv_nxtdrive/src/depth_detection.py", line 282, in depth_cb
    (contours, img_contours) = self.get_contours(img_fore)
  File "/home/alex/MAS/CV/project/cv_nxtdrive/src/depth_detection.py", line 107, in get_contours
    cont[0] = DepthDetector.merge_contours(cont[0])
TypeError: 'tuple' object does not support item assignment

[rosout][ERROR] 2012-12-15 18:01:56,775: bad callback: <bound method DepthDetector.depth_cb of <__main__.DepthDetector instance at 0x2ad4a70>>
Traceback (most recent call last):
  File "/opt/ros/electric/stacks/ros_comm/clients/rospy/src/rospy/topics.py", line 581, in _invoke_callback
    cb(msg)
  File "/home/alex/MAS/CV/project/cv_nxtdrive/src/depth_detection.py", line 282, in depth_cb
    (contours, img_contours) = self.get_contours(img_fore)
  File "/home/alex/MAS/CV/project/cv_nxtdrive/src/depth_detection.py", line 107, in get_contours
    cont[0] = DepthDetector.merge_contours(cont[0])
TypeError: 'tuple' object does not support item assignment

[rosout][ERROR] 2012-12-15 18:01:56,871: bad callback: <bound method DepthDetector.depth_cb of <__main__.DepthDetector instance at 0x2ad4a70>>
Traceback (most recent call last):
  File "/opt/ros/electric/stacks/ros_comm/clients/rospy/src/rospy/topics.py", line 581, in _invoke_callback
    cb(msg)
  File "/home/alex/MAS/CV/project/cv_nxtdrive/src/depth_detection.py", line 282, in depth_cb
    (contours, img_contours) = self.get_contours(img_fore)
  File "/home/alex/MAS/CV/project/cv_nxtdrive/src/depth_detection.py", line 107, in get_contours
    cont[0] = DepthDetector.merge_contours(cont[0])
  File "/home/alex/MAS/CV/project/cv_nxtdrive/src/depth_detection.py", line 161, in merge_contours
    return cls.merge_contours(new_cont)
  File "/home/alex/MAS/CV/project/cv_nxtdrive/src/depth_detection.py", line 161, in merge_contours
    return cls.merge_contours(new_cont)
  File "/home/alex/MAS/CV/project/cv_nxtdrive/src/depth_detection.py", line 161, in merge_contours
    return cls.merge_contours(new_cont)
  File "/home/alex/MAS/CV/project/cv_nxtdrive/src/depth_detection.py", line 161, in merge_contours
    return cls.merge_contours(new_cont)
  File "/home/alex/MAS/CV/project/cv_nxtdrive/src/depth_detection.py", line 161, in merge_contours
    return cls.merge_contours(new_cont)
  File "/home/alex/MAS/CV/project/cv_nxtdrive/src/depth_detection.py", line 161, in merge_contours
    return cls.merge_contours(new_cont)
  File "/home/alex/MAS/CV/project/cv_nxtdrive/src/depth_detection.py", line 161, in merge_contours
    return cls.merge_contours(new_cont)
  File "/home/alex/MAS/CV/project/cv_nxtdrive/src/depth_detection.py", line 161, in merge_contours
    return cls.merge_contours(new_cont)
  File "/home/alex/MAS/CV/project/cv_nxtdrive/src/depth_detection.py", line 156, in merge_contours
    i, j, i_pos, j_pos = cls.find_close_conts(cont)
  File "/home/alex/MAS/CV/project/cv_nxtdrive/src/depth_detection.py", line 140, in find_close_conts
    cont[36]
IndexError: list index out of range

[rosout][ERROR] 2012-12-15 18:01:57,004: bad callback: <bound method DepthDetector.depth_cb of <__main__.DepthDetector instance at 0x2ad4a70>>
Traceback (most recent call last):
  File "/opt/ros/electric/stacks/ros_comm/clients/rospy/src/rospy/topics.py", line 581, in _invoke_callback
    cb(msg)
  File "/home/alex/MAS/CV/project/cv_nxtdrive/src/depth_detection.py", line 282, in depth_cb
    (contours, img_contours) = self.get_contours(img_fore)
  File "/home/alex/MAS/CV/project/cv_nxtdrive/src/depth_detection.py", line 107, in get_contours
    cont[0] = DepthDetector.merge_contours(cont[0])
TypeError: 'tuple' object does not support item assignment

[rosout][ERROR] 2012-12-15 18:01:57,171: bad callback: <bound method DepthDetector.depth_cb of <__main__.DepthDetector instance at 0x2ad4a70>>
Traceback (most recent call last):
  File "/opt/ros/electric/stacks/ros_comm/clients/rospy/src/rospy/topics.py", line 581, in _invoke_callback
    cb(msg)
  File "/home/alex/MAS/CV/project/cv_nxtdrive/src/depth_detection.py", line 282, in depth_cb
    (contours, img_contours) = self.get_contours(img_fore)
  File "/home/alex/MAS/CV/project/cv_nxtdrive/src/depth_detection.py", line 107, in get_contours
    cont[0] = DepthDetector.merge_contours(cont[0])
TypeError: 'tuple' object does not support item assignment

[rosout][ERROR] 2012-12-15 18:01:57,341: bad callback: <bound method DepthDetector.depth_cb of <__main__.DepthDetector instance at 0x2ad4a70>>
Traceback (most recent call last):
  File "/opt/ros/electric/stacks/ros_comm/clients/rospy/src/rospy/topics.py", line 581, in _invoke_callback
    cb(msg)
  File "/home/alex/MAS/CV/project/cv_nxtdrive/src/depth_detection.py", line 282, in depth_cb
    (contours, img_contours) = self.get_contours(img_fore)
  File "/home/alex/MAS/CV/project/cv_nxtdrive/src/depth_detection.py", line 107, in get_contours
    cont[0] = DepthDetector.merge_contours(cont[0])
TypeError: 'tuple' object does not support item assignment

[rosout][ERROR] 2012-12-15 18:01:57,422: bad callback: <bound method DepthDetector.depth_cb of <__main__.DepthDetector instance at 0x2ad4a70>>
Traceback (most recent call last):
  File "/opt/ros/electric/stacks/ros_comm/clients/rospy/src/rospy/topics.py", line 581, in _invoke_callback
    cb(msg)
  File "/home/alex/MAS/CV/project/cv_nxtdrive/src/depth_detection.py", line 282, in depth_cb
    (contours, img_contours) = self.get_contours(img_fore)
  File "/home/alex/MAS/CV/project/cv_nxtdrive/src/depth_detection.py", line 107, in get_contours
    cont[0] = DepthDetector.merge_contours(cont[0])
  File "/home/alex/MAS/CV/project/cv_nxtdrive/src/depth_detection.py", line 161, in merge_contours
    return cls.merge_contours(new_cont)
  File "/home/alex/MAS/CV/project/cv_nxtdrive/src/depth_detection.py", line 161, in merge_contours
    return cls.merge_contours(new_cont)
  File "/home/alex/MAS/CV/project/cv_nxtdrive/src/depth_detection.py", line 161, in merge_contours
    return cls.merge_contours(new_cont)
  File "/home/alex/MAS/CV/project/cv_nxtdrive/src/depth_detection.py", line 161, in merge_contours
    return cls.merge_contours(new_cont)
  File "/home/alex/MAS/CV/project/cv_nxtdrive/src/depth_detection.py", line 161, in merge_contours
    return cls.merge_contours(new_cont)
  File "/home/alex/MAS/CV/project/cv_nxtdrive/src/depth_detection.py", line 161, in merge_contours
    return cls.merge_contours(new_cont)
  File "/home/alex/MAS/CV/project/cv_nxtdrive/src/depth_detection.py", line 161, in merge_contours
    return cls.merge_contours(new_cont)
  File "/home/alex/MAS/CV/project/cv_nxtdrive/src/depth_detection.py", line 161, in merge_contours
    return cls.merge_contours(new_cont)
  File "/home/alex/MAS/CV/project/cv_nxtdrive/src/depth_detection.py", line 156, in merge_contours
    i, j, i_pos, j_pos = cls.find_close_conts(cont)
  File "/home/alex/MAS/CV/project/cv_nxtdrive/src/depth_detection.py", line 140, in find_close_conts
    cont[36]
IndexError: list index out of range

[rosout][ERROR] 2012-12-15 18:01:57,516: bad callback: <bound method DepthDetector.depth_cb of <__main__.DepthDetector instance at 0x2ad4a70>>
Traceback (most recent call last):
  File "/opt/ros/electric/stacks/ros_comm/clients/rospy/src/rospy/topics.py", line 581, in _invoke_callback
    cb(msg)
  File "/home/alex/MAS/CV/project/cv_nxtdrive/src/depth_detection.py", line 282, in depth_cb
    (contours, img_contours) = self.get_contours(img_fore)
  File "/home/alex/MAS/CV/project/cv_nxtdrive/src/depth_detection.py", line 107, in get_contours
    cont[0] = DepthDetector.merge_contours(cont[0])
  File "/home/alex/MAS/CV/project/cv_nxtdrive/src/depth_detection.py", line 161, in merge_contours
    return cls.merge_contours(new_cont)
  File "/home/alex/MAS/CV/project/cv_nxtdrive/src/depth_detection.py", line 161, in merge_contours
    return cls.merge_contours(new_cont)
  File "/home/alex/MAS/CV/project/cv_nxtdrive/src/depth_detection.py", line 161, in merge_contours
    return cls.merge_contours(new_cont)
  File "/home/alex/MAS/CV/project/cv_nxtdrive/src/depth_detection.py", line 161, in merge_contours
    return cls.merge_contours(new_cont)
  File "/home/alex/MAS/CV/project/cv_nxtdrive/src/depth_detection.py", line 161, in merge_contours
    return cls.merge_contours(new_cont)
  File "/home/alex/MAS/CV/project/cv_nxtdrive/src/depth_detection.py", line 161, in merge_contours
    return cls.merge_contours(new_cont)
  File "/home/alex/MAS/CV/project/cv_nxtdrive/src/depth_detection.py", line 156, in merge_contours
    i, j, i_pos, j_pos = cls.find_close_conts(cont)
  File "/home/alex/MAS/CV/project/cv_nxtdrive/src/depth_detection.py", line 140, in find_close_conts
    cont[36]
IndexError: list index out of range

[rosout][ERROR] 2012-12-15 18:01:57,629: bad callback: <bound method DepthDetector.depth_cb of <__main__.DepthDetector instance at 0x2ad4a70>>
Traceback (most recent call last):
  File "/opt/ros/electric/stacks/ros_comm/clients/rospy/src/rospy/topics.py", line 581, in _invoke_callback
    cb(msg)
  File "/home/alex/MAS/CV/project/cv_nxtdrive/src/depth_detection.py", line 282, in depth_cb
    (contours, img_contours) = self.get_contours(img_fore)
  File "/home/alex/MAS/CV/project/cv_nxtdrive/src/depth_detection.py", line 107, in get_contours
    cont[0] = DepthDetector.merge_contours(cont[0])
  File "/home/alex/MAS/CV/project/cv_nxtdrive/src/depth_detection.py", line 161, in merge_contours
    return cls.merge_contours(new_cont)
  File "/home/alex/MAS/CV/project/cv_nxtdrive/src/depth_detection.py", line 161, in merge_contours
    return cls.merge_contours(new_cont)
  File "/home/alex/MAS/CV/project/cv_nxtdrive/src/depth_detection.py", line 161, in merge_contours
    return cls.merge_contours(new_cont)
  File "/home/alex/MAS/CV/project/cv_nxtdrive/src/depth_detection.py", line 161, in merge_contours
    return cls.merge_contours(new_cont)
  File "/home/alex/MAS/CV/project/cv_nxtdrive/src/depth_detection.py", line 161, in merge_contours
    return cls.merge_contours(new_cont)
  File "/home/alex/MAS/CV/project/cv_nxtdrive/src/depth_detection.py", line 161, in merge_contours
    return cls.merge_contours(new_cont)
  File "/home/alex/MAS/CV/project/cv_nxtdrive/src/depth_detection.py", line 161, in merge_contours
    return cls.merge_contours(new_cont)
  File "/home/alex/MAS/CV/project/cv_nxtdrive/src/depth_detection.py", line 161, in merge_contours
    return cls.merge_contours(new_cont)
  File "/home/alex/MAS/CV/project/cv_nxtdrive/src/depth_detection.py", line 156, in merge_contours
    i, j, i_pos, j_pos = cls.find_close_conts(cont)
  File "/home/alex/MAS/CV/project/cv_nxtdrive/src/depth_detection.py", line 140, in find_close_conts
    cont[36]
IndexError: list index out of range

[rosout][ERROR] 2012-12-15 18:01:57,811: bad callback: <bound method DepthDetector.depth_cb of <__main__.DepthDetector instance at 0x2ad4a70>>
Traceback (most recent call last):
  File "/opt/ros/electric/stacks/ros_comm/clients/rospy/src/rospy/topics.py", line 581, in _invoke_callback
    cb(msg)
  File "/home/alex/MAS/CV/project/cv_nxtdrive/src/depth_detection.py", line 282, in depth_cb
    (contours, img_contours) = self.get_contours(img_fore)
  File "/home/alex/MAS/CV/project/cv_nxtdrive/src/depth_detection.py", line 107, in get_contours
    cont[0] = DepthDetector.merge_contours(cont[0])
TypeError: 'tuple' object does not support item assignment

[rosout][ERROR] 2012-12-15 18:01:57,958: bad callback: <bound method DepthDetector.depth_cb of <__main__.DepthDetector instance at 0x2ad4a70>>
Traceback (most recent call last):
  File "/opt/ros/electric/stacks/ros_comm/clients/rospy/src/rospy/topics.py", line 581, in _invoke_callback
    cb(msg)
  File "/home/alex/MAS/CV/project/cv_nxtdrive/src/depth_detection.py", line 282, in depth_cb
    (contours, img_contours) = self.get_contours(img_fore)
  File "/home/alex/MAS/CV/project/cv_nxtdrive/src/depth_detection.py", line 107, in get_contours
    cont[0] = DepthDetector.merge_contours(cont[0])
TypeError: 'tuple' object does not support item assignment

[rosout][ERROR] 2012-12-15 18:01:58,070: bad callback: <bound method DepthDetector.depth_cb of <__main__.DepthDetector instance at 0x2ad4a70>>
Traceback (most recent call last):
  File "/opt/ros/electric/stacks/ros_comm/clients/rospy/src/rospy/topics.py", line 581, in _invoke_callback
    cb(msg)
  File "/home/alex/MAS/CV/project/cv_nxtdrive/src/depth_detection.py", line 282, in depth_cb
    (contours, img_contours) = self.get_contours(img_fore)
  File "/home/alex/MAS/CV/project/cv_nxtdrive/src/depth_detection.py", line 107, in get_contours
    cont[0] = DepthDetector.merge_contours(cont[0])
TypeError: 'tuple' object does not support item assignment

[rosout][ERROR] 2012-12-15 18:01:58,118: bad callback: <bound method DepthDetector.depth_cb of <__main__.DepthDetector instance at 0x2ad4a70>>
Traceback (most recent call last):
  File "/opt/ros/electric/stacks/ros_comm/clients/rospy/src/rospy/topics.py", line 581, in _invoke_callback
    cb(msg)
  File "/home/alex/MAS/CV/project/cv_nxtdrive/src/depth_detection.py", line 282, in depth_cb
    (contours, img_contours) = self.get_contours(img_fore)
  File "/home/alex/MAS/CV/project/cv_nxtdrive/src/depth_detection.py", line 107, in get_contours
    cont[0] = DepthDetector.merge_contours(cont[0])
  File "/home/alex/MAS/CV/project/cv_nxtdrive/src/depth_detection.py", line 161, in merge_contours
    return cls.merge_contours(new_cont)
  File "/home/alex/MAS/CV/project/cv_nxtdrive/src/depth_detection.py", line 161, in merge_contours
    return cls.merge_contours(new_cont)
  File "/home/alex/MAS/CV/project/cv_nxtdrive/src/depth_detection.py", line 161, in merge_contours
    return cls.merge_contours(new_cont)
  File "/home/alex/MAS/CV/project/cv_nxtdrive/src/depth_detection.py", line 156, in merge_contours
    i, j, i_pos, j_pos = cls.find_close_conts(cont)
  File "/home/alex/MAS/CV/project/cv_nxtdrive/src/depth_detection.py", line 140, in find_close_conts
    cont[36]
IndexError: list index out of range

[rosout][ERROR] 2012-12-15 18:01:58,277: bad callback: <bound method DepthDetector.depth_cb of <__main__.DepthDetector instance at 0x2ad4a70>>
Traceback (most recent call last):
  File "/opt/ros/electric/stacks/ros_comm/clients/rospy/src/rospy/topics.py", line 581, in _invoke_callback
    cb(msg)
  File "/home/alex/MAS/CV/project/cv_nxtdrive/src/depth_detection.py", line 282, in depth_cb
    (contours, img_contours) = self.get_contours(img_fore)
  File "/home/alex/MAS/CV/project/cv_nxtdrive/src/depth_detection.py", line 107, in get_contours
    cont[0] = DepthDetector.merge_contours(cont[0])
TypeError: 'tuple' object does not support item assignment

[rosout][ERROR] 2012-12-15 18:01:58,461: bad callback: <bound method DepthDetector.depth_cb of <__main__.DepthDetector instance at 0x2ad4a70>>
Traceback (most recent call last):
  File "/opt/ros/electric/stacks/ros_comm/clients/rospy/src/rospy/topics.py", line 581, in _invoke_callback
    cb(msg)
  File "/home/alex/MAS/CV/project/cv_nxtdrive/src/depth_detection.py", line 282, in depth_cb
    (contours, img_contours) = self.get_contours(img_fore)
  File "/home/alex/MAS/CV/project/cv_nxtdrive/src/depth_detection.py", line 107, in get_contours
    cont[0] = DepthDetector.merge_contours(cont[0])
TypeError: 'tuple' object does not support item assignment

[rosout][ERROR] 2012-12-15 18:01:58,542: bad callback: <bound method DepthDetector.depth_cb of <__main__.DepthDetector instance at 0x2ad4a70>>
Traceback (most recent call last):
  File "/opt/ros/electric/stacks/ros_comm/clients/rospy/src/rospy/topics.py", line 581, in _invoke_callback
    cb(msg)
  File "/home/alex/MAS/CV/project/cv_nxtdrive/src/depth_detection.py", line 282, in depth_cb
    (contours, img_contours) = self.get_contours(img_fore)
  File "/home/alex/MAS/CV/project/cv_nxtdrive/src/depth_detection.py", line 107, in get_contours
    cont[0] = DepthDetector.merge_contours(cont[0])
  File "/home/alex/MAS/CV/project/cv_nxtdrive/src/depth_detection.py", line 161, in merge_contours
    return cls.merge_contours(new_cont)
  File "/home/alex/MAS/CV/project/cv_nxtdrive/src/depth_detection.py", line 161, in merge_contours
    return cls.merge_contours(new_cont)
  File "/home/alex/MAS/CV/project/cv_nxtdrive/src/depth_detection.py", line 161, in merge_contours
    return cls.merge_contours(new_cont)
  File "/home/alex/MAS/CV/project/cv_nxtdrive/src/depth_detection.py", line 161, in merge_contours
    return cls.merge_contours(new_cont)
  File "/home/alex/MAS/CV/project/cv_nxtdrive/src/depth_detection.py", line 161, in merge_contours
    return cls.merge_contours(new_cont)
  File "/home/alex/MAS/CV/project/cv_nxtdrive/src/depth_detection.py", line 161, in merge_contours
    return cls.merge_contours(new_cont)
  File "/home/alex/MAS/CV/project/cv_nxtdrive/src/depth_detection.py", line 161, in merge_contours
    return cls.merge_contours(new_cont)
  File "/home/alex/MAS/CV/project/cv_nxtdrive/src/depth_detection.py", line 161, in merge_contours
    return cls.merge_contours(new_cont)
  File "/home/alex/MAS/CV/project/cv_nxtdrive/src/depth_detection.py", line 161, in merge_contours
    return cls.merge_contours(new_cont)
  File "/home/alex/MAS/CV/project/cv_nxtdrive/src/depth_detection.py", line 161, in merge_contours
    return cls.merge_contours(new_cont)
  File "/home/alex/MAS/CV/project/cv_nxtdrive/src/depth_detection.py", line 156, in merge_contours
    i, j, i_pos, j_pos = cls.find_close_conts(cont)
  File "/home/alex/MAS/CV/project/cv_nxtdrive/src/depth_detection.py", line 140, in find_close_conts
    cont[36]
IndexError: list index out of range

[rosout][ERROR] 2012-12-15 18:01:58,691: bad callback: <bound method DepthDetector.depth_cb of <__main__.DepthDetector instance at 0x2ad4a70>>
Traceback (most recent call last):
  File "/opt/ros/electric/stacks/ros_comm/clients/rospy/src/rospy/topics.py", line 581, in _invoke_callback
    cb(msg)
  File "/home/alex/MAS/CV/project/cv_nxtdrive/src/depth_detection.py", line 282, in depth_cb
    (contours, img_contours) = self.get_contours(img_fore)
  File "/home/alex/MAS/CV/project/cv_nxtdrive/src/depth_detection.py", line 107, in get_contours
    cont[0] = DepthDetector.merge_contours(cont[0])
TypeError: 'tuple' object does not support item assignment

[rosout][ERROR] 2012-12-15 18:01:58,803: bad callback: <bound method DepthDetector.depth_cb of <__main__.DepthDetector instance at 0x2ad4a70>>
Traceback (most recent call last):
  File "/opt/ros/electric/stacks/ros_comm/clients/rospy/src/rospy/topics.py", line 581, in _invoke_callback
    cb(msg)
  File "/home/alex/MAS/CV/project/cv_nxtdrive/src/depth_detection.py", line 282, in depth_cb
    (contours, img_contours) = self.get_contours(img_fore)
  File "/home/alex/MAS/CV/project/cv_nxtdrive/src/depth_detection.py", line 107, in get_contours
    cont[0] = DepthDetector.merge_contours(cont[0])
  File "/home/alex/MAS/CV/project/cv_nxtdrive/src/depth_detection.py", line 161, in merge_contours
    return cls.merge_contours(new_cont)
  File "/home/alex/MAS/CV/project/cv_nxtdrive/src/depth_detection.py", line 161, in merge_contours
    return cls.merge_contours(new_cont)
  File "/home/alex/MAS/CV/project/cv_nxtdrive/src/depth_detection.py", line 161, in merge_contours
    return cls.merge_contours(new_cont)
  File "/home/alex/MAS/CV/project/cv_nxtdrive/src/depth_detection.py", line 161, in merge_contours
    return cls.merge_contours(new_cont)
  File "/home/alex/MAS/CV/project/cv_nxtdrive/src/depth_detection.py", line 161, in merge_contours
    return cls.merge_contours(new_cont)
  File "/home/alex/MAS/CV/project/cv_nxtdrive/src/depth_detection.py", line 161, in merge_contours
    return cls.merge_contours(new_cont)
  File "/home/alex/MAS/CV/project/cv_nxtdrive/src/depth_detection.py", line 156, in merge_contours
    i, j, i_pos, j_pos = cls.find_close_conts(cont)
  File "/home/alex/MAS/CV/project/cv_nxtdrive/src/depth_detection.py", line 140, in find_close_conts
    cont[36]
IndexError: list index out of range

[rosout][ERROR] 2012-12-15 18:01:58,861: bad callback: <bound method DepthDetector.depth_cb of <__main__.DepthDetector instance at 0x2ad4a70>>
Traceback (most recent call last):
  File "/opt/ros/electric/stacks/ros_comm/clients/rospy/src/rospy/topics.py", line 581, in _invoke_callback
    cb(msg)
  File "/home/alex/MAS/CV/project/cv_nxtdrive/src/depth_detection.py", line 282, in depth_cb
    (contours, img_contours) = self.get_contours(img_fore)
  File "/home/alex/MAS/CV/project/cv_nxtdrive/src/depth_detection.py", line 107, in get_contours
    cont[0] = DepthDetector.merge_contours(cont[0])
  File "/home/alex/MAS/CV/project/cv_nxtdrive/src/depth_detection.py", line 161, in merge_contours
    return cls.merge_contours(new_cont)
  File "/home/alex/MAS/CV/project/cv_nxtdrive/src/depth_detection.py", line 161, in merge_contours
    return cls.merge_contours(new_cont)
  File "/home/alex/MAS/CV/project/cv_nxtdrive/src/depth_detection.py", line 161, in merge_contours
    return cls.merge_contours(new_cont)
  File "/home/alex/MAS/CV/project/cv_nxtdrive/src/depth_detection.py", line 161, in merge_contours
    return cls.merge_contours(new_cont)
  File "/home/alex/MAS/CV/project/cv_nxtdrive/src/depth_detection.py", line 161, in merge_contours
    return cls.merge_contours(new_cont)
  File "/home/alex/MAS/CV/project/cv_nxtdrive/src/depth_detection.py", line 161, in merge_contours
    return cls.merge_contours(new_cont)
  File "/home/alex/MAS/CV/project/cv_nxtdrive/src/depth_detection.py", line 161, in merge_contours
    return cls.merge_contours(new_cont)
  File "/home/alex/MAS/CV/project/cv_nxtdrive/src/depth_detection.py", line 161, in merge_contours
    return cls.merge_contours(new_cont)
  File "/home/alex/MAS/CV/project/cv_nxtdrive/src/depth_detection.py", line 156, in merge_contours
    i, j, i_pos, j_pos = cls.find_close_conts(cont)
  File "/home/alex/MAS/CV/project/cv_nxtdrive/src/depth_detection.py", line 140, in find_close_conts
    cont[36]
IndexError: list index out of range

[rosout][ERROR] 2012-12-15 18:01:59,001: bad callback: <bound method DepthDetector.depth_cb of <__main__.DepthDetector instance at 0x2ad4a70>>
Traceback (most recent call last):
  File "/opt/ros/electric/stacks/ros_comm/clients/rospy/src/rospy/topics.py", line 581, in _invoke_callback
    cb(msg)
  File "/home/alex/MAS/CV/project/cv_nxtdrive/src/depth_detection.py", line 282, in depth_cb
    (contours, img_contours) = self.get_contours(img_fore)
  File "/home/alex/MAS/CV/project/cv_nxtdrive/src/depth_detection.py", line 107, in get_contours
    cont[0] = DepthDetector.merge_contours(cont[0])
TypeError: 'tuple' object does not support item assignment

[rosout][ERROR] 2012-12-15 18:01:59,086: bad callback: <bound method DepthDetector.depth_cb of <__main__.DepthDetector instance at 0x2ad4a70>>
Traceback (most recent call last):
  File "/opt/ros/electric/stacks/ros_comm/clients/rospy/src/rospy/topics.py", line 581, in _invoke_callback
    cb(msg)
  File "/home/alex/MAS/CV/project/cv_nxtdrive/src/depth_detection.py", line 282, in depth_cb
    (contours, img_contours) = self.get_contours(img_fore)
  File "/home/alex/MAS/CV/project/cv_nxtdrive/src/depth_detection.py", line 107, in get_contours
    cont[0] = DepthDetector.merge_contours(cont[0])
  File "/home/alex/MAS/CV/project/cv_nxtdrive/src/depth_detection.py", line 161, in merge_contours
    return cls.merge_contours(new_cont)
  File "/home/alex/MAS/CV/project/cv_nxtdrive/src/depth_detection.py", line 161, in merge_contours
    return cls.merge_contours(new_cont)
  File "/home/alex/MAS/CV/project/cv_nxtdrive/src/depth_detection.py", line 161, in merge_contours
    return cls.merge_contours(new_cont)
  File "/home/alex/MAS/CV/project/cv_nxtdrive/src/depth_detection.py", line 161, in merge_contours
    return cls.merge_contours(new_cont)
  File "/home/alex/MAS/CV/project/cv_nxtdrive/src/depth_detection.py", line 161, in merge_contours
    return cls.merge_contours(new_cont)
  File "/home/alex/MAS/CV/project/cv_nxtdrive/src/depth_detection.py", line 161, in merge_contours
    return cls.merge_contours(new_cont)
  File "/home/alex/MAS/CV/project/cv_nxtdrive/src/depth_detection.py", line 161, in merge_contours
    return cls.merge_contours(new_cont)
  File "/home/alex/MAS/CV/project/cv_nxtdrive/src/depth_detection.py", line 161, in merge_contours
    return cls.merge_contours(new_cont)
  File "/home/alex/MAS/CV/project/cv_nxtdrive/src/depth_detection.py", line 161, in merge_contours
    return cls.merge_contours(new_cont)
  File "/home/alex/MAS/CV/project/cv_nxtdrive/src/depth_detection.py", line 161, in merge_contours
    return cls.merge_contours(new_cont)
  File "/home/alex/MAS/CV/project/cv_nxtdrive/src/depth_detection.py", line 161, in merge_contours
    return cls.merge_contours(new_cont)
  File "/home/alex/MAS/CV/project/cv_nxtdrive/src/depth_detection.py", line 161, in merge_contours
    return cls.merge_contours(new_cont)
  File "/home/alex/MAS/CV/project/cv_nxtdrive/src/depth_detection.py", line 156, in merge_contours
    i, j, i_pos, j_pos = cls.find_close_conts(cont)
  File "/home/alex/MAS/CV/project/cv_nxtdrive/src/depth_detection.py", line 140, in find_close_conts
    cont[36]
IndexError: list index out of range

[rosout][ERROR] 2012-12-15 18:01:59,239: bad callback: <bound method DepthDetector.depth_cb of <__main__.DepthDetector instance at 0x2ad4a70>>
Traceback (most recent call last):
  File "/opt/ros/electric/stacks/ros_comm/clients/rospy/src/rospy/topics.py", line 581, in _invoke_callback
    cb(msg)
  File "/home/alex/MAS/CV/project/cv_nxtdrive/src/depth_detection.py", line 282, in depth_cb
    (contours, img_contours) = self.get_contours(img_fore)
  File "/home/alex/MAS/CV/project/cv_nxtdrive/src/depth_detection.py", line 107, in get_contours
    cont[0] = DepthDetector.merge_contours(cont[0])
TypeError: 'tuple' object does not support item assignment

[rosout][ERROR] 2012-12-15 18:01:59,280: bad callback: <bound method DepthDetector.depth_cb of <__main__.DepthDetector instance at 0x2ad4a70>>
Traceback (most recent call last):
  File "/opt/ros/electric/stacks/ros_comm/clients/rospy/src/rospy/topics.py", line 581, in _invoke_callback
    cb(msg)
  File "/home/alex/MAS/CV/project/cv_nxtdrive/src/depth_detection.py", line 282, in depth_cb
    (contours, img_contours) = self.get_contours(img_fore)
  File "/home/alex/MAS/CV/project/cv_nxtdrive/src/depth_detection.py", line 107, in get_contours
    cont[0] = DepthDetector.merge_contours(cont[0])
  File "/home/alex/MAS/CV/project/cv_nxtdrive/src/depth_detection.py", line 161, in merge_contours
    return cls.merge_contours(new_cont)
  File "/home/alex/MAS/CV/project/cv_nxtdrive/src/depth_detection.py", line 161, in merge_contours
    return cls.merge_contours(new_cont)
  File "/home/alex/MAS/CV/project/cv_nxtdrive/src/depth_detection.py", line 161, in merge_contours
    return cls.merge_contours(new_cont)
  File "/home/alex/MAS/CV/project/cv_nxtdrive/src/depth_detection.py", line 156, in merge_contours
    i, j, i_pos, j_pos = cls.find_close_conts(cont)
  File "/home/alex/MAS/CV/project/cv_nxtdrive/src/depth_detection.py", line 140, in find_close_conts
    cont[36]
IndexError: list index out of range

[rosout][ERROR] 2012-12-15 18:01:59,473: bad callback: <bound method DepthDetector.depth_cb of <__main__.DepthDetector instance at 0x2ad4a70>>
Traceback (most recent call last):
  File "/opt/ros/electric/stacks/ros_comm/clients/rospy/src/rospy/topics.py", line 581, in _invoke_callback
    cb(msg)
  File "/home/alex/MAS/CV/project/cv_nxtdrive/src/depth_detection.py", line 282, in depth_cb
    (contours, img_contours) = self.get_contours(img_fore)
  File "/home/alex/MAS/CV/project/cv_nxtdrive/src/depth_detection.py", line 107, in get_contours
    cont[0] = DepthDetector.merge_contours(cont[0])
TypeError: 'tuple' object does not support item assignment

[rosout][ERROR] 2012-12-15 18:01:59,587: bad callback: <bound method DepthDetector.depth_cb of <__main__.DepthDetector instance at 0x2ad4a70>>
Traceback (most recent call last):
  File "/opt/ros/electric/stacks/ros_comm/clients/rospy/src/rospy/topics.py", line 581, in _invoke_callback
    cb(msg)
  File "/home/alex/MAS/CV/project/cv_nxtdrive/src/depth_detection.py", line 282, in depth_cb
    (contours, img_contours) = self.get_contours(img_fore)
  File "/home/alex/MAS/CV/project/cv_nxtdrive/src/depth_detection.py", line 107, in get_contours
    cont[0] = DepthDetector.merge_contours(cont[0])
TypeError: 'tuple' object does not support item assignment

[rosout][ERROR] 2012-12-15 18:01:59,781: bad callback: <bound method DepthDetector.depth_cb of <__main__.DepthDetector instance at 0x2ad4a70>>
Traceback (most recent call last):
  File "/opt/ros/electric/stacks/ros_comm/clients/rospy/src/rospy/topics.py", line 581, in _invoke_callback
    cb(msg)
  File "/home/alex/MAS/CV/project/cv_nxtdrive/src/depth_detection.py", line 282, in depth_cb
    (contours, img_contours) = self.get_contours(img_fore)
  File "/home/alex/MAS/CV/project/cv_nxtdrive/src/depth_detection.py", line 107, in get_contours
    cont[0] = DepthDetector.merge_contours(cont[0])
TypeError: 'tuple' object does not support item assignment

[rosout][ERROR] 2012-12-15 18:02:00,017: bad callback: <bound method DepthDetector.depth_cb of <__main__.DepthDetector instance at 0x2ad4a70>>
Traceback (most recent call last):
  File "/opt/ros/electric/stacks/ros_comm/clients/rospy/src/rospy/topics.py", line 581, in _invoke_callback
    cb(msg)
  File "/home/alex/MAS/CV/project/cv_nxtdrive/src/depth_detection.py", line 282, in depth_cb
    (contours, img_contours) = self.get_contours(img_fore)
  File "/home/alex/MAS/CV/project/cv_nxtdrive/src/depth_detection.py", line 107, in get_contours
    cont[0] = DepthDetector.merge_contours(cont[0])
TypeError: 'tuple' object does not support item assignment

[rosout][ERROR] 2012-12-15 18:02:00,072: bad callback: <bound method DepthDetector.depth_cb of <__main__.DepthDetector instance at 0x2ad4a70>>
Traceback (most recent call last):
  File "/opt/ros/electric/stacks/ros_comm/clients/rospy/src/rospy/topics.py", line 581, in _invoke_callback
    cb(msg)
  File "/home/alex/MAS/CV/project/cv_nxtdrive/src/depth_detection.py", line 282, in depth_cb
    (contours, img_contours) = self.get_contours(img_fore)
  File "/home/alex/MAS/CV/project/cv_nxtdrive/src/depth_detection.py", line 107, in get_contours
    cont[0] = DepthDetector.merge_contours(cont[0])
  File "/home/alex/MAS/CV/project/cv_nxtdrive/src/depth_detection.py", line 161, in merge_contours
    return cls.merge_contours(new_cont)
  File "/home/alex/MAS/CV/project/cv_nxtdrive/src/depth_detection.py", line 161, in merge_contours
    return cls.merge_contours(new_cont)
  File "/home/alex/MAS/CV/project/cv_nxtdrive/src/depth_detection.py", line 161, in merge_contours
    return cls.merge_contours(new_cont)
  File "/home/alex/MAS/CV/project/cv_nxtdrive/src/depth_detection.py", line 161, in merge_contours
    return cls.merge_contours(new_cont)
  File "/home/alex/MAS/CV/project/cv_nxtdrive/src/depth_detection.py", line 156, in merge_contours
    i, j, i_pos, j_pos = cls.find_close_conts(cont)
  File "/home/alex/MAS/CV/project/cv_nxtdrive/src/depth_detection.py", line 140, in find_close_conts
    cont[36]
IndexError: list index out of range

[rosout][ERROR] 2012-12-15 18:02:00,177: bad callback: <bound method DepthDetector.depth_cb of <__main__.DepthDetector instance at 0x2ad4a70>>
Traceback (most recent call last):
  File "/opt/ros/electric/stacks/ros_comm/clients/rospy/src/rospy/topics.py", line 581, in _invoke_callback
    cb(msg)
  File "/home/alex/MAS/CV/project/cv_nxtdrive/src/depth_detection.py", line 282, in depth_cb
    (contours, img_contours) = self.get_contours(img_fore)
  File "/home/alex/MAS/CV/project/cv_nxtdrive/src/depth_detection.py", line 107, in get_contours
    cont[0] = DepthDetector.merge_contours(cont[0])
  File "/home/alex/MAS/CV/project/cv_nxtdrive/src/depth_detection.py", line 161, in merge_contours
    return cls.merge_contours(new_cont)
  File "/home/alex/MAS/CV/project/cv_nxtdrive/src/depth_detection.py", line 161, in merge_contours
    return cls.merge_contours(new_cont)
  File "/home/alex/MAS/CV/project/cv_nxtdrive/src/depth_detection.py", line 161, in merge_contours
    return cls.merge_contours(new_cont)
  File "/home/alex/MAS/CV/project/cv_nxtdrive/src/depth_detection.py", line 161, in merge_contours
    return cls.merge_contours(new_cont)
  File "/home/alex/MAS/CV/project/cv_nxtdrive/src/depth_detection.py", line 161, in merge_contours
    return cls.merge_contours(new_cont)
  File "/home/alex/MAS/CV/project/cv_nxtdrive/src/depth_detection.py", line 161, in merge_contours
    return cls.merge_contours(new_cont)
  File "/home/alex/MAS/CV/project/cv_nxtdrive/src/depth_detection.py", line 161, in merge_contours
    return cls.merge_contours(new_cont)
  File "/home/alex/MAS/CV/project/cv_nxtdrive/src/depth_detection.py", line 156, in merge_contours
    i, j, i_pos, j_pos = cls.find_close_conts(cont)
  File "/home/alex/MAS/CV/project/cv_nxtdrive/src/depth_detection.py", line 140, in find_close_conts
    cont[36]
IndexError: list index out of range

[rosout][ERROR] 2012-12-15 18:02:00,283: bad callback: <bound method DepthDetector.depth_cb of <__main__.DepthDetector instance at 0x2ad4a70>>
Traceback (most recent call last):
  File "/opt/ros/electric/stacks/ros_comm/clients/rospy/src/rospy/topics.py", line 581, in _invoke_callback
    cb(msg)
  File "/home/alex/MAS/CV/project/cv_nxtdrive/src/depth_detection.py", line 282, in depth_cb
    (contours, img_contours) = self.get_contours(img_fore)
  File "/home/alex/MAS/CV/project/cv_nxtdrive/src/depth_detection.py", line 107, in get_contours
    cont[0] = DepthDetector.merge_contours(cont[0])
  File "/home/alex/MAS/CV/project/cv_nxtdrive/src/depth_detection.py", line 161, in merge_contours
    return cls.merge_contours(new_cont)
  File "/home/alex/MAS/CV/project/cv_nxtdrive/src/depth_detection.py", line 161, in merge_contours
    return cls.merge_contours(new_cont)
  File "/home/alex/MAS/CV/project/cv_nxtdrive/src/depth_detection.py", line 161, in merge_contours
    return cls.merge_contours(new_cont)
  File "/home/alex/MAS/CV/project/cv_nxtdrive/src/depth_detection.py", line 161, in merge_contours
    return cls.merge_contours(new_cont)
  File "/home/alex/MAS/CV/project/cv_nxtdrive/src/depth_detection.py", line 161, in merge_contours
    return cls.merge_contours(new_cont)
  File "/home/alex/MAS/CV/project/cv_nxtdrive/src/depth_detection.py", line 161, in merge_contours
    return cls.merge_contours(new_cont)
  File "/home/alex/MAS/CV/project/cv_nxtdrive/src/depth_detection.py", line 161, in merge_contours
    return cls.merge_contours(new_cont)
  File "/home/alex/MAS/CV/project/cv_nxtdrive/src/depth_detection.py", line 161, in merge_contours
    return cls.merge_contours(new_cont)
  File "/home/alex/MAS/CV/project/cv_nxtdrive/src/depth_detection.py", line 161, in merge_contours
    return cls.merge_contours(new_cont)
  File "/home/alex/MAS/CV/project/cv_nxtdrive/src/depth_detection.py", line 161, in merge_contours
    return cls.merge_contours(new_cont)
  File "/home/alex/MAS/CV/project/cv_nxtdrive/src/depth_detection.py", line 161, in merge_contours
    return cls.merge_contours(new_cont)
  File "/home/alex/MAS/CV/project/cv_nxtdrive/src/depth_detection.py", line 156, in merge_contours
    i, j, i_pos, j_pos = cls.find_close_conts(cont)
  File "/home/alex/MAS/CV/project/cv_nxtdrive/src/depth_detection.py", line 140, in find_close_conts
    cont[36]
IndexError: list index out of range

[rosout][ERROR] 2012-12-15 18:02:00,331: bad callback: <bound method DepthDetector.depth_cb of <__main__.DepthDetector instance at 0x2ad4a70>>
Traceback (most recent call last):
  File "/opt/ros/electric/stacks/ros_comm/clients/rospy/src/rospy/topics.py", line 581, in _invoke_callback
    cb(msg)
  File "/home/alex/MAS/CV/project/cv_nxtdrive/src/depth_detection.py", line 282, in depth_cb
    (contours, img_contours) = self.get_contours(img_fore)
  File "/home/alex/MAS/CV/project/cv_nxtdrive/src/depth_detection.py", line 107, in get_contours
    cont[0] = DepthDetector.merge_contours(cont[0])
  File "/home/alex/MAS/CV/project/cv_nxtdrive/src/depth_detection.py", line 161, in merge_contours
    return cls.merge_contours(new_cont)
  File "/home/alex/MAS/CV/project/cv_nxtdrive/src/depth_detection.py", line 161, in merge_contours
    return cls.merge_contours(new_cont)
  File "/home/alex/MAS/CV/project/cv_nxtdrive/src/depth_detection.py", line 161, in merge_contours
    return cls.merge_contours(new_cont)
  File "/home/alex/MAS/CV/project/cv_nxtdrive/src/depth_detection.py", line 161, in merge_contours
    return cls.merge_contours(new_cont)
  File "/home/alex/MAS/CV/project/cv_nxtdrive/src/depth_detection.py", line 161, in merge_contours
    return cls.merge_contours(new_cont)
  File "/home/alex/MAS/CV/project/cv_nxtdrive/src/depth_detection.py", line 161, in merge_contours
    return cls.merge_contours(new_cont)
  File "/home/alex/MAS/CV/project/cv_nxtdrive/src/depth_detection.py", line 156, in merge_contours
    i, j, i_pos, j_pos = cls.find_close_conts(cont)
  File "/home/alex/MAS/CV/project/cv_nxtdrive/src/depth_detection.py", line 140, in find_close_conts
    cont[36]
IndexError: list index out of range

[rosout][ERROR] 2012-12-15 18:02:00,459: bad callback: <bound method DepthDetector.depth_cb of <__main__.DepthDetector instance at 0x2ad4a70>>
Traceback (most recent call last):
  File "/opt/ros/electric/stacks/ros_comm/clients/rospy/src/rospy/topics.py", line 581, in _invoke_callback
    cb(msg)
  File "/home/alex/MAS/CV/project/cv_nxtdrive/src/depth_detection.py", line 282, in depth_cb
    (contours, img_contours) = self.get_contours(img_fore)
  File "/home/alex/MAS/CV/project/cv_nxtdrive/src/depth_detection.py", line 107, in get_contours
    cont[0] = DepthDetector.merge_contours(cont[0])
TypeError: 'tuple' object does not support item assignment

[rosout][ERROR] 2012-12-15 18:02:00,489: bad callback: <bound method DepthDetector.depth_cb of <__main__.DepthDetector instance at 0x2ad4a70>>
Traceback (most recent call last):
  File "/opt/ros/electric/stacks/ros_comm/clients/rospy/src/rospy/topics.py", line 581, in _invoke_callback
    cb(msg)
  File "/home/alex/MAS/CV/project/cv_nxtdrive/src/depth_detection.py", line 282, in depth_cb
    (contours, img_contours) = self.get_contours(img_fore)
  File "/home/alex/MAS/CV/project/cv_nxtdrive/src/depth_detection.py", line 107, in get_contours
    cont[0] = DepthDetector.merge_contours(cont[0])
  File "/home/alex/MAS/CV/project/cv_nxtdrive/src/depth_detection.py", line 161, in merge_contours
    return cls.merge_contours(new_cont)
  File "/home/alex/MAS/CV/project/cv_nxtdrive/src/depth_detection.py", line 156, in merge_contours
    i, j, i_pos, j_pos = cls.find_close_conts(cont)
  File "/home/alex/MAS/CV/project/cv_nxtdrive/src/depth_detection.py", line 140, in find_close_conts
    cont[36]
IndexError: list index out of range

[rosout][ERROR] 2012-12-15 18:02:00,594: bad callback: <bound method DepthDetector.depth_cb of <__main__.DepthDetector instance at 0x2ad4a70>>
Traceback (most recent call last):
  File "/opt/ros/electric/stacks/ros_comm/clients/rospy/src/rospy/topics.py", line 581, in _invoke_callback
    cb(msg)
  File "/home/alex/MAS/CV/project/cv_nxtdrive/src/depth_detection.py", line 282, in depth_cb
    (contours, img_contours) = self.get_contours(img_fore)
  File "/home/alex/MAS/CV/project/cv_nxtdrive/src/depth_detection.py", line 107, in get_contours
    cont[0] = DepthDetector.merge_contours(cont[0])
TypeError: 'tuple' object does not support item assignment

[rosout][ERROR] 2012-12-15 18:02:00,692: bad callback: <bound method DepthDetector.depth_cb of <__main__.DepthDetector instance at 0x2ad4a70>>
Traceback (most recent call last):
  File "/opt/ros/electric/stacks/ros_comm/clients/rospy/src/rospy/topics.py", line 581, in _invoke_callback
    cb(msg)
  File "/home/alex/MAS/CV/project/cv_nxtdrive/src/depth_detection.py", line 282, in depth_cb
    (contours, img_contours) = self.get_contours(img_fore)
  File "/home/alex/MAS/CV/project/cv_nxtdrive/src/depth_detection.py", line 107, in get_contours
    cont[0] = DepthDetector.merge_contours(cont[0])
  File "/home/alex/MAS/CV/project/cv_nxtdrive/src/depth_detection.py", line 161, in merge_contours
    return cls.merge_contours(new_cont)
  File "/home/alex/MAS/CV/project/cv_nxtdrive/src/depth_detection.py", line 161, in merge_contours
    return cls.merge_contours(new_cont)
  File "/home/alex/MAS/CV/project/cv_nxtdrive/src/depth_detection.py", line 161, in merge_contours
    return cls.merge_contours(new_cont)
  File "/home/alex/MAS/CV/project/cv_nxtdrive/src/depth_detection.py", line 161, in merge_contours
    return cls.merge_contours(new_cont)
  File "/home/alex/MAS/CV/project/cv_nxtdrive/src/depth_detection.py", line 161, in merge_contours
    return cls.merge_contours(new_cont)
  File "/home/alex/MAS/CV/project/cv_nxtdrive/src/depth_detection.py", line 161, in merge_contours
    return cls.merge_contours(new_cont)
  File "/home/alex/MAS/CV/project/cv_nxtdrive/src/depth_detection.py", line 161, in merge_contours
    return cls.merge_contours(new_cont)
  File "/home/alex/MAS/CV/project/cv_nxtdrive/src/depth_detection.py", line 161, in merge_contours
    return cls.merge_contours(new_cont)
  File "/home/alex/MAS/CV/project/cv_nxtdrive/src/depth_detection.py", line 161, in merge_contours
    return cls.merge_contours(new_cont)
  File "/home/alex/MAS/CV/project/cv_nxtdrive/src/depth_detection.py", line 161, in merge_contours
    return cls.merge_contours(new_cont)
  File "/home/alex/MAS/CV/project/cv_nxtdrive/src/depth_detection.py", line 161, in merge_contours
    return cls.merge_contours(new_cont)
  File "/home/alex/MAS/CV/project/cv_nxtdrive/src/depth_detection.py", line 161, in merge_contours
    return cls.merge_contours(new_cont)
  File "/home/alex/MAS/CV/project/cv_nxtdrive/src/depth_detection.py", line 161, in merge_contours
    return cls.merge_contours(new_cont)
  File "/home/alex/MAS/CV/project/cv_nxtdrive/src/depth_detection.py", line 156, in merge_contours
    i, j, i_pos, j_pos = cls.find_close_conts(cont)
  File "/home/alex/MAS/CV/project/cv_nxtdrive/src/depth_detection.py", line 140, in find_close_conts
    cont[36]
IndexError: list index out of range

[rospy.core][INFO] 2012-12-15 18:02:00,720: signal_shutdown [signal-2]
[rospy.impl.masterslave][INFO] 2012-12-15 18:02:00,728: signal-2
[rospy.topics][WARNING] 2012-12-15 18:02:00,775: during shutdown, bad callback: <bound method DepthDetector.depth_cb of <__main__.DepthDetector instance at 0x2ad4a70>>
Traceback (most recent call last):
  File "/opt/ros/electric/stacks/ros_comm/clients/rospy/src/rospy/topics.py", line 581, in _invoke_callback
    cb(msg)
  File "/home/alex/MAS/CV/project/cv_nxtdrive/src/depth_detection.py", line 282, in depth_cb
    (contours, img_contours) = self.get_contours(img_fore)
  File "/home/alex/MAS/CV/project/cv_nxtdrive/src/depth_detection.py", line 107, in get_contours
    cont[0] = DepthDetector.merge_contours(cont[0])
  File "/home/alex/MAS/CV/project/cv_nxtdrive/src/depth_detection.py", line 161, in merge_contours
    return cls.merge_contours(new_cont)
  File "/home/alex/MAS/CV/project/cv_nxtdrive/src/depth_detection.py", line 161, in merge_contours
    return cls.merge_contours(new_cont)
  File "/home/alex/MAS/CV/project/cv_nxtdrive/src/depth_detection.py", line 161, in merge_contours
    return cls.merge_contours(new_cont)
  File "/home/alex/MAS/CV/project/cv_nxtdrive/src/depth_detection.py", line 161, in merge_contours
    return cls.merge_contours(new_cont)
  File "/home/alex/MAS/CV/project/cv_nxtdrive/src/depth_detection.py", line 161, in merge_contours
    return cls.merge_contours(new_cont)
  File "/home/alex/MAS/CV/project/cv_nxtdrive/src/depth_detection.py", line 161, in merge_contours
    return cls.merge_contours(new_cont)
  File "/home/alex/MAS/CV/project/cv_nxtdrive/src/depth_detection.py", line 161, in merge_contours
    return cls.merge_contours(new_cont)
  File "/home/alex/MAS/CV/project/cv_nxtdrive/src/depth_detection.py", line 161, in merge_contours
    return cls.merge_contours(new_cont)
  File "/home/alex/MAS/CV/project/cv_nxtdrive/src/depth_detection.py", line 156, in merge_contours
    i, j, i_pos, j_pos = cls.find_close_conts(cont)
  File "/home/alex/MAS/CV/project/cv_nxtdrive/src/depth_detection.py", line 140, in find_close_conts
    cont[36]
IndexError: list index out of range

[rospy.core][INFO] 2012-12-15 18:02:00,844: signal_shutdown [atexit]
